Workbook

Sheet 📖 Инструкция
B2: 📋 КАЛЬКУЛЯТОР NEV v7
B4: Инструкция · Многоуровневая рецептура · Расчёт сырья · Многовалютные цены
B6: 🎯 ЛИСТЫ ДЛЯ РАБОТЫ
B7: Калькулятор | C7: Расчёт себестоимости готового продукта из каталога
B8: Калькулятор X | C8: Расчёт нового продукта (произвольный состав)
B9: Расчёт сырья | C9: Планирование закупок: ввод заявки → список сырья
B11: 📚 СПРАВОЧНИКИ
B12: Продукты | C12: Каталог готовой продукции (191 наименование)
B13: Полупродукты | C13: Каталог производимых полупродуктов (50)
B14: Сырьё | C14: Каталог покупного сырья (226 позиций, валюты RUB/USD/EUR/CNY)
B15: Курсы ЦБ | C15: История курсов валют (обновляется автоматически)
B16: Потери | C16: Реальные потери производства по данным выпусков (31 артикул)
B18: ⚠️ КАЧЕСТВО ДАННЫХ
B19: ⚠️ Что заполнить | C19: Дашборд: сырьё без цены, ошибки рецептур, нехватка полупродуктов
B21: 🛠 СЛУЖЕБНЫЕ (скрытые)
B22: Рецептуры | C22: Базовая таблица рецептов (read-only)
B23: _Развёртки | C23: Предрасчёт сырья для «Расчёта сырья»
B24: Apps Script код | C24: Код скрипта (см. также отдельный файл)
B27: 🚀 КАК НАЧАТЬ
B28: 1. | C28: Откройте файл в Google Sheets (загрузите на Drive, откройте через Sheets)
B29: 2. | C29: Установите Apps Script: Расширения → Apps Script → вставьте код из листа «Apps Script код» → Сохранить
B30: 3. | C30: Перезагрузите таблицу (F5) — появится меню «🛠 NEV»
B31: 4. | C31: Меню → «💱 Обновить курсы ЦБ» — загрузится актуальный курс. Дальше — обновляется автоматически при открытии
B32: 5. | C32: Откройте «⚠️ Что заполнить» — увидите, какие данные нужно дозаполнить (32 позиции без цен)
B33: 6. | C33: Заполните цены сырья в Сырьё (J=валюта, K=цена, F=дата необязательно)
B34: 7. | C34: Используйте «Калькулятор» для готовых продуктов, «Расчёт сырья» — для заявок
B37: 💡 ВАЖНЫЕ ОСОБЕННОСТИ
B38: • | C38: Курс EUR/RUB в K8 — авто из «Курсы ЦБ», можно перезаписать вручную
B39: • | C39: Цены сырья в 4 валютах: RUB, USD, EUR, CNY. Кросс-курс через ЦБ на дату поступления
B40: • | C40: • Колонка M в Калькуляторе — «Пред. цена €/кг без НДС» (ручной ввод, подменяет J)
B41: • | C41: • Ячейка M11 в Калькуляторе и Калькуляторе X — глобальные потери, % (ручной ввод, напр. 5%). Сбрасывается автоматически при смене продукта в B8.
B42: • | C42: В Расчёте сырья развёртки с потерями 3%, тара/сырьё/полупр. — отдельные секции с подытогами
B43: • | C43: При смене продукта (B8) ручные значения авто-сбрасываются
B44: • | C44: Σ% в L15 (сумма % компонентов): 🟢 ≈100%, 🔴 >100% — ошибка, 🟡 <100% — недозаполнено

Sheet Apps Script код
A1: /**
A2: * Google Apps Script для Калькулятор_NEV (версия 7)
A3: *
A4: * ИЗМЕНЕНИЯ в v7:
A5: * • Основной источник курсов — официальный API ЦБ РФ
A6: * (https://www.cbr.ru/scripts/XML_daily.asp), XML
A7: * • Fallback-источники: cbr-xml-daily.ru → cbr-xml-daily.com
A8: * • Подробное сообщение об ошибке, если ни один источник не отдал данные
A9: *
A10: * Все остальные функции v6 (сброс калькуляторов, M11 для потерь,
A11: * автообновление при открытии) — без изменений.
A12: */
... A461: }

Sheet ⚠️ Что заполнить
B2: ⚠️ ДАШБОРД КАЧЕСТВА ДАННЫХ
B3: Список того, что требует внимания. Обновляется автоматически.
B5: 📊 СВОДКА
B6: Сырья без цены: | C6: =SUMPRODUCT(('Сырьё'!$C$6:$C$233<>"")*(IFERROR('Сырьё'!$K$6:$K$231,0)=0)) -> #N/A
B7: Продуктов с Σ% > 100%: | C7: =COUNTIF(D17:D200,">1.005") -> 58
B8: Продуктов с Σ% < 99%: | C8: =COUNTIFS(D17:D200,">0",D17:D200,"<0.99") -> 0
B9: Полупродуктов без рецептуры: | C9: 56
B12: 🔴 1. СЫРЬЁ БЕЗ ЦЕНЫ — без этих цен себестоимость считается некорректно
B14: № | C14: Наименование | D14: Тип | E14: Поставщик | F14: Артикул
B15: 1 | C15: ='Сырьё'!C6 -> ASTRA11305 | D15: ='Сырьё'!I6 | E15: ='Сырьё'!G6 | F15: ='Сырьё'!H6
B16: 2 | C16: ='Сырьё'!C7 -> ASTRA11306 | D16: ='Сырьё'!I7 | E16: ='Сырьё'!G7 | F16: ='Сырьё'!H7
B17: 3 | C17: ='Сырьё'!C8 -> BLACK (PBl 7) | D17: ='Сырьё'!I8 | E17: ='Сырьё'!G8 | F17: ='Сырьё'!H8
B18: 4 | C18: ='Сырьё'!C22 -> Extender TRIPOL 16 | D18: ='Сырьё'!I22 -> ⚗️ полупр. | E18: ='Сырьё'!G22 | F18: ='Сырьё'!H22
B19: 5 | C19: ='Сырьё'!C34 -> LuWax AF31 | D19: ='Сырьё'!I34 | E19: ='Сырьё'!G34 | F19: ='Сырьё'!H34
B20: 6 | C20: ='Сырьё'!C35 -> MAGENTA (PR 57:1) SURF | D20: ='Сырьё'!I35 | E20: ='Сырьё'!G35 | F20: ='Сырьё'!H35
B21: 7 | C21: ='Сырьё'!C38 -> Neocrylic Resin B 819 | D21: ='Сырьё'!I38 | E21: ='Сырьё'!G38 | F21: ='Сырьё'!H38
B22: 8 | C22: ='Сырьё'!C39 -> Neocrylic Resin BM 619 | D22: ='Сырьё'!I39 | E22: ='Сырьё'!G39 | F22: ='Сырьё'!H39
B23: 9 | C23: ='Сырьё'!C40 -> Neorez u 476 | D23: ='Сырьё'!I40 | E23: ='Сырьё'!G40 | F23: ='Сырьё'!H40
B24: 10 | C24: ='Сырьё'!C44 -> Nitrocellulose L1\8 SEC(IPA) | D24: ='Сырьё'!I44 | E24: ='Сырьё'!G44 | F24: ='Сырьё'!H44
B25: 11 | C25: ='Сырьё'!C57 -> Pigment Red (PR 122) СИНТЕЗ ЦВЕТА | D25: ='Сырьё'!I57 | E25: ='Сырьё'!G57 | F25: ='Сырьё'!H57
B26: 12 | C26: ='Сырьё'!C58 -> Pigment RED (PR 254) ХС | D26: ='Сырьё'!I58 | E26: ='Сырьё'!G58 | F26: ='Сырьё'!H58
B27: 13 | C27: ='Сырьё'!C64 -> Pigment Yellow (PY 74)(синтез цвета) | D27: ='Сырьё'!I64 | E27: ='Сырьё'!G64 | F27: ='Сырьё'!H64
B28: 14 | C28: ='Сырьё'!C65 -> Pigment Yellow (PY 83)радиант | D28: ='Сырьё'!I65 | E28: ='Сырьё'!G65 | F28: ='Сырьё'!H65
B29: 15 | C29: ='Сырьё'!C71 -> Pigment Yellow PY 13 ЕТС | D29: ='Сырьё'!I71 | E29: ='Сырьё'!G71 | F29: ='Сырьё'!H71
B30: 16 | C30: ='Сырьё'!C78 -> Technical extender AL_RESIST | D30: ='Сырьё'!I78 -> ⚗️ полупр. | E30: ='Сырьё'!G78 | F30: ='Сырьё'!H78
B31: 17 | C31: ='Сырьё'!C82 -> Technical Extender SURF ROTO | D31: ='Сырьё'!I82 -> ⚗️ полупр. | E31: ='Сырьё'!G82 | F31: ='Сырьё'!H82
B32: 18 | C32: ='Сырьё'!C86 -> TRIPOL 16 | D32: ='Сырьё'!I86 | E32: ='Сырьё'!G86 | F32: ='Сырьё'!H86
B33: 19 | C33: ='Сырьё'!C91 -> w 106r (для прямой печати ) | D33: ='Сырьё'!I91 | E33: ='Сырьё'!G91 | F33: ='Сырьё'!H91
B34: 20 | C34: ='Сырьё'!C93 -> YELLOW (PY 13) | D34: ='Сырьё'!I93 | E34: ='Сырьё'!G93 | F34: ='Сырьё'!H93
B35: 21 | C35: ='Сырьё'!C94 -> YL-904 | D35: ='Сырьё'!I94 | E35: ='Сырьё'!G94 | F35: ='Сырьё'!H94
B36: 22 | C36: ='Сырьё'!C121 -> Краска NSF/LAM ROTAGRAV | D36: ='Сырьё'!I121 | E36: ='Сырьё'!G121 | F36: ='Сырьё'!H121
B37: 23 | C37: ='Сырьё'!C141 -> Краска NSF/White (PW 6) PV ver1 | D37: ='Сырьё'!I141 | E37: ='Сырьё'!G141 | F37: ='Сырьё'!H141
B38: 24 | C38: ='Сырьё'!C142 -> Краска NSF/White (PW 6) PV ver2 | D38: ='Сырьё'!I142 | E38: ='Сырьё'!G142 | F38: ='Сырьё'!H142
B39: 25 | C39: ='Сырьё'!C156 -> ЛАК НЦ -0711 | D39: ='Сырьё'!I156 -> ⚗️ полупр. | E39: ='Сырьё'!G156 | F39: ='Сырьё'!H156
B40: 26 | C40: ='Сырьё'!C157 -> ЛАК НЦ 35 ROTO | D40: ='Сырьё'!I157 -> ⚗️ полупр. | E40: ='Сырьё'!G157 | F40: ='Сырьё'!H157
B41: 27 | C41: ='Сырьё'!C160 -> Лак покрывной | D41: ='Сырьё'!I160 -> ⚗️ полупр. | E41: ='Сырьё'!G160 | F41: ='Сырьё'!H160
B42: 28 | C42: ='Сырьё'!C161 -> Лак покрывной(холодный клей) | D42: ='Сырьё'!I161 -> ⚗️ полупр. | E42: ='Сырьё'!G161 | F42: ='Сырьё'!H161
B43: 29 | C43: ='Сырьё'!C205 -> Пирогенный диоксид кремния HL-200 | D43: ='Сырьё'!I205 | E43: ='Сырьё'!G205 | F43: ='Сырьё'!H205
B44: 30 | C44: ='Сырьё'!C206 -> покрывной лак | D44: ='Сырьё'!I206 -> ⚗️ полупр. | E44: ='Сырьё'!G206 | F44: ='Сырьё'!H206
B45: 31 | C45: ='Сырьё'!C207 -> покрывной лак (OVERPRINT VARNISH ) | D45: ='Сырьё'!I207 -> ⚗️ полупр. | E45: ='Сырьё'!G207 | F45: ='Сырьё'!H207
...

Sheet Калькулятор
T1: {=IF($I$14=0,$B$8,IFERROR(INDEX('Рецептуры'!$F:$F,MATCH($B$8&"|"&$I$14,'Рецептуры'!$K:$K,0)),$B$8))} -> Black (PBl 7) / RASTR
F2: КАЛЬКУЛЯТОР СЕБЕСТОИМОСТИ
F4: Многоуровневая рецептура · €/кг и ₽/кг · с НДС и без НДС
B7: 📦 ПРОДУКТ | F7: 🔖 АРТИКУЛ | G7: 🔎 ПОИСК ПО АРТИКУЛУ | J7: 💱 КУРС EUR / ₽
B8: Black (PBl 7) / RASTR | F8: {=IFERROR(IF(INDEX('Продукты'!$F:$F,MATCH($B$8,'Продукты'!$D:$D,0))=0,IF(INDEX('Полупродукты'!$F:$F,MATCH($B$8,'Полупродукты'!$C:$C,0))=0,"—",INDEX('Полупродукты'!$F:$F,MATCH($B$8,'Полупродукты'!$C:$C,0))),INDEX('Продукты'!$F:$F,MATCH($B$8,'Продукты'!$D:$D,0))),IFERROR(IF(INDEX('Полупродукты'!$F:$F,MATCH($B$8,'Полупродукты'!$C:$C,0))=0,"—",INDEX('Полупродукты'!$F:$F,MATCH($B$8,'Полупродукты'!$C:$C,0))),"—"))} -> — | H8: {=IF($G$8="","",IFERROR(INDEX('Продукты'!$D:$D,MATCH($G$8,'Продукты'!$F:$F,0)),IFERROR(INDEX('Полупродукты'!$C:$C,MATCH($G$8,'Полупродукты'!$F:$F,0)),"❌ артикул не найден")))} | J8: =IFERROR(LOOKUP(2,1/('Курсы ЦБ'!$C$7:$C$1000<>""),'Курсы ЦБ'!$C$7:$C$1000),100) -> 83.6892 | N8: 💼 МИНИ-КАЛЬКУЛЯТОР · ЦЕНА КЛИЕНТУ
B9: нажмите ▼ — выбор из списка | F9: автоматически по B8 | G9: ввод → | H9: ↑ скопируйте имя в B8 | J9: авто из «Курсы ЦБ» (можно перезаписать)
B10: ИТОГОВАЯ СЕБЕСТОИМОСТЬ · 1 КГ ГП | M10: 🔻 ПОТЕРИ
B11: =ROUND(K37,2) -> 3.12 | E11: =ROUND(K37*(1+0.22),2) -> 3.81 | G11: =ROUND(K37*$J$8,2) -> 261.11 | J11: =ROUND(K37*(1+0.22)*$J$8,2) -> 318.55
B12: €/кг без НДС | E12: €/кг с НДС | G12: ₽/кг без НДС | J12: ₽/кг с НДС | M12: ручной ввод, %
B13: =IF($B$8="","← Выберите продукт в B8","Продукт: "&$B$8&" | Артикул: "&$F$8&" | Σ%: "&TEXT($K$15,"0.00%")&IF($G$15<>""," | "&$G$15,"")) -> Продукт: Black (PBl 7) / RASTR | Артикул: — | Σ%: 100,00%
B14: 🔍 Раскрыть полупродукт — введите № строки: | I14: 0 | J14: (0 = основной продукт)
B15: Рецептура | I15: Σ %: | K15: =SUM(H17:H36) -> 1
B16: № | C16: Тип | D16: Компонент | E16: Раздел | F16: Ед. | G16: % ввод ручной | H16: % факт 100% | I16: Кол-во на 1 кг | J16: Цена €/кг база | K16: €/кг без НДС | L16: ₽/кг без НДС | M16: Пред. цена €/кг без НДС | N16: Статья | O16: €/кг с НДС | P16: ₽/кг с НДС
B17: 1 | C17: =IF(D17="","",IF(ISNUMBER(MATCH(D17,'Полупродукты'!$C$6:$C$62,0)),"⚗️ Полупр.","Сырьё")) -> Сырьё | D17: {=IFERROR(INDEX('Рецептуры'!$F:$F,MATCH($T$1&"|"&1,'Рецептуры'!$K:$K,0)),"")} -> Паста NSF/Paste Black (Pbk 7) КП 80 РАСТ | E17: =IF(D17="","","Материал основной") -> Материал основной | F17: =IF(D17="","","кг") -> кг | H17: {=IF(D17="","",IF(G17="",IFERROR(INDEX('Рецептуры'!$G:$G,MATCH($T$1&"|"&1,'Рецептуры'!$K:$K,0)),0),G17))} -> 0.78 | I17: =IF(D17="","",ROUND(H17*(1+IFERROR($M$11,0)),6)) -> 0.78 | J17: =IF(D17="","",IF(AND(M17<>"",M17>0),M17,IFERROR(VLOOKUP(D17,'Полупродукты'!$C$6:$E$62,3,FALSE()),IFERROR(VLOOKUP(D17,'Сырьё'!$C$6:$E$233,3,FALSE()),0)))) -> 3.6225 | K17: =IF(D17="","",ROUND(IFERROR(I17*J17,0),2)) -> 2.83 | L17: =IF(D17="","",ROUND(IFERROR(K17*$J$8,0),2)) -> 236.84 | N17: Себестоимость | O17: =E11 -> 3.81 | P17: =ROUND(O17*$J$8,2) -> 318.86
B18: 2 | C18: =IF(D18="","",IF(ISNUMBER(MATCH(D18,'Полупродукты'!$C$6:$C$62,0)),"⚗️ Полупр.","Сырьё")) -> ⚗️ Полупр. | D18: {=IFERROR(INDEX('Рецептуры'!$F:$F,MATCH($T$1&"|"&2,'Рецептуры'!$K:$K,0)),"")} -> Technical Extender UNI 397 | E18: =IF(D18="","","Материал основной") -> Материал основной | F18: =IF(D18="","","кг") -> кг | H18: {=IF(D18="","",IF(G18="",IFERROR(INDEX('Рецептуры'!$G:$G,MATCH($T$1&"|"&2,'Рецептуры'!$K:$K,0)),0),G18))} -> 0.12 | I18: =IF(D18="","",ROUND(H18*(1+IFERROR($M$11,0)),6)) -> 0.12 | J18: =IF(D18="","",IF(AND(M18<>"",M18>0),M18,IFERROR(VLOOKUP(D18,'Полупродукты'!$C$6:$E$62,3,FALSE()),IFERROR(VLOOKUP(D18,'Сырьё'!$C$6:$E$233,3,FALSE()),0)))) | K18: =IF(D18="","",ROUND(IFERROR(I18*J18,0),2)) -> 0 | L18: =IF(D18="","",ROUND(IFERROR(K18*$J$8,0),2)) -> 0 | N18: Доставка на 1 кг | O18: 0.12 | P18: =ROUND(O18*$J$8,2) -> 10.04
B19: 3 | C19: =IF(D19="","",IF(ISNUMBER(MATCH(D19,'Полупродукты'!$C$6:$C$62,0)),"⚗️ Полупр.","Сырьё")) -> ⚗️ Полупр. | D19: {=IFERROR(INDEX('Рецептуры'!$F:$F,MATCH($T$1&"|"&3,'Рецептуры'!$K:$K,0)),"")} -> Extender SL-2 ЭЦ | E19: =IF(D19="","","Материал основной") -> Материал основной | F19: =IF(D19="","","кг") -> кг | H19: {=IF(D19="","",IF(G19="",IFERROR(INDEX('Рецептуры'!$G:$G,MATCH($T$1&"|"&3,'Рецептуры'!$K:$K,0)),0),G19))} -> 0.05 | I19: =IF(D19="","",ROUND(H19*(1+IFERROR($M$11,0)),6)) -> 0.05 | J19: =IF(D19="","",IF(AND(M19<>"",M19>0),M19,IFERROR(VLOOKUP(D19,'Полупродукты'!$C$6:$E$62,3,FALSE()),IFERROR(VLOOKUP(D19,'Сырьё'!$C$6:$E$233,3,FALSE()),0)))) -> 2.7708 | K19: =IF(D19="","",ROUND(IFERROR(I19*J19,0),2)) -> 0.14 | L19: =IF(D19="","",ROUND(IFERROR(K19*$J$8,0),2)) -> 11.72 | N19: GM2 | O19: 0.65 | P19: =ROUND(O19*$J$8,2) -> 54.4
B20: 4 | C20: =IF(D20="","",IF(ISNUMBER(MATCH(D20,'Полупродукты'!$C$6:$C$62,0)),"⚗️ Полупр.","Сырьё")) -> Сырьё | D20: {=IFERROR(INDEX('Рецептуры'!$F:$F,MATCH($T$1&"|"&4,'Рецептуры'!$K:$K,0)),"")} -> TCA-IAM20 (аналог Титан АП 100/Титан АП 130 Д) | E20: =IF(D20="","","Материал основной") -> Материал основной | F20: =IF(D20="","","кг") -> кг | H20: {=IF(D20="","",IF(G20="",IFERROR(INDEX('Рецептуры'!$G:$G,MATCH($T$1&"|"&4,'Рецептуры'!$K:$K,0)),0),G20))} -> 0.005 | I20: =IF(D20="","",ROUND(H20*(1+IFERROR($M$11,0)),6)) -> 0.005 | J20: =IF(D20="","",IF(AND(M20<>"",M20>0),M20,IFERROR(VLOOKUP(D20,'Полупродукты'!$C$6:$E$62,3,FALSE()),IFERROR(VLOOKUP(D20,'Сырьё'!$C$6:$E$233,3,FALSE()),0)))) -> 14.556 | K20: =IF(D20="","",ROUND(IFERROR(I20*J20,0),2)) -> 0.07 | L20: =IF(D20="","",ROUND(IFERROR(K20*$J$8,0),2)) -> 5.86 | N20: КВ | O20: 0 | P20: =ROUND(O20*$J$8,2) -> 0
B21: 5 | C21: =IF(D21="","",IF(ISNUMBER(MATCH(D21,'Полупродукты'!$C$6:$C$62,0)),"⚗️ Полупр.","Сырьё")) -> Сырьё | D21: {=IFERROR(INDEX('Рецептуры'!$F:$F,MATCH($T$1&"|"&5,'Рецептуры'!$K:$K,0)),"")} -> Этилцеллозольв | E21: =IF(D21="","","Материал основной") -> Материал основной | F21: =IF(D21="","","кг") -> кг | H21: {=IF(D21="","",IF(G21="",IFERROR(INDEX('Рецептуры'!$G:$G,MATCH($T$1&"|"&5,'Рецептуры'!$K:$K,0)),0),G21))} -> 0.045 | I21: =IF(D21="","",ROUND(H21*(1+IFERROR($M$11,0)),6)) -> 0.045 | J21: =IF(D21="","",IF(AND(M21<>"",M21>0),M21,IFERROR(VLOOKUP(D21,'Полупродукты'!$C$6:$E$62,3,FALSE()),IFERROR(VLOOKUP(D21,'Сырьё'!$C$6:$E$233,3,FALSE()),0)))) -> 1.7145 | K21: =IF(D21="","",ROUND(IFERROR(I21*J21,0),2)) -> 0.08 | L21: =IF(D21="","",ROUND(IFERROR(K21*$J$8,0),2)) -> 6.7 | N21: Прочие расходы | O21: 0 | P21: =ROUND(O21*$J$8,2) -> 0
B22: 6 | C22: =IF(D22="","",IF(ISNUMBER(MATCH(D22,'Полупродукты'!$C$6:$C$62,0)),"⚗️ Полупр.","Сырьё")) | D22: {=IFERROR(INDEX('Рецептуры'!$F:$F,MATCH($T$1&"|"&6,'Рецептуры'!$K:$K,0)),"")} | E22: =IF(D22="","","Материал основной") | F22: =IF(D22="","","кг") | H22: {=IF(D22="","",IF(G22="",IFERROR(INDEX('Рецептуры'!$G:$G,MATCH($T$1&"|"&6,'Рецептуры'!$K:$K,0)),0),G22))} | I22: =IF(D22="","",ROUND(H22*(1+IFERROR($M$11,0)),6)) | J22: =IF(D22="","",IF(AND(M22<>"",M22>0),M22,IFERROR(VLOOKUP(D22,'Полупродукты'!$C$6:$E$62,3,FALSE()),IFERROR(VLOOKUP(D22,'Сырьё'!$C$6:$E$233,3,FALSE()),0)))) | K22: =IF(D22="","",ROUND(IFERROR(I22*J22,0),2)) | L22: =IF(D22="","",ROUND(IFERROR(K22*$J$8,0),2)) | N22: Полная стоимость | O22: =ROUND(SUM(O17:O21),2) -> 4.58 | P22: =ROUND(O22*$J$8,2) -> 383.3
B23: 7 | C23: =IF(D23="","",IF(ISNUMBER(MATCH(D23,'Полупродукты'!$C$6:$C$62,0)),"⚗️ Полупр.","Сырьё")) | D23: {=IFERROR(INDEX('Рецептуры'!$F:$F,MATCH($T$1&"|"&7,'Рецептуры'!$K:$K,0)),"")} | E23: =IF(D23="","","Материал основной") | F23: =IF(D23="","","кг") | H23: {=IF(D23="","",IF(G23="",IFERROR(INDEX('Рецептуры'!$G:$G,MATCH($T$1&"|"&7,'Рецептуры'!$K:$K,0)),0),G23))} | I23: =IF(D23="","",ROUND(H23*(1+IFERROR($M$11,0)),6)) | J23: =IF(D23="","",IF(AND(M23<>"",M23>0),M23,IFERROR(VLOOKUP(D23,'Полупродукты'!$C$6:$E$62,3,FALSE()),IFERROR(VLOOKUP(D23,'Сырьё'!$C$6:$E$233,3,FALSE()),0)))) | K23: =IF(D23="","",ROUND(IFERROR(I23*J23,0),2)) | L23: =IF(D23="","",ROUND(IFERROR(K23*$J$8,0),2)) | N23: Наценка, % | O23: 0 | P23: =ROUND(O22*O23*$J$8,2) -> 0
B24: 8 | C24: =IF(D24="","",IF(ISNUMBER(MATCH(D24,'Полупродукты'!$C$6:$C$62,0)),"⚗️ Полупр.","Сырьё")) | D24: {=IFERROR(INDEX('Рецептуры'!$F:$F,MATCH($T$1&"|"&8,'Рецептуры'!$K:$K,0)),"")} | E24: =IF(D24="","","Материал основной") | F24: =IF(D24="","","кг") | H24: {=IF(D24="","",IF(G24="",IFERROR(INDEX('Рецептуры'!$G:$G,MATCH($T$1&"|"&8,'Рецептуры'!$K:$K,0)),0),G24))} | I24: =IF(D24="","",ROUND(H24*(1+IFERROR($M$11,0)),6)) | J24: =IF(D24="","",IF(AND(M24<>"",M24>0),M24,IFERROR(VLOOKUP(D24,'Полупродукты'!$C$6:$E$62,3,FALSE()),IFERROR(VLOOKUP(D24,'Сырьё'!$C$6:$E$233,3,FALSE()),0)))) | K24: =IF(D24="","",ROUND(IFERROR(I24*J24,0),2)) | L24: =IF(D24="","",ROUND(IFERROR(K24*$J$8,0),2)) | N24: Наценка, € | O24: =ROUND(O22*O23,2) -> 0 | P24: =ROUND(O24*$J$8,2) -> 0
B25: 9 | C25: =IF(D25="","",IF(ISNUMBER(MATCH(D25,'Полупродукты'!$C$6:$C$62,0)),"⚗️ Полупр.","Сырьё")) | D25: {=IFERROR(INDEX('Рецептуры'!$F:$F,MATCH($T$1&"|"&9,'Рецептуры'!$K:$K,0)),"")} | E25: =IF(D25="","","Материал основной") | F25: =IF(D25="","","кг") | H25: {=IF(D25="","",IF(G25="",IFERROR(INDEX('Рецептуры'!$G:$G,MATCH($T$1&"|"&9,'Рецептуры'!$K:$K,0)),0),G25))} | I25: =IF(D25="","",ROUND(H25*(1+IFERROR($M$11,0)),6)) | J25: =IF(D25="","",IF(AND(M25<>"",M25>0),M25,IFERROR(VLOOKUP(D25,'Полупродукты'!$C$6:$E$62,3,FALSE()),IFERROR(VLOOKUP(D25,'Сырьё'!$C$6:$E$233,3,FALSE()),0)))) | K25: =IF(D25="","",ROUND(IFERROR(I25*J25,0),2)) | L25: =IF(D25="","",ROUND(IFERROR(K25*$J$8,0),2))
B26: 10 | C26: =IF(D26="","",IF(ISNUMBER(MATCH(D26,'Полупродукты'!$C$6:$C$62,0)),"⚗️ Полупр.","Сырьё")) | D26: {=IFERROR(INDEX('Рецептуры'!$F:$F,MATCH($T$1&"|"&10,'Рецептуры'!$K:$K,0)),"")} | E26: =IF(D26="","","Материал основной") | F26: =IF(D26="","","кг") | H26: {=IF(D26="","",IF(G26="",IFERROR(INDEX('Рецептуры'!$G:$G,MATCH($T$1&"|"&10,'Рецептуры'!$K:$K,0)),0),G26))} | I26: =IF(D26="","",ROUND(H26*(1+IFERROR($M$11,0)),6)) | J26: =IF(D26="","",IF(AND(M26<>"",M26>0),M26,IFERROR(VLOOKUP(D26,'Полупродукты'!$C$6:$E$62,3,FALSE()),IFERROR(VLOOKUP(D26,'Сырьё'!$C$6:$E$233,3,FALSE()),0)))) | K26: =IF(D26="","",ROUND(IFERROR(I26*J26,0),2)) | L26: =IF(D26="","",ROUND(IFERROR(K26*$J$8,0),2)) | N26: ЦЕНА ДЛЯ КЛИЕНТА
B27: 11 | C27: =IF(D27="","",IF(ISNUMBER(MATCH(D27,'Полупродукты'!$C$6:$C$62,0)),"⚗️ Полупр.","Сырьё")) | D27: {=IFERROR(INDEX('Рецептуры'!$F:$F,MATCH($T$1&"|"&11,'Рецептуры'!$K:$K,0)),"")} | E27: =IF(D27="","","Материал основной") | F27: =IF(D27="","","кг") | H27: {=IF(D27="","",IF(G27="",IFERROR(INDEX('Рецептуры'!$G:$G,MATCH($T$1&"|"&11,'Рецептуры'!$K:$K,0)),0),G27))} | I27: =IF(D27="","",ROUND(H27*(1+IFERROR($M$11,0)),6)) | J27: =IF(D27="","",IF(AND(M27<>"",M27>0),M27,IFERROR(VLOOKUP(D27,'Полупродукты'!$C$6:$E$62,3,FALSE()),IFERROR(VLOOKUP(D27,'Сырьё'!$C$6:$E$233,3,FALSE()),0)))) | K27: =IF(D27="","",ROUND(IFERROR(I27*J27,0),2)) | L27: =IF(D27="","",ROUND(IFERROR(K27*$J$8,0),2)) | N27: с НДС | O27: =ROUND(O22*(1+O23),2) -> 4.58 | P27: =ROUND(O27*$J$8,2) -> 383.3
B28: 12 | C28: =IF(D28="","",IF(ISNUMBER(MATCH(D28,'Полупродукты'!$C$6:$C$62,0)),"⚗️ Полупр.","Сырьё")) | D28: {=IFERROR(INDEX('Рецептуры'!$F:$F,MATCH($T$1&"|"&12,'Рецептуры'!$K:$K,0)),"")} | E28: =IF(D28="","","Материал основной") | F28: =IF(D28="","","кг") | H28: {=IF(D28="","",IF(G28="",IFERROR(INDEX('Рецептуры'!$G:$G,MATCH($T$1&"|"&12,'Рецептуры'!$K:$K,0)),0),G28))} | I28: =IF(D28="","",ROUND(H28*(1+IFERROR($M$11,0)),6)) | J28: =IF(D28="","",IF(AND(M28<>"",M28>0),M28,IFERROR(VLOOKUP(D28,'Полупродукты'!$C$6:$E$62,3,FALSE()),IFERROR(VLOOKUP(D28,'Сырьё'!$C$6:$E$233,3,FALSE()),0)))) | K28: =IF(D28="","",ROUND(IFERROR(I28*J28,0),2)) | L28: =IF(D28="","",ROUND(IFERROR(K28*$J$8,0),2)) | N28: без НДС | O28: =ROUND(O27/(1+0.22),2) -> 3.75 | P28: =ROUND(O28*$J$8,2) -> 313.83
B29: 13 | C29: =IF(D29="","",IF(ISNUMBER(MATCH(D29,'Полупродукты'!$C$6:$C$62,0)),"⚗️ Полупр.","Сырьё")) | D29: {=IFERROR(INDEX('Рецептуры'!$F:$F,MATCH($T$1&"|"&13,'Рецептуры'!$K:$K,0)),"")} | E29: =IF(D29="","","Материал основной") | F29: =IF(D29="","","кг") | H29: {=IF(D29="","",IF(G29="",IFERROR(INDEX('Рецептуры'!$G:$G,MATCH($T$1&"|"&13,'Рецептуры'!$K:$K,0)),0),G29))} | I29: =IF(D29="","",ROUND(H29*(1+IFERROR($M$11,0)),6)) | J29: =IF(D29="","",IF(AND(M29<>"",M29>0),M29,IFERROR(VLOOKUP(D29,'Полупродукты'!$C$6:$E$62,3,FALSE()),IFERROR(VLOOKUP(D29,'Сырьё'!$C$6:$E$233,3,FALSE()),0)))) | K29: =IF(D29="","",ROUND(IFERROR(I29*J29,0),2)) | L29: =IF(D29="","",ROUND(IFERROR(K29*$J$8,0),2))
B30: 14 | C30: =IF(D30="","",IF(ISNUMBER(MATCH(D30,'Полупродукты'!$C$6:$C$62,0)),"⚗️ Полупр.","Сырьё")) | D30: {=IFERROR(INDEX('Рецептуры'!$F:$F,MATCH($T$1&"|"&14,'Рецептуры'!$K:$K,0)),"")} | E30: =IF(D30="","","Материал основной") | F30: =IF(D30="","","кг") | H30: {=IF(D30="","",IF(G30="",IFERROR(INDEX('Рецептуры'!$G:$G,MATCH($T$1&"|"&14,'Рецептуры'!$K:$K,0)),0),G30))} | I30: =IF(D30="","",ROUND(H30*(1+IFERROR($M$11,0)),6)) | J30: =IF(D30="","",IF(AND(M30<>"",M30>0),M30,IFERROR(VLOOKUP(D30,'Полупродукты'!$C$6:$E$62,3,FALSE()),IFERROR(VLOOKUP(D30,'Сырьё'!$C$6:$E$233,3,FALSE()),0)))) | K30: =IF(D30="","",ROUND(IFERROR(I30*J30,0),2)) | L30: =IF(D30="","",ROUND(IFERROR(K30*$J$8,0),2))
B31: 15 | C31: =IF(D31="","",IF(ISNUMBER(MATCH(D31,'Полупродукты'!$C$6:$C$62,0)),"⚗️ Полупр.","Сырьё")) | D31: {=IFERROR(INDEX('Рецептуры'!$F:$F,MATCH($T$1&"|"&15,'Рецептуры'!$K:$K,0)),"")} | E31: =IF(D31="","","Материал основной") | F31: =IF(D31="","","кг") | H31: {=IF(D31="","",IF(G31="",IFERROR(INDEX('Рецептуры'!$G:$G,MATCH($T$1&"|"&15,'Рецептуры'!$K:$K,0)),0),G31))} | I31: =IF(D31="","",ROUND(H31*(1+IFERROR($M$11,0)),6)) | J31: =IF(D31="","",IF(AND(M31<>"",M31>0),M31,IFERROR(VLOOKUP(D31,'Полупродукты'!$C$6:$E$62,3,FALSE()),IFERROR(VLOOKUP(D31,'Сырьё'!$C$6:$E$233,3,FALSE()),0)))) | K31: =IF(D31="","",ROUND(IFERROR(I31*J31,0),2)) | L31: =IF(D31="","",ROUND(IFERROR(K31*$J$8,0),2))
B32: 16 | C32: =IF(D32="","",IF(ISNUMBER(MATCH(D32,'Полупродукты'!$C$6:$C$62,0)),"⚗️ Полупр.","Сырьё")) | D32: {=IFERROR(INDEX('Рецептуры'!$F:$F,MATCH($T$1&"|"&16,'Рецептуры'!$K:$K,0)),"")} | E32: =IF(D32="","","Материал основной") | F32: =IF(D32="","","кг") | H32: {=IF(D32="","",IF(G32="",IFERROR(INDEX('Рецептуры'!$G:$G,MATCH($T$1&"|"&16,'Рецептуры'!$K:$K,0)),0),G32))} | I32: =IF(D32="","",ROUND(H32*(1+IFERROR($M$11,0)),6)) | J32: =IF(D32="","",IF(AND(M32<>"",M32>0),M32,IFERROR(VLOOKUP(D32,'Полупродукты'!$C$6:$E$62,3,FALSE()),IFERROR(VLOOKUP(D32,'Сырьё'!$C$6:$E$233,3,FALSE()),0)))) | K32: =IF(D32="","",ROUND(IFERROR(I32*J32,0),2)) | L32: =IF(D32="","",ROUND(IFERROR(K32*$J$8,0),2))
B33: 17 | C33: =IF(D33="","",IF(ISNUMBER(MATCH(D33,'Полупродукты'!$C$6:$C$62,0)),"⚗️ Полупр.","Сырьё")) | D33: {=IFERROR(INDEX('Рецептуры'!$F:$F,MATCH($T$1&"|"&17,'Рецептуры'!$K:$K,0)),"")} | E33: =IF(D33="","","Материал основной") | F33: =IF(D33="","","кг") | H33: {=IF(D33="","",IF(G33="",IFERROR(INDEX('Рецептуры'!$G:$G,MATCH($T$1&"|"&17,'Рецептуры'!$K:$K,0)),0),G33))} | I33: =IF(D33="","",ROUND(H33*(1+IFERROR($M$11,0)),6)) | J33: =IF(D33="","",IF(AND(M33<>"",M33>0),M33,IFERROR(VLOOKUP(D33,'Полупродукты'!$C$6:$E$62,3,FALSE()),IFERROR(VLOOKUP(D33,'Сырьё'!$C$6:$E$233,3,FALSE()),0)))) | K33: =IF(D33="","",ROUND(IFERROR(I33*J33,0),2)) | L33: =IF(D33="","",ROUND(IFERROR(K33*$J$8,0),2))
B34: 18 | C34: =IF(D34="","",IF(ISNUMBER(MATCH(D34,'Полупродукты'!$C$6:$C$62,0)),"⚗️ Полупр.","Сырьё")) | D34: {=IFERROR(INDEX('Рецептуры'!$F:$F,MATCH($T$1&"|"&18,'Рецептуры'!$K:$K,0)),"")} | E34: =IF(D34="","","Материал основной") | F34: =IF(D34="","","кг") | H34: {=IF(D34="","",IF(G34="",IFERROR(INDEX('Рецептуры'!$G:$G,MATCH($T$1&"|"&18,'Рецептуры'!$K:$K,0)),0),G34))} | I34: =IF(D34="","",ROUND(H34*(1+IFERROR($M$11,0)),6)) | J34: =IF(D34="","",IF(AND(M34<>"",M34>0),M34,IFERROR(VLOOKUP(D34,'Полупродукты'!$C$6:$E$62,3,FALSE()),IFERROR(VLOOKUP(D34,'Сырьё'!$C$6:$E$233,3,FALSE()),0)))) | K34: =IF(D34="","",ROUND(IFERROR(I34*J34,0),2)) | L34: =IF(D34="","",ROUND(IFERROR(K34*$J$8,0),2))
B35: 19 | C35: =IF(D35="","",IF(ISNUMBER(MATCH(D35,'Полупродукты'!$C$6:$C$62,0)),"⚗️ Полупр.","Сырьё")) | D35: {=IFERROR(INDEX('Рецептуры'!$F:$F,MATCH($T$1&"|"&19,'Рецептуры'!$K:$K,0)),"")} | E35: =IF(D35="","","Материал основной") | F35: =IF(D35="","","кг") | H35: {=IF(D35="","",IF(G35="",IFERROR(INDEX('Рецептуры'!$G:$G,MATCH($T$1&"|"&19,'Рецептуры'!$K:$K,0)),0),G35))} | I35: =IF(D35="","",ROUND(H35*(1+IFERROR($M$11,0)),6)) | J35: =IF(D35="","",IF(AND(M35<>"",M35>0),M35,IFERROR(VLOOKUP(D35,'Полупродукты'!$C$6:$E$62,3,FALSE()),IFERROR(VLOOKUP(D35,'Сырьё'!$C$6:$E$233,3,FALSE()),0)))) | K35: =IF(D35="","",ROUND(IFERROR(I35*J35,0),2)) | L35: =IF(D35="","",ROUND(IFERROR(K35*$J$8,0),2))
B36: 20 | C36: =IF(D36="","",IF(ISNUMBER(MATCH(D36,'Полупродукты'!$C$6:$C$62,0)),"⚗️ Полупр.","Сырьё")) | D36: {=IFERROR(INDEX('Рецептуры'!$F:$F,MATCH($T$1&"|"&20,'Рецептуры'!$K:$K,0)),"")} | E36: =IF(D36="","","Материал основной") | F36: =IF(D36="","","кг") | H36: {=IF(D36="","",IF(G36="",IFERROR(INDEX('Рецептуры'!$G:$G,MATCH($T$1&"|"&20,'Рецептуры'!$K:$K,0)),0),G36))} | I36: =IF(D36="","",ROUND(H36*(1+IFERROR($M$11,0)),6)) | J36: =IF(D36="","",IF(AND(M36<>"",M36>0),M36,IFERROR(VLOOKUP(D36,'Полупродукты'!$C$6:$E$62,3,FALSE()),IFERROR(VLOOKUP(D36,'Сырьё'!$C$6:$E$233,3,FALSE()),0)))) | K36: =IF(D36="","",ROUND(IFERROR(I36*J36,0),2)) | L36: =IF(D36="","",ROUND(IFERROR(K36*$J$8,0),2))
B37: Σ ИТОГО | H37: =SUM(H17:H36) -> 1 | K37: =ROUND(SUM(K17:K36),2) -> 3.12 | L37: =ROUND(SUM(L17:L36),2) -> 261.12
B39: =IF($I$14=0,"⬇ Чтобы увидеть состав полупродукта — введите № его строки в желтую ячейку справа от 🔍","🔬 Состав полупродукта: "&$T$1) -> ⬇ Чтобы увидеть состав полупродукта — введите № его строки в желтую ячейку справа от 🔍
B40: № | C40: Тип | D40: Компонент | E40: Раздел | F40: Ед. | H40: % массы | I40: Кол-во на 1 кг | J40: Цена €/кг база | K40: €/кг без НДС | L40: ₽/кг без НДС
B41: =IF($I$14=0,"",1) | C41: =IF(OR($I$14=0,D41=""),"",IF(ISNUMBER(MATCH(D41,'Полупродукты'!$C$6:$C$62,0)),"⚗️ Полупр.","Сырьё")) | D41: {=IF($I$14=0,"",IFERROR(INDEX('Рецептуры'!$F:$F,MATCH($T$1&"|"&1,'Рецептуры'!$K:$K,0)),""))} | E41: =IF(D41="","","Материал основной") | F41: =IF(D41="","","кг") | H41: {=IF(OR($I$14=0,D41=""),"",IFERROR(INDEX('Рецептуры'!$G:$G,MATCH($T$1&"|"&1,'Рецептуры'!$K:$K,0)),0))} | I41: =IF(OR($I$14=0,D41=""),"",IFERROR(H41,0)) | J41: =IF(OR($I$14=0,D41=""),"",IFERROR(VLOOKUP(D41,'Полупродукты'!$C$6:$E$62,3,FALSE()),IFERROR(VLOOKUP(D41,'Сырьё'!$C$6:$E$233,3,FALSE()),0))) | K41: =IF(OR($I$14=0,D41=""),"",ROUND(IFERROR(I41*J41,0),2)) | L41: =IF(OR($I$14=0,D41=""),"",ROUND(IFERROR(K41*$J$8,0),2))
B42: =IF($I$14=0,"",2) | C42: =IF(OR($I$14=0,D42=""),"",IF(ISNUMBER(MATCH(D42,'Полупродукты'!$C$6:$C$62,0)),"⚗️ Полупр.","Сырьё")) | D42: {=IF($I$14=0,"",IFERROR(INDEX('Рецептуры'!$F:$F,MATCH($T$1&"|"&2,'Рецептуры'!$K:$K,0)),""))} | E42: =IF(D42="","","Материал основной") | F42: =IF(D42="","","кг") | H42: {=IF(OR($I$14=0,D42=""),"",IFERROR(INDEX('Рецептуры'!$G:$G,MATCH($T$1&"|"&2,'Рецептуры'!$K:$K,0)),0))} | I42: =IF(OR($I$14=0,D42=""),"",IFERROR(H42,0)) | J42: =IF(OR($I$14=0,D42=""),"",IFERROR(VLOOKUP(D42,'Полупродукты'!$C$6:$E$62,3,FALSE()),IFERROR(VLOOKUP(D42,'Сырьё'!$C$6:$E$233,3,FALSE()),0))) | K42: =IF(OR($I$14=0,D42=""),"",ROUND(IFERROR(I42*J42,0),2)) | L42: =IF(OR($I$14=0,D42=""),"",ROUND(IFERROR(K42*$J$8,0),2))
B43: =IF($I$14=0,"",3) | C43: =IF(OR($I$14=0,D43=""),"",IF(ISNUMBER(MATCH(D43,'Полупродукты'!$C$6:$C$62,0)),"⚗️ Полупр.","Сырьё")) | D43: {=IF($I$14=0,"",IFERROR(INDEX('Рецептуры'!$F:$F,MATCH($T$1&"|"&3,'Рецептуры'!$K:$K,0)),""))} | E43: =IF(D43="","","Материал основной") | F43: =IF(D43="","","кг") | H43: {=IF(OR($I$14=0,D43=""),"",IFERROR(INDEX('Рецептуры'!$G:$G,MATCH($T$1&"|"&3,'Рецептуры'!$K:$K,0)),0))} | I43: =IF(OR($I$14=0,D43=""),"",IFERROR(H43,0)) | J43: =IF(OR($I$14=0,D43=""),"",IFERROR(VLOOKUP(D43,'Полупродукты'!$C$6:$E$62,3,FALSE()),IFERROR(VLOOKUP(D43,'Сырьё'!$C$6:$E$233,3,FALSE()),0))) | K43: =IF(OR($I$14=0,D43=""),"",ROUND(IFERROR(I43*J43,0),2)) | L43: =IF(OR($I$14=0,D43=""),"",ROUND(IFERROR(K43*$J$8,0),2))
B44: =IF($I$14=0,"",4) | C44: =IF(OR($I$14=0,D44=""),"",IF(ISNUMBER(MATCH(D44,'Полупродукты'!$C$6:$C$62,0)),"⚗️ Полупр.","Сырьё")) | D44: {=IF($I$14=0,"",IFERROR(INDEX('Рецептуры'!$F:$F,MATCH($T$1&"|"&4,'Рецептуры'!$K:$K,0)),""))} | E44: =IF(D44="","","Материал основной") | F44: =IF(D44="","","кг") | H44: {=IF(OR($I$14=0,D44=""),"",IFERROR(INDEX('Рецептуры'!$G:$G,MATCH($T$1&"|"&4,'Рецептуры'!$K:$K,0)),0))} | I44: =IF(OR($I$14=0,D44=""),"",IFERROR(H44,0)) | J44: =IF(OR($I$14=0,D44=""),"",IFERROR(VLOOKUP(D44,'Полупродукты'!$C$6:$E$62,3,FALSE()),IFERROR(VLOOKUP(D44,'Сырьё'!$C$6:$E$233,3,FALSE()),0))) | K44: =IF(OR($I$14=0,D44=""),"",ROUND(IFERROR(I44*J44,0),2)) | L44: =IF(OR($I$14=0,D44=""),"",ROUND(IFERROR(K44*$J$8,0),2))
...

Sheet Калькулятор X
F2: КАЛЬКУЛЯТОР X · НОВЫЕ ПРОДУКТЫ
F4: Произвольный состав · компоненты и проценты вводятся вручную
B7: 📦 ПРОДУКТ | F7: 🔖 АРТИКУЛ | G7: 🔎 ПОИСК ПО АРТИКУЛУ | J7: 💱 КУРС EUR / ₽
B8: INK Magenta (PR 57:1) гу | F8: {=IFERROR(IF(INDEX('Продукты'!$F:$F,MATCH($B$8,'Продукты'!$D:$D,0))=0,IF(INDEX('Полупродукты'!$F:$F,MATCH($B$8,'Полупродукты'!$C:$C,0))=0,"—",INDEX('Полупродукты'!$F:$F,MATCH($B$8,'Полупродукты'!$C:$C,0))),INDEX('Продукты'!$F:$F,MATCH($B$8,'Продукты'!$D:$D,0))),IFERROR(IF(INDEX('Полупродукты'!$F:$F,MATCH($B$8,'Полупродукты'!$C:$C,0))=0,"—",INDEX('Полупродукты'!$F:$F,MATCH($B$8,'Полупродукты'!$C:$C,0))),"—"))} -> — | H8: {=IF($G$8="","",IFERROR(INDEX('Продукты'!$D:$D,MATCH($G$8,'Продукты'!$F:$F,0)),IFERROR(INDEX('Полупродукты'!$C:$C,MATCH($G$8,'Полупродукты'!$F:$F,0)),"❌ артикул не найден")))} | J8: =IFERROR(LOOKUP(2,1/('Курсы ЦБ'!$C$7:$C$1000<>""),'Курсы ЦБ'!$C$7:$C$1000),100) -> 83.6892 | N8: 💼 МИНИ-КАЛЬКУЛЯТОР · ЦЕНА КЛИЕНТУ
B9: состав вводится вручную ниже | F9: автоматически по B8 | G9: ввод → | H9: ↑ скопируйте имя в B8 | J9: авто из «Курсы ЦБ» (можно перезаписать)
B10: ИТОГОВАЯ СЕБЕСТОИМОСТЬ · 1 КГ ГП | M10: 🔻 ПОТЕРИ
B11: =ROUND(K37,2) -> 0 | E11: =ROUND(K37*(1+0.22),2) -> 0 | G11: =ROUND(K37*$J$8,2) -> 0 | J11: =ROUND(K37*(1+0.22)*$J$8,2) -> 0
B12: €/кг без НДС | E12: €/кг с НДС | G12: ₽/кг без НДС | J12: ₽/кг с НДС | M12: ручной ввод, %
B13: =IF($B$8="","← Выберите продукт в B8","Продукт: "&$B$8&" | Артикул: "&$F$8&" | Σ%: "&TEXT($K$15,"0.00%")&IF($G$15<>""," | "&$G$15,"")) -> Продукт: INK Magenta (PR 57:1) гу | Артикул: — | Σ%: 0,00%
B14: 💡 Заполните название компонента и % в строках ниже. Можно использовать имена с листа «Сырьё» или вводить свои.
B15: Рецептура (ручной ввод) | I15: Σ %: | K15: =SUM(H17:H36) -> 0
B16: № | C16: Тип | D16: Компонент | E16: Раздел | F16: Ед. | G16: % ввод ручной | H16: % факт 100% | I16: Кол-во на 1 кг | J16: Цена €/кг база | K16: €/кг без НДС | L16: ₽/кг без НДС | M16: Пред. цена €/кг без НДС | N16: Статья | O16: €/кг с НДС | P16: ₽/кг с НДС
B17: 1 | C17: =IF(D17="","",IF(ISNUMBER(MATCH(D17,'Полупродукты'!$C$6:$C$62,0)),"⚗️ Полупр.","Сырьё")) | F17: =IF(D17="","","кг") | H17: =IF(D17="","",IFERROR(G17,0)) | I17: =IF(D17="","",ROUND(H17*(1+IFERROR($M$11,0)),6)) | J17: =IF(D17="","",IF(AND(M17<>"",M17>0),M17,IFERROR(VLOOKUP(D17,'Полупродукты'!$C$6:$E$62,3,FALSE()),IFERROR(VLOOKUP(D17,'Сырьё'!$C$6:$E$233,3,FALSE()),0)))) | K17: =IF(D17="","",ROUND(IFERROR(I17*J17,0),2)) | L17: =IF(D17="","",ROUND(IFERROR(K17*$J$8,0),2)) | N17: Себестоимость | O17: =E11 -> 0 | P17: =ROUND(O17*$J$8,2) -> 0
B18: 2 | C18: =IF(D18="","",IF(ISNUMBER(MATCH(D18,'Полупродукты'!$C$6:$C$62,0)),"⚗️ Полупр.","Сырьё")) | F18: =IF(D18="","","кг") | H18: =IF(D18="","",IFERROR(G18,0)) | I18: =IF(D18="","",ROUND(H18*(1+IFERROR($M$11,0)),6)) | J18: =IF(D18="","",IF(AND(M18<>"",M18>0),M18,IFERROR(VLOOKUP(D18,'Полупродукты'!$C$6:$E$62,3,FALSE()),IFERROR(VLOOKUP(D18,'Сырьё'!$C$6:$E$233,3,FALSE()),0)))) | K18: =IF(D18="","",ROUND(IFERROR(I18*J18,0),2)) | L18: =IF(D18="","",ROUND(IFERROR(K18*$J$8,0),2)) | N18: Доставка на 1 кг | O18: 0.1 | P18: =ROUND(O18*$J$8,2) -> 8.37
B19: 3 | C19: =IF(D19="","",IF(ISNUMBER(MATCH(D19,'Полупродукты'!$C$6:$C$62,0)),"⚗️ Полупр.","Сырьё")) | F19: =IF(D19="","","кг") | H19: =IF(D19="","",IFERROR(G19,0)) | I19: =IF(D19="","",ROUND(H19*(1+IFERROR($M$11,0)),6)) | J19: =IF(D19="","",IF(AND(M19<>"",M19>0),M19,IFERROR(VLOOKUP(D19,'Полупродукты'!$C$6:$E$62,3,FALSE()),IFERROR(VLOOKUP(D19,'Сырьё'!$C$6:$E$233,3,FALSE()),0)))) | K19: =IF(D19="","",ROUND(IFERROR(I19*J19,0),2)) | L19: =IF(D19="","",ROUND(IFERROR(K19*$J$8,0),2)) | N19: GM2 | O19: 0.05 | P19: =ROUND(O19*$J$8,2) -> 4.18
B20: 4 | C20: =IF(D20="","",IF(ISNUMBER(MATCH(D20,'Полупродукты'!$C$6:$C$62,0)),"⚗️ Полупр.","Сырьё")) | F20: =IF(D20="","","кг") | H20: =IF(D20="","",IFERROR(G20,0)) | I20: =IF(D20="","",ROUND(H20*(1+IFERROR($M$11,0)),6)) | J20: =IF(D20="","",IF(AND(M20<>"",M20>0),M20,IFERROR(VLOOKUP(D20,'Полупродукты'!$C$6:$E$62,3,FALSE()),IFERROR(VLOOKUP(D20,'Сырьё'!$C$6:$E$233,3,FALSE()),0)))) | K20: =IF(D20="","",ROUND(IFERROR(I20*J20,0),2)) | L20: =IF(D20="","",ROUND(IFERROR(K20*$J$8,0),2)) | N20: КВ | O20: 0 | P20: =ROUND(O20*$J$8,2) -> 0
B21: 5 | C21: =IF(D21="","",IF(ISNUMBER(MATCH(D21,'Полупродукты'!$C$6:$C$62,0)),"⚗️ Полупр.","Сырьё")) | F21: =IF(D21="","","кг") | H21: =IF(D21="","",IFERROR(G21,0)) | I21: =IF(D21="","",ROUND(H21*(1+IFERROR($M$11,0)),6)) | J21: =IF(D21="","",IF(AND(M21<>"",M21>0),M21,IFERROR(VLOOKUP(D21,'Полупродукты'!$C$6:$E$62,3,FALSE()),IFERROR(VLOOKUP(D21,'Сырьё'!$C$6:$E$233,3,FALSE()),0)))) | K21: =IF(D21="","",ROUND(IFERROR(I21*J21,0),2)) | L21: =IF(D21="","",ROUND(IFERROR(K21*$J$8,0),2)) | N21: Прочие расходы | O21: 0 | P21: =ROUND(O21*$J$8,2) -> 0
B22: 6 | C22: =IF(D22="","",IF(ISNUMBER(MATCH(D22,'Полупродукты'!$C$6:$C$62,0)),"⚗️ Полупр.","Сырьё")) | F22: =IF(D22="","","кг") | H22: =IF(D22="","",IFERROR(G22,0)) | I22: =IF(D22="","",ROUND(H22*(1+IFERROR($M$11,0)),6)) | J22: =IF(D22="","",IF(AND(M22<>"",M22>0),M22,IFERROR(VLOOKUP(D22,'Полупродукты'!$C$6:$E$62,3,FALSE()),IFERROR(VLOOKUP(D22,'Сырьё'!$C$6:$E$233,3,FALSE()),0)))) | K22: =IF(D22="","",ROUND(IFERROR(I22*J22,0),2)) | L22: =IF(D22="","",ROUND(IFERROR(K22*$J$8,0),2)) | N22: Полная стоимость | O22: =ROUND(SUM(O17:O21),2) -> 0.15 | P22: =ROUND(O22*$J$8,2) -> 12.55
B23: 7 | C23: =IF(D23="","",IF(ISNUMBER(MATCH(D23,'Полупродукты'!$C$6:$C$62,0)),"⚗️ Полупр.","Сырьё")) | F23: =IF(D23="","","кг") | H23: =IF(D23="","",IFERROR(G23,0)) | I23: =IF(D23="","",ROUND(H23*(1+IFERROR($M$11,0)),6)) | J23: =IF(D23="","",IF(AND(M23<>"",M23>0),M23,IFERROR(VLOOKUP(D23,'Полупродукты'!$C$6:$E$62,3,FALSE()),IFERROR(VLOOKUP(D23,'Сырьё'!$C$6:$E$233,3,FALSE()),0)))) | K23: =IF(D23="","",ROUND(IFERROR(I23*J23,0),2)) | L23: =IF(D23="","",ROUND(IFERROR(K23*$J$8,0),2)) | N23: Наценка, % | O23: 0.2 | P23: =ROUND(O22*O23*$J$8,2) -> 2.51
B24: 8 | C24: =IF(D24="","",IF(ISNUMBER(MATCH(D24,'Полупродукты'!$C$6:$C$62,0)),"⚗️ Полупр.","Сырьё")) | F24: =IF(D24="","","кг") | H24: =IF(D24="","",IFERROR(G24,0)) | I24: =IF(D24="","",ROUND(H24*(1+IFERROR($M$11,0)),6)) | J24: =IF(D24="","",IF(AND(M24<>"",M24>0),M24,IFERROR(VLOOKUP(D24,'Полупродукты'!$C$6:$E$62,3,FALSE()),IFERROR(VLOOKUP(D24,'Сырьё'!$C$6:$E$233,3,FALSE()),0)))) | K24: =IF(D24="","",ROUND(IFERROR(I24*J24,0),2)) | L24: =IF(D24="","",ROUND(IFERROR(K24*$J$8,0),2)) | N24: Наценка, € | O24: =ROUND(O22*O23,2) -> 0.03 | P24: =ROUND(O24*$J$8,2) -> 2.51
B25: 9 | C25: =IF(D25="","",IF(ISNUMBER(MATCH(D25,'Полупродукты'!$C$6:$C$62,0)),"⚗️ Полупр.","Сырьё")) | F25: =IF(D25="","","кг") | H25: =IF(D25="","",IFERROR(G25,0)) | I25: =IF(D25="","",ROUND(H25*(1+IFERROR($M$11,0)),6)) | J25: =IF(D25="","",IF(AND(M25<>"",M25>0),M25,IFERROR(VLOOKUP(D25,'Полупродукты'!$C$6:$E$62,3,FALSE()),IFERROR(VLOOKUP(D25,'Сырьё'!$C$6:$E$233,3,FALSE()),0)))) | K25: =IF(D25="","",ROUND(IFERROR(I25*J25,0),2)) | L25: =IF(D25="","",ROUND(IFERROR(K25*$J$8,0),2))
B26: 10 | C26: =IF(D26="","",IF(ISNUMBER(MATCH(D26,'Полупродукты'!$C$6:$C$62,0)),"⚗️ Полупр.","Сырьё")) | F26: =IF(D26="","","кг") | H26: =IF(D26="","",IFERROR(G26,0)) | I26: =IF(D26="","",ROUND(H26*(1+IFERROR($M$11,0)),6)) | J26: =IF(D26="","",IF(AND(M26<>"",M26>0),M26,IFERROR(VLOOKUP(D26,'Полупродукты'!$C$6:$E$62,3,FALSE()),IFERROR(VLOOKUP(D26,'Сырьё'!$C$6:$E$233,3,FALSE()),0)))) | K26: =IF(D26="","",ROUND(IFERROR(I26*J26,0),2)) | L26: =IF(D26="","",ROUND(IFERROR(K26*$J$8,0),2)) | N26: ЦЕНА ДЛЯ КЛИЕНТА
B27: 11 | C27: =IF(D27="","",IF(ISNUMBER(MATCH(D27,'Полупродукты'!$C$6:$C$62,0)),"⚗️ Полупр.","Сырьё")) | F27: =IF(D27="","","кг") | H27: =IF(D27="","",IFERROR(G27,0)) | I27: =IF(D27="","",ROUND(H27*(1+IFERROR($M$11,0)),6)) | J27: =IF(D27="","",IF(AND(M27<>"",M27>0),M27,IFERROR(VLOOKUP(D27,'Полупродукты'!$C$6:$E$62,3,FALSE()),IFERROR(VLOOKUP(D27,'Сырьё'!$C$6:$E$233,3,FALSE()),0)))) | K27: =IF(D27="","",ROUND(IFERROR(I27*J27,0),2)) | L27: =IF(D27="","",ROUND(IFERROR(K27*$J$8,0),2)) | N27: с НДС | O27: =ROUND(O22*(1+O23),2) -> 0.18 | P27: =ROUND(O27*$J$8,2) -> 15.06
B28: 12 | C28: =IF(D28="","",IF(ISNUMBER(MATCH(D28,'Полупродукты'!$C$6:$C$62,0)),"⚗️ Полупр.","Сырьё")) | F28: =IF(D28="","","кг") | H28: =IF(D28="","",IFERROR(G28,0)) | I28: =IF(D28="","",ROUND(H28*(1+IFERROR($M$11,0)),6)) | J28: =IF(D28="","",IF(AND(M28<>"",M28>0),M28,IFERROR(VLOOKUP(D28,'Полупродукты'!$C$6:$E$62,3,FALSE()),IFERROR(VLOOKUP(D28,'Сырьё'!$C$6:$E$233,3,FALSE()),0)))) | K28: =IF(D28="","",ROUND(IFERROR(I28*J28,0),2)) | L28: =IF(D28="","",ROUND(IFERROR(K28*$J$8,0),2)) | N28: без НДС | O28: =ROUND(O27/(1+0.22),2) -> 0.15 | P28: =ROUND(O28*$J$8,2) -> 12.55
B29: 13 | C29: =IF(D29="","",IF(ISNUMBER(MATCH(D29,'Полупродукты'!$C$6:$C$62,0)),"⚗️ Полупр.","Сырьё")) | F29: =IF(D29="","","кг") | H29: =IF(D29="","",IFERROR(G29,0)) | I29: =IF(D29="","",ROUND(H29*(1+IFERROR($M$11,0)),6)) | J29: =IF(D29="","",IF(AND(M29<>"",M29>0),M29,IFERROR(VLOOKUP(D29,'Полупродукты'!$C$6:$E$62,3,FALSE()),IFERROR(VLOOKUP(D29,'Сырьё'!$C$6:$E$233,3,FALSE()),0)))) | K29: =IF(D29="","",ROUND(IFERROR(I29*J29,0),2)) | L29: =IF(D29="","",ROUND(IFERROR(K29*$J$8,0),2))
B30: 14 | C30: =IF(D30="","",IF(ISNUMBER(MATCH(D30,'Полупродукты'!$C$6:$C$62,0)),"⚗️ Полупр.","Сырьё")) | F30: =IF(D30="","","кг") | H30: =IF(D30="","",IFERROR(G30,0)) | I30: =IF(D30="","",ROUND(H30*(1+IFERROR($M$11,0)),6)) | J30: =IF(D30="","",IF(AND(M30<>"",M30>0),M30,IFERROR(VLOOKUP(D30,'Полупродукты'!$C$6:$E$62,3,FALSE()),IFERROR(VLOOKUP(D30,'Сырьё'!$C$6:$E$233,3,FALSE()),0)))) | K30: =IF(D30="","",ROUND(IFERROR(I30*J30,0),2)) | L30: =IF(D30="","",ROUND(IFERROR(K30*$J$8,0),2))
B31: 15 | C31: =IF(D31="","",IF(ISNUMBER(MATCH(D31,'Полупродукты'!$C$6:$C$62,0)),"⚗️ Полупр.","Сырьё")) | F31: =IF(D31="","","кг") | H31: =IF(D31="","",IFERROR(G31,0)) | I31: =IF(D31="","",ROUND(H31*(1+IFERROR($M$11,0)),6)) | J31: =IF(D31="","",IF(AND(M31<>"",M31>0),M31,IFERROR(VLOOKUP(D31,'Полупродукты'!$C$6:$E$62,3,FALSE()),IFERROR(VLOOKUP(D31,'Сырьё'!$C$6:$E$233,3,FALSE()),0)))) | K31: =IF(D31="","",ROUND(IFERROR(I31*J31,0),2)) | L31: =IF(D31="","",ROUND(IFERROR(K31*$J$8,0),2))
B32: 16 | C32: =IF(D32="","",IF(ISNUMBER(MATCH(D32,'Полупродукты'!$C$6:$C$62,0)),"⚗️ Полупр.","Сырьё")) | F32: =IF(D32="","","кг") | H32: =IF(D32="","",IFERROR(G32,0)) | I32: =IF(D32="","",ROUND(H32*(1+IFERROR($M$11,0)),6)) | J32: =IF(D32="","",IF(AND(M32<>"",M32>0),M32,IFERROR(VLOOKUP(D32,'Полупродукты'!$C$6:$E$62,3,FALSE()),IFERROR(VLOOKUP(D32,'Сырьё'!$C$6:$E$233,3,FALSE()),0)))) | K32: =IF(D32="","",ROUND(IFERROR(I32*J32,0),2)) | L32: =IF(D32="","",ROUND(IFERROR(K32*$J$8,0),2))
B33: 17 | C33: =IF(D33="","",IF(ISNUMBER(MATCH(D33,'Полупродукты'!$C$6:$C$62,0)),"⚗️ Полупр.","Сырьё")) | F33: =IF(D33="","","кг") | H33: =IF(D33="","",IFERROR(G33,0)) | I33: =IF(D33="","",ROUND(H33*(1+IFERROR($M$11,0)),6)) | J33: =IF(D33="","",IF(AND(M33<>"",M33>0),M33,IFERROR(VLOOKUP(D33,'Полупродукты'!$C$6:$E$62,3,FALSE()),IFERROR(VLOOKUP(D33,'Сырьё'!$C$6:$E$233,3,FALSE()),0)))) | K33: =IF(D33="","",ROUND(IFERROR(I33*J33,0),2)) | L33: =IF(D33="","",ROUND(IFERROR(K33*$J$8,0),2))
B34: 18 | C34: =IF(D34="","",IF(ISNUMBER(MATCH(D34,'Полупродукты'!$C$6:$C$62,0)),"⚗️ Полупр.","Сырьё")) | F34: =IF(D34="","","кг") | H34: =IF(D34="","",IFERROR(G34,0)) | I34: =IF(D34="","",ROUND(H34*(1+IFERROR($M$11,0)),6)) | J34: =IF(D34="","",IF(AND(M34<>"",M34>0),M34,IFERROR(VLOOKUP(D34,'Полупродукты'!$C$6:$E$62,3,FALSE()),IFERROR(VLOOKUP(D34,'Сырьё'!$C$6:$E$233,3,FALSE()),0)))) | K34: =IF(D34="","",ROUND(IFERROR(I34*J34,0),2)) | L34: =IF(D34="","",ROUND(IFERROR(K34*$J$8,0),2))
B35: 19 | C35: =IF(D35="","",IF(ISNUMBER(MATCH(D35,'Полупродукты'!$C$6:$C$62,0)),"⚗️ Полупр.","Сырьё")) | F35: =IF(D35="","","кг") | H35: =IF(D35="","",IFERROR(G35,0)) | I35: =IF(D35="","",ROUND(H35*(1+IFERROR($M$11,0)),6)) | J35: =IF(D35="","",IF(AND(M35<>"",M35>0),M35,IFERROR(VLOOKUP(D35,'Полупродукты'!$C$6:$E$62,3,FALSE()),IFERROR(VLOOKUP(D35,'Сырьё'!$C$6:$E$233,3,FALSE()),0)))) | K35: =IF(D35="","",ROUND(IFERROR(I35*J35,0),2)) | L35: =IF(D35="","",ROUND(IFERROR(K35*$J$8,0),2))
B36: 20 | C36: =IF(D36="","",IF(ISNUMBER(MATCH(D36,'Полупродукты'!$C$6:$C$62,0)),"⚗️ Полупр.","Сырьё")) | F36: =IF(D36="","","кг") | H36: =IF(D36="","",IFERROR(G36,0)) | I36: =IF(D36="","",ROUND(H36*(1+IFERROR($M$11,0)),6)) | J36: =IF(D36="","",IF(AND(M36<>"",M36>0),M36,IFERROR(VLOOKUP(D36,'Полупродукты'!$C$6:$E$62,3,FALSE()),IFERROR(VLOOKUP(D36,'Сырьё'!$C$6:$E$233,3,FALSE()),0)))) | K36: =IF(D36="","",ROUND(IFERROR(I36*J36,0),2)) | L36: =IF(D36="","",ROUND(IFERROR(K36*$J$8,0),2))
B37: Σ ИТОГО | H37: =SUM(H17:H36) -> 0 | K37: =ROUND(SUM(K17:K36),2) -> 0 | L37: =ROUND(SUM(L17:L36),2) -> 0
B40: 💡 Калькулятор X — новые продукты. B8: выбрать из списка или ввести своё. N — пред. цена €/кг (ручной ввод). K8 — авто из «Курсы ЦБ». Σ% (L15) контролируется.

Sheet Расчёт сырья
B2: 📋 Расчёт сырья для планирования закупок
B4: Введите продукты заявки в таблицу ниже (B7:B26) и количество в кг (C7:C26). В сводке справа автоматически рассчитается сырьё для закупки (полупродукты раскрываются до базового сырья).
B6: 📦 ЗАЯВКА КЛИЕНТА (ввод) | G6: 🛒 СВОДКА: СЫРЬЁ К ЗАКУПКЕ (авто, с потерями 3%)
A7: № | B7: Продукт | C7: Кол-во, кг | D7: €/кг б.НДС | E7: Сумма, € | G7: № | H7: Компонент | I7: Ед. | J7: Кол-во | K7: Цена €/ед. | L7: Сумма €
A8: 1 | B8: NSF/PC Cyan Blue (PB 15:3) | C8: 600 | D8: =IF(B8="","",SUMPRODUCT(('_Развёртки'!$A$2:$A$1361=B8)*'_Развёртки'!$F$2:$F$1361)) -> 3.7125966 | E8: =IF(OR(B8="",C8=""),"",C8*D8) -> 2227.558 | G8: 📦 ТАРА (упаковка)
A9: 2 | B9: Краска NSF/UNI Magenta (PR 57:1) TR VER 1.3 | C9: 1200 | D9: =IF(B9="","",SUMPRODUCT(('_Развёртки'!$A$2:$A$1361=B9)*'_Развёртки'!$F$2:$F$1361)) -> 3.5113175 | E9: =IF(OR(B9="",C9=""),"",C9*D9) -> 4213.581 | G9: 1 | H9: Бочка стальная 210 л. | I9: =IFERROR(VLOOKUP(H9,'Сырьё'!$C$6:$D$233,2,FALSE()),IFERROR(VLOOKUP(H9,'Полупродукты'!$C$6:$D$60,2,FALSE()),"кг")) -> кг | J9: {=IF(B8="",0,IFERROR(INDEX('_Развёртки'!$C$2:$C$1358,MATCH(B8&"|"&H9,'_Развёртки'!$D$2:$D$1358,0)),0)*N(C8))+IF(B9="",0,IFERROR(INDEX('_Развёртки'!$C$2:$C$1358,MATCH(B9&"|"&H9,'_Развёртки'!$D$2:$D$1358,0)),0)*N(C9))+IF(B10="",0,IFERROR(INDEX('_Развёртки'!$C$2:$C$1358,MATCH(B10&"|"&H9,'_Развёртки'!$D$2:$D$1358,0)),0)*N(C10))+IF(B11="",0,IFERROR(INDEX('_Развёртки'!$C$2:$C$1358,MATCH(B11&"|"&H9,'_Развёртки'!$D$2:$D$1358,0)),0)*N(C11))+IF(B12="",0,IFERROR(INDEX('_Развёртки'!$C$2:$C$1358,MATCH(B12&"|"&H9,'_Развёртки'!$D$2:$D$1358,0)),0)*N(C12))+IF(B13="",0,IFERROR(INDEX('_Развёртки'!$C$2:$C$1358,MATCH(B13&"|"&H9,'_Развёртки'!$D$2:$D$1358,0)),0)*N(C13))+IF(B14="",0,IFERROR(INDEX('_Развёртки'!$C$2:$C$1358,MATCH(B14&"|"&H9,'_Развёртки'!$D$2:$D$1358,0)),0)*N(C14))+IF(B15="",0,IFERROR(INDEX('_Развёртки'!$C$2:$C$1358,MATCH(B15&"|"&H9,'_Развёртки'!$D$2:$D$1358,0)),0)*N(C15))+IF(B16="",0,IFERROR(INDEX('_Развёртки'!$C$2:$C$1358,MATCH(B16&"|"&H9,'_Развёртки'!$D$2:$D$1358,0)),0)*N(C16))+IF(B17="",0,IFERROR(INDEX('_Развёртки'!$C$2:$C$1358,MATCH(B17&"|"&H9,'_Развёртки'!$D$2:$D$1358,0)),0)*N(C17))+IF(B18="",0,IFERROR(INDEX('_Развёртки'!$C$2:$C$1358,MATCH(B18&"|"&H9,'_Развёртки'!$D$2:$D$1358,0)),0)*N(C18))+IF(B19="",0,IFERROR(INDEX('_Развёртки'!$C$2:$C$1358,MATCH(B19&"|"&H9,'_Развёртки'!$D$2:$D$1358,0)),0)*N(C19))+IF(B20="",0,IFERROR(INDEX('_Развёртки'!$C$2:$C$1358,MATCH(B20&"|"&H9,'_Развёртки'!$D$2:$D$1358,0)),0)*N(C20))+IF(B21="",0,IFERROR(INDEX('_Развёртки'!$C$2:$C$1358,MATCH(B21&"|"&H9,'_Развёртки'!$D$2:$D$1358,0)),0)*N(C21))+IF(B22="",0,IFERROR(INDEX('_Развёртки'!$C$2:$C$1358,MATCH(B22&"|"&H9,'_Развёртки'!$D$2:$D$1358,0)),0)*N(C22))+IF(B23="",0,IFERROR(INDEX('_Развёртки'!$C$2:$C$1358,MATCH(B23&"|"&H9,'_Развёртки'!$D$2:$D$1358,0)),0)*N(C23))+IF(B24="",0,IFERROR(INDEX('_Развёртки'!$C$2:$C$1358,MATCH(B24&"|"&H9,'_Развёртки'!$D$2:$D$1358,0)),0)*N(C24))+IF(B25="",0,IFERROR(INDEX('_Развёртки'!$C$2:$C$1358,MATCH(B25&"|"&H9,'_Развёртки'!$D$2:$D$1358,0)),0)*N(C25))+IF(B26="",0,IFERROR(INDEX('_Развёртки'!$C$2:$C$1358,MATCH(B26&"|"&H9,'_Развёртки'!$D$2:$D$1358,0)),0)*N(C26))+IF(B27="",0,IFERROR(INDEX('_Развёртки'!$C$2:$C$1358,MATCH(B27&"|"&H9,'_Развёртки'!$D$2:$D$1358,0)),0)*N(C27))} -> 3.259 | K9: =IFERROR(VLOOKUP(H9,'Сырьё'!$C$6:$E$233,3,FALSE()),IFERROR(VLOOKUP(H9,'Полупродукты'!$C$6:$E$60,3,FALSE()),0)) -> 30.1527 | L9: =IF(J9=0,0,J9*K9) -> 98.267649
A10: 3 | B10: Orange (PO 34) | C10: 20 | D10: =IF(B10="","",SUMPRODUCT(('_Развёртки'!$A$2:$A$1361=B10)*'_Развёртки'!$F$2:$F$1361)) -> 3.7563635 | E10: =IF(OR(B10="",C10=""),"",C10*D10) -> 75.12727 | G10: 2 | H10: Ведро 25 л. | I10: =IFERROR(VLOOKUP(H10,'Сырьё'!$C$6:$D$233,2,FALSE()),IFERROR(VLOOKUP(H10,'Полупродукты'!$C$6:$D$60,2,FALSE()),"кг")) -> кг | J10: {=IF(B8="",0,IFERROR(INDEX('_Развёртки'!$C$2:$C$1358,MATCH(B8&"|"&H10,'_Развёртки'!$D$2:$D$1358,0)),0)*N(C8))+IF(B9="",0,IFERROR(INDEX('_Развёртки'!$C$2:$C$1358,MATCH(B9&"|"&H10,'_Развёртки'!$D$2:$D$1358,0)),0)*N(C9))+IF(B10="",0,IFERROR(INDEX('_Развёртки'!$C$2:$C$1358,MATCH(B10&"|"&H10,'_Развёртки'!$D$2:$D$1358,0)),0)*N(C10))+IF(B11="",0,IFERROR(INDEX('_Развёртки'!$C$2:$C$1358,MATCH(B11&"|"&H10,'_Развёртки'!$D$2:$D$1358,0)),0)*N(C11))+IF(B12="",0,IFERROR(INDEX('_Развёртки'!$C$2:$C$1358,MATCH(B12&"|"&H10,'_Развёртки'!$D$2:$D$1358,0)),0)*N(C12))+IF(B13="",0,IFERROR(INDEX('_Развёртки'!$C$2:$C$1358,MATCH(B13&"|"&H10,'_Развёртки'!$D$2:$D$1358,0)),0)*N(C13))+IF(B14="",0,IFERROR(INDEX('_Развёртки'!$C$2:$C$1358,MATCH(B14&"|"&H10,'_Развёртки'!$D$2:$D$1358,0)),0)*N(C14))+IF(B15="",0,IFERROR(INDEX('_Развёртки'!$C$2:$C$1358,MATCH(B15&"|"&H10,'_Развёртки'!$D$2:$D$1358,0)),0)*N(C15))+IF(B16="",0,IFERROR(INDEX('_Развёртки'!$C$2:$C$1358,MATCH(B16&"|"&H10,'_Развёртки'!$D$2:$D$1358,0)),0)*N(C16))+IF(B17="",0,IFERROR(INDEX('_Развёртки'!$C$2:$C$1358,MATCH(B17&"|"&H10,'_Развёртки'!$D$2:$D$1358,0)),0)*N(C17))+IF(B18="",0,IFERROR(INDEX('_Развёртки'!$C$2:$C$1358,MATCH(B18&"|"&H10,'_Развёртки'!$D$2:$D$1358,0)),0)*N(C18))+IF(B19="",0,IFERROR(INDEX('_Развёртки'!$C$2:$C$1358,MATCH(B19&"|"&H10,'_Развёртки'!$D$2:$D$1358,0)),0)*N(C19))+IF(B20="",0,IFERROR(INDEX('_Развёртки'!$C$2:$C$1358,MATCH(B20&"|"&H10,'_Развёртки'!$D$2:$D$1358,0)),0)*N(C20))+IF(B21="",0,IFERROR(INDEX('_Развёртки'!$C$2:$C$1358,MATCH(B21&"|"&H10,'_Развёртки'!$D$2:$D$1358,0)),0)*N(C21))+IF(B22="",0,IFERROR(INDEX('_Развёртки'!$C$2:$C$1358,MATCH(B22&"|"&H10,'_Развёртки'!$D$2:$D$1358,0)),0)*N(C22))+IF(B23="",0,IFERROR(INDEX('_Развёртки'!$C$2:$C$1358,MATCH(B23&"|"&H10,'_Развёртки'!$D$2:$D$1358,0)),0)*N(C23))+IF(B24="",0,IFERROR(INDEX('_Развёртки'!$C$2:$C$1358,MATCH(B24&"|"&H10,'_Развёртки'!$D$2:$D$1358,0)),0)*N(C24))+IF(B25="",0,IFERROR(INDEX('_Развёртки'!$C$2:$C$1358,MATCH(B25&"|"&H10,'_Развёртки'!$D$2:$D$1358,0)),0)*N(C25))+IF(B26="",0,IFERROR(INDEX('_Развёртки'!$C$2:$C$1358,MATCH(B26&"|"&H10,'_Развёртки'!$D$2:$D$1358,0)),0)*N(C26))+IF(B27="",0,IFERROR(INDEX('_Развёртки'!$C$2:$C$1358,MATCH(B27&"|"&H10,'_Развёртки'!$D$2:$D$1358,0)),0)*N(C27))} -> 145.04138 | K10: =IFERROR(VLOOKUP(H10,'Сырьё'!$C$6:$E$233,3,FALSE()),IFERROR(VLOOKUP(H10,'Полупродукты'!$C$6:$E$60,3,FALSE()),0)) -> 3.7834 | L10: =IF(J10=0,0,J10*K10) -> 548.74956
A11: 4 | B11: Warm Red (PR 53:1) | C11: 1200 | D11: =IF(B11="","",SUMPRODUCT(('_Развёртки'!$A$2:$A$1361=B11)*'_Развёртки'!$F$2:$F$1361)) -> 3.1645346 | E11: =IF(OR(B11="",C11=""),"",C11*D11) -> 3797.4416 | H11: Итого тары: | J11: =SUM(J9:J10) -> 148.30038 | L11: =SUM(L9:L10) -> 647.01721
A12: 5 | B12: Краска NSF/uni White (PW 6) AF35 | C12: 3500 | D12: =IF(B12="","",SUMPRODUCT(('_Развёртки'!$A$2:$A$1361=B12)*'_Развёртки'!$F$2:$F$1361)) -> 2.5218752 | E12: =IF(OR(B12="",C12=""),"",C12*D12) -> 8826.5631
A13: 6 | B13: Краска NSF/UNI Yellow (PY 13) TR VER 1.3 | C13: 1600 | D13: =IF(B13="","",SUMPRODUCT(('_Развёртки'!$A$2:$A$1361=B13)*'_Развёртки'!$F$2:$F$1361)) -> 1.7317047 | E13: =IF(OR(B13="",C13=""),"",C13*D13) -> 2770.7275 | G13: ⚗️ СЫРЬЁ (химия)
A14: 7 | B14: Black (PBl 7) / RASTR | C14: 300 | D14: =IF(B14="","",SUMPRODUCT(('_Развёртки'!$A$2:$A$1361=B14)*'_Развёртки'!$F$2:$F$1361)) -> 3.5118476 | E14: =IF(OR(B14="",C14=""),"",C14*D14) -> 1053.5543 | G14: 3 | H14: ASTRA11305 | I14: =IFERROR(VLOOKUP(H14,'Сырьё'!$C$6:$D$233,2,FALSE()),IFERROR(VLOOKUP(H14,'Полупродукты'!$C$6:$D$60,2,FALSE()),"кг")) -> кг | J14: {=IF(B8="",0,IFERROR(INDEX('_Развёртки'!$C$2:$C$1358,MATCH(B8&"|"&H14,'_Развёртки'!$D$2:$D$1358,0)),0)*N(C8))+IF(B9="",0,IFERROR(INDEX('_Развёртки'!$C$2:$C$1358,MATCH(B9&"|"&H14,'_Развёртки'!$D$2:$D$1358,0)),0)*N(C9))+IF(B10="",0,IFERROR(INDEX('_Развёртки'!$C$2:$C$1358,MATCH(B10&"|"&H14,'_Развёртки'!$D$2:$D$1358,0)),0)*N(C10))+IF(B11="",0,IFERROR(INDEX('_Развёртки'!$C$2:$C$1358,MATCH(B11&"|"&H14,'_Развёртки'!$D$2:$D$1358,0)),0)*N(C11))+IF(B12="",0,IFERROR(INDEX('_Развёртки'!$C$2:$C$1358,MATCH(B12&"|"&H14,'_Развёртки'!$D$2:$D$1358,0)),0)*N(C12))+IF(B13="",0,IFERROR(INDEX('_Развёртки'!$C$2:$C$1358,MATCH(B13&"|"&H14,'_Развёртки'!$D$2:$D$1358,0)),0)*N(C13))+IF(B14="",0,IFERROR(INDEX('_Развёртки'!$C$2:$C$1358,MATCH(B14&"|"&H14,'_Развёртки'!$D$2:$D$1358,0)),0)*N(C14))+IF(B15="",0,IFERROR(INDEX('_Развёртки'!$C$2:$C$1358,MATCH(B15&"|"&H14,'_Развёртки'!$D$2:$D$1358,0)),0)*N(C15))+IF(B16="",0,IFERROR(INDEX('_Развёртки'!$C$2:$C$1358,MATCH(B16&"|"&H14,'_Развёртки'!$D$2:$D$1358,0)),0)*N(C16))+IF(B17="",0,IFERROR(INDEX('_Развёртки'!$C$2:$C$1358,MATCH(B17&"|"&H14,'_Развёртки'!$D$2:$D$1358,0)),0)*N(C17))+IF(B18="",0,IFERROR(INDEX('_Развёртки'!$C$2:$C$1358,MATCH(B18&"|"&H14,'_Развёртки'!$D$2:$D$1358,0)),0)*N(C18))+IF(B19="",0,IFERROR(INDEX('_Развёртки'!$C$2:$C$1358,MATCH(B19&"|"&H14,'_Развёртки'!$D$2:$D$1358,0)),0)*N(C19))+IF(B20="",0,IFERROR(INDEX('_Развёртки'!$C$2:$C$1358,MATCH(B20&"|"&H14,'_Развёртки'!$D$2:$D$1358,0)),0)*N(C20))+IF(B21="",0,IFERROR(INDEX('_Развёртки'!$C$2:$C$1358,MATCH(B21&"|"&H14,'_Развёртки'!$D$2:$D$1358,0)),0)*N(C21))+IF(B22="",0,IFERROR(INDEX('_Развёртки'!$C$2:$C$1358,MATCH(B22&"|"&H14,'_Развёртки'!$D$2:$D$1358,0)),0)*N(C22))+IF(B23="",0,IFERROR(INDEX('_Развёртки'!$C$2:$C$1358,MATCH(B23&"|"&H14,'_Развёртки'!$D$2:$D$1358,0)),0)*N(C23))+IF(B24="",0,IFERROR(INDEX('_Развёртки'!$C$2:$C$1358,MATCH(B24&"|"&H14,'_Развёртки'!$D$2:$D$1358,0)),0)*N(C24))+IF(B25="",0,IFERROR(INDEX('_Развёртки'!$C$2:$C$1358,MATCH(B25&"|"&H14,'_Развёртки'!$D$2:$D$1358,0)),0)*N(C25))+IF(B26="",0,IFERROR(INDEX('_Развёртки'!$C$2:$C$1358,MATCH(B26&"|"&H14,'_Развёртки'!$D$2:$D$1358,0)),0)*N(C26))+IF(B27="",0,IFERROR(INDEX('_Развёртки'!$C$2:$C$1358,MATCH(B27&"|"&H14,'_Развёртки'!$D$2:$D$1358,0)),0)*N(C27))} -> 0 | K14: =IFERROR(VLOOKUP(H14,'Сырьё'!$C$6:$E$233,3,FALSE()),IFERROR(VLOOKUP(H14,'Полупродукты'!$C$6:$E$60,3,FALSE()),0)) -> 0 | L14: =IF(J14=0,0,J14*K14) -> 0
A15: 8 | B15: Краска NSF/LAM Cyan Blue (PB 15:3) | C15: 60 | D15: =IF(B15="","",SUMPRODUCT(('_Развёртки'!$A$2:$A$1361=B15)*'_Развёртки'!$F$2:$F$1361)) -> 4.0520045 | E15: =IF(OR(B15="",C15=""),"",C15*D15) -> 243.12027 | G15: 4 | H15: ASTRA11306 | I15: =IFERROR(VLOOKUP(H15,'Сырьё'!$C$6:$D$233,2,FALSE()),IFERROR(VLOOKUP(H15,'Полупродукты'!$C$6:$D$60,2,FALSE()),"кг")) -> кг | J15: {=IF(B8="",0,IFERROR(INDEX('_Развёртки'!$C$2:$C$1358,MATCH(B8&"|"&H15,'_Развёртки'!$D$2:$D$1358,0)),0)*N(C8))+IF(B9="",0,IFERROR(INDEX('_Развёртки'!$C$2:$C$1358,MATCH(B9&"|"&H15,'_Развёртки'!$D$2:$D$1358,0)),0)*N(C9))+IF(B10="",0,IFERROR(INDEX('_Развёртки'!$C$2:$C$1358,MATCH(B10&"|"&H15,'_Развёртки'!$D$2:$D$1358,0)),0)*N(C10))+IF(B11="",0,IFERROR(INDEX('_Развёртки'!$C$2:$C$1358,MATCH(B11&"|"&H15,'_Развёртки'!$D$2:$D$1358,0)),0)*N(C11))+IF(B12="",0,IFERROR(INDEX('_Развёртки'!$C$2:$C$1358,MATCH(B12&"|"&H15,'_Развёртки'!$D$2:$D$1358,0)),0)*N(C12))+IF(B13="",0,IFERROR(INDEX('_Развёртки'!$C$2:$C$1358,MATCH(B13&"|"&H15,'_Развёртки'!$D$2:$D$1358,0)),0)*N(C13))+IF(B14="",0,IFERROR(INDEX('_Развёртки'!$C$2:$C$1358,MATCH(B14&"|"&H15,'_Развёртки'!$D$2:$D$1358,0)),0)*N(C14))+IF(B15="",0,IFERROR(INDEX('_Развёртки'!$C$2:$C$1358,MATCH(B15&"|"&H15,'_Развёртки'!$D$2:$D$1358,0)),0)*N(C15))+IF(B16="",0,IFERROR(INDEX('_Развёртки'!$C$2:$C$1358,MATCH(B16&"|"&H15,'_Развёртки'!$D$2:$D$1358,0)),0)*N(C16))+IF(B17="",0,IFERROR(INDEX('_Развёртки'!$C$2:$C$1358,MATCH(B17&"|"&H15,'_Развёртки'!$D$2:$D$1358,0)),0)*N(C17))+IF(B18="",0,IFERROR(INDEX('_Развёртки'!$C$2:$C$1358,MATCH(B18&"|"&H15,'_Развёртки'!$D$2:$D$1358,0)),0)*N(C18))+IF(B19="",0,IFERROR(INDEX('_Развёртки'!$C$2:$C$1358,MATCH(B19&"|"&H15,'_Развёртки'!$D$2:$D$1358,0)),0)*N(C19))+IF(B20="",0,IFERROR(INDEX('_Развёртки'!$C$2:$C$1358,MATCH(B20&"|"&H15,'_Развёртки'!$D$2:$D$1358,0)),0)*N(C20))+IF(B21="",0,IFERROR(INDEX('_Развёртки'!$C$2:$C$1358,MATCH(B21&"|"&H15,'_Развёртки'!$D$2:$D$1358,0)),0)*N(C21))+IF(B22="",0,IFERROR(INDEX('_Развёртки'!$C$2:$C$1358,MATCH(B22&"|"&H15,'_Развёртки'!$D$2:$D$1358,0)),0)*N(C22))+IF(B23="",0,IFERROR(INDEX('_Развёртки'!$C$2:$C$1358,MATCH(B23&"|"&H15,'_Развёртки'!$D$2:$D$1358,0)),0)*N(C23))+IF(B24="",0,IFERROR(INDEX('_Развёртки'!$C$2:$C$1358,MATCH(B24&"|"&H15,'_Развёртки'!$D$2:$D$1358,0)),0)*N(C24))+IF(B25="",0,IFERROR(INDEX('_Развёртки'!$C$2:$C$1358,MATCH(B25&"|"&H15,'_Развёртки'!$D$2:$D$1358,0)),0)*N(C25))+IF(B26="",0,IFERROR(INDEX('_Развёртки'!$C$2:$C$1358,MATCH(B26&"|"&H15,'_Развёртки'!$D$2:$D$1358,0)),0)*N(C26))+IF(B27="",0,IFERROR(INDEX('_Развёртки'!$C$2:$C$1358,MATCH(B27&"|"&H15,'_Развёртки'!$D$2:$D$1358,0)),0)*N(C27))} -> 0 | K15: =IFERROR(VLOOKUP(H15,'Сырьё'!$C$6:$E$233,3,FALSE()),IFERROR(VLOOKUP(H15,'Полупродукты'!$C$6:$E$60,3,FALSE()),0)) -> 0 | L15: =IF(J15=0,0,J15*K15) -> 0
A16: 9 | B16: Лак LAM Extender плашка, | C16: 600 | D16: =IF(B16="","",SUMPRODUCT(('_Развёртки'!$A$2:$A$1361=B16)*'_Развёртки'!$F$2:$F$1361)) -> 2.7766843 | E16: =IF(OR(B16="",C16=""),"",C16*D16) -> 1666.0106 | G16: 5 | H16: DOA Plasticiser | I16: =IFERROR(VLOOKUP(H16,'Сырьё'!$C$6:$D$233,2,FALSE()),IFERROR(VLOOKUP(H16,'Полупродукты'!$C$6:$D$60,2,FALSE()),"кг")) -> кг | J16: {=IF(B8="",0,IFERROR(INDEX('_Развёртки'!$C$2:$C$1358,MATCH(B8&"|"&H16,'_Развёртки'!$D$2:$D$1358,0)),0)*N(C8))+IF(B9="",0,IFERROR(INDEX('_Развёртки'!$C$2:$C$1358,MATCH(B9&"|"&H16,'_Развёртки'!$D$2:$D$1358,0)),0)*N(C9))+IF(B10="",0,IFERROR(INDEX('_Развёртки'!$C$2:$C$1358,MATCH(B10&"|"&H16,'_Развёртки'!$D$2:$D$1358,0)),0)*N(C10))+IF(B11="",0,IFERROR(INDEX('_Развёртки'!$C$2:$C$1358,MATCH(B11&"|"&H16,'_Развёртки'!$D$2:$D$1358,0)),0)*N(C11))+IF(B12="",0,IFERROR(INDEX('_Развёртки'!$C$2:$C$1358,MATCH(B12&"|"&H16,'_Развёртки'!$D$2:$D$1358,0)),0)*N(C12))+IF(B13="",0,IFERROR(INDEX('_Развёртки'!$C$2:$C$1358,MATCH(B13&"|"&H16,'_Развёртки'!$D$2:$D$1358,0)),0)*N(C13))+IF(B14="",0,IFERROR(INDEX('_Развёртки'!$C$2:$C$1358,MATCH(B14&"|"&H16,'_Развёртки'!$D$2:$D$1358,0)),0)*N(C14))+IF(B15="",0,IFERROR(INDEX('_Развёртки'!$C$2:$C$1358,MATCH(B15&"|"&H16,'_Развёртки'!$D$2:$D$1358,0)),0)*N(C15))+IF(B16="",0,IFERROR(INDEX('_Развёртки'!$C$2:$C$1358,MATCH(B16&"|"&H16,'_Развёртки'!$D$2:$D$1358,0)),0)*N(C16))+IF(B17="",0,IFERROR(INDEX('_Развёртки'!$C$2:$C$1358,MATCH(B17&"|"&H16,'_Развёртки'!$D$2:$D$1358,0)),0)*N(C17))+IF(B18="",0,IFERROR(INDEX('_Развёртки'!$C$2:$C$1358,MATCH(B18&"|"&H16,'_Развёртки'!$D$2:$D$1358,0)),0)*N(C18))+IF(B19="",0,IFERROR(INDEX('_Развёртки'!$C$2:$C$1358,MATCH(B19&"|"&H16,'_Развёртки'!$D$2:$D$1358,0)),0)*N(C19))+IF(B20="",0,IFERROR(INDEX('_Развёртки'!$C$2:$C$1358,MATCH(B20&"|"&H16,'_Развёртки'!$D$2:$D$1358,0)),0)*N(C20))+IF(B21="",0,IFERROR(INDEX('_Развёртки'!$C$2:$C$1358,MATCH(B21&"|"&H16,'_Развёртки'!$D$2:$D$1358,0)),0)*N(C21))+IF(B22="",0,IFERROR(INDEX('_Развёртки'!$C$2:$C$1358,MATCH(B22&"|"&H16,'_Развёртки'!$D$2:$D$1358,0)),0)*N(C22))+IF(B23="",0,IFERROR(INDEX('_Развёртки'!$C$2:$C$1358,MATCH(B23&"|"&H16,'_Развёртки'!$D$2:$D$1358,0)),0)*N(C23))+IF(B24="",0,IFERROR(INDEX('_Развёртки'!$C$2:$C$1358,MATCH(B24&"|"&H16,'_Развёртки'!$D$2:$D$1358,0)),0)*N(C24))+IF(B25="",0,IFERROR(INDEX('_Развёртки'!$C$2:$C$1358,MATCH(B25&"|"&H16,'_Развёртки'!$D$2:$D$1358,0)),0)*N(C25))+IF(B26="",0,IFERROR(INDEX('_Развёртки'!$C$2:$C$1358,MATCH(B26&"|"&H16,'_Развёртки'!$D$2:$D$1358,0)),0)*N(C26))+IF(B27="",0,IFERROR(INDEX('_Развёртки'!$C$2:$C$1358,MATCH(B27&"|"&H16,'_Развёртки'!$D$2:$D$1358,0)),0)*N(C27))} -> 68.21192 | K16: =IFERROR(VLOOKUP(H16,'Сырьё'!$C$6:$E$233,3,FALSE()),IFERROR(VLOOKUP(H16,'Полупродукты'!$C$6:$E$60,3,FALSE()),0)) -> 2.337 | L16: =IF(J16=0,0,J16*K16) -> 159.41126
A17: 10 | B17: INK Orange (PO 34) LAM | C17: 20 | D17: =IF(B17="","",SUMPRODUCT(('_Развёртки'!$A$2:$A$1361=B17)*'_Развёртки'!$F$2:$F$1361)) -> 4.2233609 | E17: =IF(OR(B17="",C17=""),"",C17*D17) -> 84.467218 | G17: 6 | H17: Dromide 957 | I17: =IFERROR(VLOOKUP(H17,'Сырьё'!$C$6:$D$233,2,FALSE()),IFERROR(VLOOKUP(H17,'Полупродукты'!$C$6:$D$60,2,FALSE()),"кг")) -> кг | J17: {=IF(B8="",0,IFERROR(INDEX('_Развёртки'!$C$2:$C$1358,MATCH(B8&"|"&H17,'_Развёртки'!$D$2:$D$1358,0)),0)*N(C8))+IF(B9="",0,IFERROR(INDEX('_Развёртки'!$C$2:$C$1358,MATCH(B9&"|"&H17,'_Развёртки'!$D$2:$D$1358,0)),0)*N(C9))+IF(B10="",0,IFERROR(INDEX('_Развёртки'!$C$2:$C$1358,MATCH(B10&"|"&H17,'_Развёртки'!$D$2:$D$1358,0)),0)*N(C10))+IF(B11="",0,IFERROR(INDEX('_Развёртки'!$C$2:$C$1358,MATCH(B11&"|"&H17,'_Развёртки'!$D$2:$D$1358,0)),0)*N(C11))+IF(B12="",0,IFERROR(INDEX('_Развёртки'!$C$2:$C$1358,MATCH(B12&"|"&H17,'_Развёртки'!$D$2:$D$1358,0)),0)*N(C12))+IF(B13="",0,IFERROR(INDEX('_Развёртки'!$C$2:$C$1358,MATCH(B13&"|"&H17,'_Развёртки'!$D$2:$D$1358,0)),0)*N(C13))+IF(B14="",0,IFERROR(INDEX('_Развёртки'!$C$2:$C$1358,MATCH(B14&"|"&H17,'_Развёртки'!$D$2:$D$1358,0)),0)*N(C14))+IF(B15="",0,IFERROR(INDEX('_Развёртки'!$C$2:$C$1358,MATCH(B15&"|"&H17,'_Развёртки'!$D$2:$D$1358,0)),0)*N(C15))+IF(B16="",0,IFERROR(INDEX('_Развёртки'!$C$2:$C$1358,MATCH(B16&"|"&H17,'_Развёртки'!$D$2:$D$1358,0)),0)*N(C16))+IF(B17="",0,IFERROR(INDEX('_Развёртки'!$C$2:$C$1358,MATCH(B17&"|"&H17,'_Развёртки'!$D$2:$D$1358,0)),0)*N(C17))+IF(B18="",0,IFERROR(INDEX('_Развёртки'!$C$2:$C$1358,MATCH(B18&"|"&H17,'_Развёртки'!$D$2:$D$1358,0)),0)*N(C18))+IF(B19="",0,IFERROR(INDEX('_Развёртки'!$C$2:$C$1358,MATCH(B19&"|"&H17,'_Развёртки'!$D$2:$D$1358,0)),0)*N(C19))+IF(B20="",0,IFERROR(INDEX('_Развёртки'!$C$2:$C$1358,MATCH(B20&"|"&H17,'_Развёртки'!$D$2:$D$1358,0)),0)*N(C20))+IF(B21="",0,IFERROR(INDEX('_Развёртки'!$C$2:$C$1358,MATCH(B21&"|"&H17,'_Развёртки'!$D$2:$D$1358,0)),0)*N(C21))+IF(B22="",0,IFERROR(INDEX('_Развёртки'!$C$2:$C$1358,MATCH(B22&"|"&H17,'_Развёртки'!$D$2:$D$1358,0)),0)*N(C22))+IF(B23="",0,IFERROR(INDEX('_Развёртки'!$C$2:$C$1358,MATCH(B23&"|"&H17,'_Развёртки'!$D$2:$D$1358,0)),0)*N(C23))+IF(B24="",0,IFERROR(INDEX('_Развёртки'!$C$2:$C$1358,MATCH(B24&"|"&H17,'_Развёртки'!$D$2:$D$1358,0)),0)*N(C24))+IF(B25="",0,IFERROR(INDEX('_Развёртки'!$C$2:$C$1358,MATCH(B25&"|"&H17,'_Развёртки'!$D$2:$D$1358,0)),0)*N(C25))+IF(B26="",0,IFERROR(INDEX('_Развёртки'!$C$2:$C$1358,MATCH(B26&"|"&H17,'_Развёртки'!$D$2:$D$1358,0)),0)*N(C26))+IF(B27="",0,IFERROR(INDEX('_Развёртки'!$C$2:$C$1358,MATCH(B27&"|"&H17,'_Развёртки'!$D$2:$D$1358,0)),0)*N(C27))} -> 0 | K17: =IFERROR(VLOOKUP(H17,'Сырьё'!$C$6:$E$233,3,FALSE()),IFERROR(VLOOKUP(H17,'Полупродукты'!$C$6:$E$60,3,FALSE()),0)) -> 6.305 | L17: =IF(J17=0,0,J17*K17) -> 0
