Workbook

Sheet сентябрь 2024- июнь 2026
A1: Дата передачи материалов | B1: Дата выпуска продукции | C1: курс | D1: № ЗП | E1: Продукт | F1: Вес готового продукта | G1: Израсходовано по факту | H1: Израсходовано по факту Polyether Polyol Puranol, Пропиленгликоль | I1: Потери, кг | J1: % потерь | K1: СС 1С на дату выпуска, EUR | L1: % пропиленгликоля в составе | M1: СС КГ, РУБ, Б/НДС | N1: СС Факт , EUR, Б/НДС | O1: СС Партии, EUR, Б/НДС | P1: СС Партии, РУБ, Б/НДС | R1: Примечание
A2: 45537 | B2: 45538 | C2: =VLOOKUP(B:B,'Курс валют'!A:D,4,0) -> 99.2613 | D2: 632 | E2: Отвердитель Starkbond 525C 2.0 Бочка 200 кг | F2: 3200 | G2: 3208.4 | H2: 0 | I2: =G2-F2 -> 8.4 | J2: =I2/F2*100 -> 0.2625 | K2: 3.43 | L2: =H2/F2*100 -> 0 | M2: =P2/F2 -> 340.46626 | N2: =(F2*K2-H2*3.04)/F2 -> 3.43 | O2: =N2*F2 -> 10976 | P2: =O2*C2 -> 1089492
A3: 45538 | B3: 45538 | C3: =VLOOKUP(B:B,'Курс валют'!A:D,4,0) -> 99.2613 | D3: 631 | E3: Клей Starkbond 2014 бочка 225кг | F3: 900 | G3: 927 | H3: 368 | I3: =G3-F3 -> 27 | J3: =I3/F3*100 -> 3 | K3: 3.24 | L3: =H3/F3*100 -> 40.888889 | M3: =P3/F3 -> 198.22261 | N3: =(F3*K3-H3*3.04)/F3 -> 1.9969778 | O3: =N3*F3 -> 1797.28 | P3: =O3*C3 -> 178400.35
A4: 45538 | B4: 45539 | C4: =VLOOKUP(B:B,'Курс валют'!A:D,4,0) -> 97.8121 | D4: 624 | E4: Клей Starkbond 745/41 А (бочка 200 кг) | F4: 1000 | G4: 1038 | H4: 219 | I4: =G4-F4 -> 38 | J4: =I4/F4*100 -> 3.8 | K4: 3.25 | L4: =H4/F4*100 -> 21.9 | M4: =P4/F4 -> 252.76994 | N4: =(F4*K4-H4*3.04)/F4 -> 2.58424 | O4: =N4*F4 -> 2584.24 | P4: =O4*C4 -> 252769.94
A5: 45538 | B5: 45539 | C5: =VLOOKUP(B:B,'Курс валют'!A:D,4,0) -> 97.8121 | D5: 633 | E5: Отвердитель Starkbond 525C 2.0 Бочка 200 кг | F5: 1600 | G5: 1624.2 | H5: 0 | I5: =G5-F5 -> 24.2 | J5: =I5/F5*100 -> 1.5125 | K5: 3.41 | L5: =H5/F5*100 -> 0 | M5: =P5/F5 -> 333.53926 | N5: =(F5*K5-H5*3.04)/F5 -> 3.41 | O5: =N5*F5 -> 5456 | P5: =O5*C5 -> 533662.82
A6: 45538 | B6: 45539 | C6: =VLOOKUP(B:B,'Курс валют'!A:D,4,0) -> 97.8121 | D6: 634 | E6: Клей Starkbond 521A ведро 22 кг | F6: 220 | G6: 220 | H6: 0 | I6: =G6-F6 -> 0 | J6: =I6/F6*100 -> 0 | K6: 4.09 | L6: =H6/F6*100 -> 0 | M6: =P6/F6 -> 400.05149 | N6: =(F6*K6-H6*3.04)/F6 -> 4.09 | O6: =N6*F6 -> 899.8 | P6: =O6*C6 -> 88011.328 | R6: перелив
A7: 45538 | B7: 45539 | C7: =VLOOKUP(B:B,'Курс валют'!A:D,4,0) -> 97.8121 | D7: 635 | E7: Отвердитель Starkbond 521C 10.0 ведро 11кг | F7: 198 | G7: 200 | H7: 0 | I7: =G7-F7 -> 2 | J7: =I7/F7*100 -> 1.010101 | K7: 2.26 | L7: =H7/F7*100 -> 0 | M7: =P7/F7 -> 221.05535 | N7: =(F7*K7-H7*3.04)/F7 -> 2.26 | O7: =N7*F7 -> 447.48 | P7: =O7*C7 -> 43768.959 | R7: перелив
A8: 45539 | B8: 45540 | C8: =VLOOKUP(B:B,'Курс валют'!A:D,4,0) -> 98.0725 | D8: 636 | E8: Клей Starkbond 2014 бочка 225кг | F8: 900 | G8: 935.5 | H8: 365 | I8: =G8-F8 -> 35.5 | J8: =I8/F8*100 -> 3.9444444 | K8: 3.27 | L8: =H8/F8*100 -> 40.555556 | M8: =P8/F8 -> 199.78458 | N8: =(F8*K8-H8*3.04)/F8 -> 2.0371111 | O8: =N8*F8 -> 1833.4 | P8: =O8*C8 -> 179806.12
A9: 45539 | B9: 45540 | C9: =VLOOKUP(B:B,'Курс валют'!A:D,4,0) -> 98.0725 | D9: 637 | E9: клей Starkbond 521 A бочка 220кг | F9: 6600 | G9: 6616 | H9: 3025 | I9: =G9-F9 -> 16 | J9: =I9/F9*100 -> 0.24242424 | K9: 3.87 | L9: =H9/F9*100 -> 45.833333 | M9: =P9/F9 -> 242.89289 | N9: =(F9*K9-H9*3.04)/F9 -> 2.4766667 | O9: =N9*F9 -> 16346 | P9: =O9*C9 -> 1603093.1
A10: 45539 | B10: 45540 | C10: =VLOOKUP(B:B,'Курс валют'!A:D,4,0) -> 98.0725 | D10: 638 | E10: Клей Starkbond 2014 бочка 225кг | F10: 900 | G10: 935 | H10: 365 | I10: =G10-F10 -> 35 | J10: =I10/F10*100 -> 3.8888889 | K10: 3.27 | L10: =H10/F10*100 -> 40.555556 | M10: =P10/F10 -> 199.78458 | N10: =(F10*K10-H10*3.04)/F10 -> 2.0371111 | O10: =N10*F10 -> 1833.4 | P10: =O10*C10 -> 179806.12
A11: 45540 | B11: 45540 | C11: =VLOOKUP(B:B,'Курс валют'!A:D,4,0) -> 98.0725 | D11: 640 | E11: отвердитель Starkbond 746/1 С ведро 20кг | F11: 120 | G11: 120 | H11: 0 | I11: =G11-F11 -> 0 | J11: =I11/F11*100 -> 0 | K11: 2.91 | L11: =H11/F11*100 -> 0 | M11: =P11/F11 -> 285.39098 | N11: =(F11*K11-H11*3.04)/F11 -> 2.91 | O11: =N11*F11 -> 349.2 | P11: =O11*C11 -> 34246.917 | R11: перелив
A12: 45541 | B12: 45544 | C12: =VLOOKUP(B:B,'Курс валют'!A:D,4,0) -> 99.7156 | D12: 641 | E12: Клей Starkbond 2014 бочка 225кг | F12: 900 | G12: 931.28 | H12: 365 | I12: =G12-F12 -> 31.28 | J12: =I12/F12*100 -> 3.4755556 | K12: 3.26 | L12: =H12/F12*100 -> 40.555556 | M12: =P12/F12 -> 202.1346 | N12: =(F12*K12-H12*3.04)/F12 -> 2.0271111 | O12: =N12*F12 -> 1824.4 | P12: =O12*C12 -> 181921.14
A13: 45541 | B13: 45544 | C13: =VLOOKUP(B:B,'Курс валют'!A:D,4,0) -> 99.7156 | D13: 642 | E13: Отвердитель Starkbond 521C 10.0 бочка 200кг | F13: 8000 | G13: 8010.5 | H13: 0 | I13: =G13-F13 -> 10.5 | J13: =I13/F13*100 -> 0.13125 | K13: 1.95 | L13: =H13/F13*100 -> 0 | M13: =P13/F13 -> 194.44542 | N13: =(F13*K13-H13*3.04)/F13 -> 1.95 | O13: =N13*F13 -> 15600 | P13: =O13*C13 -> 1555563.4
A14: 45541 | B14: 45544 | C14: =VLOOKUP(B:B,'Курс валют'!A:D,4,0) -> 99.7156 | D14: 643 | E14: Клей Starkbond 2014 бочка 225кг | F14: 900 | G14: 935.72 | H14: 365 | I14: =G14-F14 -> 35.72 | J14: =I14/F14*100 -> 3.9688889 | K14: 3.26 | L14: =H14/F14*100 -> 40.555556 | M14: =P14/F14 -> 202.1346 | N14: =(F14*K14-H14*3.04)/F14 -> 2.0271111 | O14: =N14*F14 -> 1824.4 | P14: =O14*C14 -> 181921.14
A15: 45541 | B15: 45544 | C15: =VLOOKUP(B:B,'Курс валют'!A:D,4,0) -> 99.7156 | D15: 644 | E15: отвердитель Starkbond 525C 3.0 ведро 20кг | F15: 200 | G15: 208 | H15: 0 | I15: =G15-F15 -> 8 | J15: =I15/F15*100 -> 4 | K15: 3.46 | L15: =H15/F15*100 -> 0 | M15: =P15/F15 -> 345.01598 | N15: =(F15*K15-H15*3.04)/F15 -> 3.46 | O15: =N15*F15 -> 692 | P15: =O15*C15 -> 69003.195
A16: 45541 | B16: 45544 | C16: =VLOOKUP(B:B,'Курс валют'!A:D,4,0) -> 99.7156 | D16: 645 | E16: Отвердитель Starkbond 521C 10.0 бочка 200кг | F16: 8000 | G16: 8010.5 | H16: 0 | I16: =G16-F16 -> 10.5 | J16: =I16/F16*100 -> 0.13125 | K16: 1.95 | L16: =H16/F16*100 -> 0 | M16: =P16/F16 -> 194.44542 | N16: =(F16*K16-H16*3.04)/F16 -> 1.95 | O16: =N16*F16 -> 15600 | P16: =O16*C16 -> 1555563.4
A17: 45541 | B17: 45544 | C17: =VLOOKUP(B:B,'Курс валют'!A:D,4,0) -> 99.7156 | D17: 646 | E17: Отвердитель Starkbond 521C 10.0 бочка 200кг | F17: 8000 | G17: 8020.5 | H17: 0 | I17: =G17-F17 -> 20.5 | J17: =I17/F17*100 -> 0.25625 | K17: 1.95 | L17: =H17/F17*100 -> 0 | M17: =P17/F17 -> 194.44542 | N17: =(F17*K17-H17*3.04)/F17 -> 1.95 | O17: =N17*F17 -> 15600 | P17: =O17*C17 -> 1555563.4
A18: 45542 | B18: 45545 | C18: =VLOOKUP(B:B,'Курс валют'!A:D,4,0) -> 99.9067 | D18: 647 | E18: Клей Starkbond 525A бочка 220 кг и ведро 22 кг | F18: 1100 | G18: 1137 | H18: 577 | I18: =G18-F18 -> 37 | J18: =I18/F18*100 -> 3.3636364 | K18: 4.05 | L18: =H18/F18*100 -> 52.454545 | M18: =P18/F18 -> 245.30909 | N18: =(F18*K18-H18*3.04)/F18 -> 2.4553818 | O18: =N18*F18 -> 2700.92 | P18: =O18*C18 -> 269840
A19: 45542 | B19: 45545 | C19: =VLOOKUP(B:B,'Курс валют'!A:D,4,0) -> 99.9067 | D19: 648 | E19: Клей Starkbond 522A бочка 220 кг | F19: 6600 | G19: 6620 | H19: 2750 | I19: =G19-F19 -> 20 | J19: =I19/F19*100 -> 0.3030303 | K19: 3.86 | L19: =H19/F19*100 -> 41.666667 | M19: =P19/F19 -> 259.09138 | N19: =(F19*K19-H19*3.04)/F19 -> 2.5933333 | O19: =N19*F19 -> 17116 | P19: =O19*C19 -> 1710003.1
A20: 45542 | B20: 45545 | C20: =VLOOKUP(B:B,'Курс валют'!A:D,4,0) -> 99.9067 | D20: 649 | E20: отвердитель Starkbond 525C 2.0 ведро 20кг | F20: 186 | G20: 200 | H20: 0 | I20: =G20-F20 -> 14 | J20: =I20/F20*100 -> 7.5268817 | K20: 3.94 | L20: =H20/F20*100 -> 0 | M20: =P20/F20 -> 393.6324 | N20: =(F20*K20-H20*3.04)/F20 -> 3.94 | O20: =N20*F20 -> 732.84 | P20: =O20*C20 -> 73215.626 | R20: перелив
A21: 45545 | B21: 45545 | C21: =VLOOKUP(B:B,'Курс валют'!A:D,4,0) -> 99.9067 | D21: 650 | E21: Клей Starkbond 522A бочка 220 кг | F21: 6600 | G21: 6620 | H21: 2750 | I21: =G21-F21 -> 20 | J21: =I21/F21*100 -> 0.3030303 | K21: 3.86 | L21: =H21/F21*100 -> 41.666667 | M21: =P21/F21 -> 259.09138 | N21: =(F21*K21-H21*3.04)/F21 -> 2.5933333 | O21: =N21*F21 -> 17116 | P21: =O21*C21 -> 1710003.1
A22: 45545 | B22: 45545 | C22: =VLOOKUP(B:B,'Курс валют'!A:D,4,0) -> 99.9067 | D22: 651 | E22: отвердитель Starkbond 746/1 С ведро 20кг | F22: 200 | G22: 200 | H22: 0 | I22: =G22-F22 -> 0 | J22: =I22/F22*100 -> 0 | K22: 2.79 | L22: =H22/F22*100 -> 0 | M22: =P22/F22 -> 278.73969 | N22: =(F22*K22-H22*3.04)/F22 -> 2.79 | O22: =N22*F22 -> 558 | P22: =O22*C22 -> 55747.939 | R22: перелив
A23: 45546 | B23: 45546 | C23: =VLOOKUP(B:B,'Курс валют'!A:D,4,0) -> 100.4995 | D23: 653 | E23: Клей Starkbond 745/41 А (бочка 200 кг) | F23: 1000 | G23: 1041 | H23: 220 | I23: =G23-F23 -> 41 | J23: =I23/F23*100 -> 4.1 | K23: 3.3 | L23: =H23/F23*100 -> 22 | M23: =P23/F23 -> 264.43428 | N23: =(F23*K23-H23*3.04)/F23 -> 2.6312 | O23: =N23*F23 -> 2631.2 | P23: =O23*C23 -> 264434.28
A24: 45546 | B24: 45547 | C24: =VLOOKUP(B:B,'Курс валют'!A:D,4,0) -> 100.7421 | D24: 654 | E24: Клей Starkbond 745/41 А (бочка 200 кг) | F24: 1000 | G24: 1030 | H24: 215 | I24: =G24-F24 -> 30 | J24: =I24/F24*100 -> 3 | K24: 3.28 | L24: =H24/F24*100 -> 21.5 | M24: =P24/F24 -> 264.58905 | N24: =(F24*K24-H24*3.04)/F24 -> 2.6264 | O24: =N24*F24 -> 2626.4 | P24: =O24*C24 -> 264589.05
A25: 45546 | B25: 45545 | C25: =VLOOKUP(B:B,'Курс валют'!A:D,4,0) -> 99.9067 | D25: 655 | E25: отвердитель Starkbond 746/1 С ведро 20кг | F25: 200 | G25: 200 | H25: 0 | I25: =G25-F25 -> 0 | J25: =I25/F25*100 -> 0 | K25: 2.79 | L25: =H25/F25*100 -> 0 | M25: =P25/F25 -> 278.73969 | N25: =(F25*K25-H25*3.04)/F25 -> 2.79 | O25: =N25*F25 -> 558 | P25: =O25*C25 -> 55747.939 | R25: перелив
A26: 45547 | B26: 45547 | C26: =VLOOKUP(B:B,'Курс валют'!A:D,4,0) -> 100.7421 | D26: 656 | E26: клей Starkbond 521 A бочка 220кг | F26: 6600 | G26: 6630 | H26: 3030 | I26: =G26-F26 -> 30 | J26: =I26/F26*100 -> 0.45454545 | K26: 4.24 | L26: =H26/F26*100 -> 45.909091 | M26: =P26/F26 -> 286.54717 | N26: =(F26*K26-H26*3.04)/F26 -> 2.8443636 | O26: =N26*F26 -> 18772.8 | P26: =O26*C26 -> 1891211.3
A27: 45540 | B27: 45541 | C27: =VLOOKUP(B:B,'Курс валют'!A:D,4,0) -> 99.1927 | D27: 639 | E27: клей Starkbond 521 A бочка 220кг | F27: 6600 | G27: 6615 | H27: 3015 | I27: =G27-F27 -> 15 | J27: =I27/F27*100 -> 0.22727273 | K27: 4.22 | L27: =H27/F27*100 -> 45.681818 | M27: =P27/F27 -> 280.84159 | N27: =(F27*K27-H27*3.04)/F27 -> 2.8312727 | O27: =N27*F27 -> 18686.4 | P27: =O27*C27 -> 1853554.5
A28: 45546 | B28: 45546 | C28: =VLOOKUP(B:B,'Курс валют'!A:D,4,0) -> 100.4995 | D28: 652 | E28: клей Starkbond 521 A бочка 220кг | F28: 6600 | G28: 6620 | H28: 3020 | I28: =G28-F28 -> 20 | J28: =I28/F28*100 -> 0.3030303 | K28: 4.2 | L28: =H28/F28*100 -> 45.757576 | M28: =P28/F28 -> 282.30005 | N28: =(F28*K28-H28*3.04)/F28 -> 2.8089697 | O28: =N28*F28 -> 18539.2 | P28: =O28*C28 -> 1863180.3
A29: 45547 | B29: 45547 | C29: =VLOOKUP(B:B,'Курс валют'!A:D,4,0) -> 100.7421 | D29: 657 | E29: Клей Starkbond 745/41 А (бочка 200 кг) | F29: 1000 | G29: 1040 | H29: 220 | I29: =G29-F29 -> 40 | J29: =I29/F29*100 -> 4 | K29: 3.28 | L29: =H29/F29*100 -> 22 | M29: =P29/F29 -> 263.05777 | N29: =(F29*K29-H29*3.04)/F29 -> 2.6112 | O29: =N29*F29 -> 2611.2 | P29: =O29*C29 -> 263057.77
A30: 45548 | B30: 45548 | C30: =VLOOKUP(B:B,'Курс валют'!A:D,4,0) -> 100.3907 | D30: 658 | E30: Клей Starkbond 522A бочка 220 кг | F30: 6600 | G30: 6620 | H30: 2750 | I30: =G30-F30 -> 20 | J30: =I30/F30*100 -> 0.3030303 | K30: 3.86 | L30: =H30/F30*100 -> 41.666667 | M30: =P30/F30 -> 260.34655 | N30: =(F30*K30-H30*3.04)/F30 -> 2.5933333 | O30: =N30*F30 -> 17116 | P30: =O30*C30 -> 1718287.2
A31: 45548 | B31: 45548 | C31: =VLOOKUP(B:B,'Курс валют'!A:D,4,0) -> 100.3907 | D31: 659 | E31: Клей Starkbond 745/41 А (бочка 200 кг) | F31: 1000 | G31: 1030 | H31: 240 | I31: =G31-F31 -> 30 | J31: =I31/F31*100 -> 3 | K31: 3.33 | L31: =H31/F31*100 -> 24 | M31: =P31/F31 -> 261.05598 | N31: =(F31*K31-H31*3.04)/F31 -> 2.6004 | O31: =N31*F31 -> 2600.4 | P31: =O31*C31 -> 261055.98
A32: 45548 | B32: 45551 | C32: =VLOOKUP(B:B,'Курс валют'!A:D,4,0) -> 100.7958 | D32: 660 | E32: Клей Starkbond 522A бочка 220 кг | F32: 6600 | G32: 6620 | H32: 2750 | I32: =G32-F32 -> 20 | J32: =I32/F32*100 -> 0.3030303 | K32: 3.86 | L32: =H32/F32*100 -> 41.666667 | M32: =P32/F32 -> 261.39711 | N32: =(F32*K32-H32*3.04)/F32 -> 2.5933333 | O32: =N32*F32 -> 17116 | P32: =O32*C32 -> 1725220.9
A33: 45548 | B33: 45551 | C33: =VLOOKUP(B:B,'Курс валют'!A:D,4,0) -> 100.7958 | D33: 661 | E33: Starkbond 2004 бочка 225 кг | F33: 900 | G33: 951 | H33: 500 | I33: =G33-F33 -> 51 | J33: =I33/F33*100 -> 5.6666667 | K33: 3.79 | L33: =H33/F33*100 -> 55.555556 | M33: =P33/F33 -> 211.78318 | N33: =(F33*K33-H33*3.04)/F33 -> 2.1011111 | O33: =N33*F33 -> 1891 | P33: =O33*C33 -> 190604.86
A34: 45548 | B34: 45551 | C34: =VLOOKUP(B:B,'Курс валют'!A:D,4,0) -> 100.7958 | D34: 662 | E34: Starkbond 2004 бочка 225 кг | F34: 900 | G34: 927 | H34: 500 | I34: =G34-F34 -> 27 | J34: =I34/F34*100 -> 3 | K34: 3.79 | L34: =H34/F34*100 -> 55.555556 | M34: =P34/F34 -> 211.78318 | N34: =(F34*K34-H34*3.04)/F34 -> 2.1011111 | O34: =N34*F34 -> 1891 | P34: =O34*C34 -> 190604.86
A35: 45548 | B35: 45551 | C35: =VLOOKUP(B:B,'Курс валют'!A:D,4,0) -> 100.7958 | D35: 663 | E35: клей Starkbond 521 A бочка 220кг | F35: 4400 | G35: 4410 | H35: 2010 | I35: =G35-F35 -> 10 | J35: =I35/F35*100 -> 0.22727273 | K35: 4.23 | L35: =H35/F35*100 -> 45.681818 | M35: =P35/F35 -> 286.38836 | N35: =(F35*K35-H35*3.04)/F35 -> 2.8412727 | O35: =N35*F35 -> 12501.6 | P35: =O35*C35 -> 1260108.8
A36: 45548 | B36: 45548 | C36: =VLOOKUP(B:B,'Курс валют'!A:D,4,0) -> 100.3907 | D36: 664 | E36: Отвердитель Starkbond 521C 11.0 бочка 200кг | F36: 1600 | G36: 1564.2 | H36: 0 | I36: =G36-F36 -> -35.8 | J36: =I36/F36*100 -> -2.2375 | K36: 1.94 | L36: =H36/F36*100 -> 0 | M36: =P36/F36 -> 194.75796 | N36: =(F36*K36-H36*3.04)/F36 -> 1.94 | O36: =N36*F36 -> 3104 | P36: =O36*C36 -> 311612.73
A37: 45548 | B37: 45551 | C37: =VLOOKUP(B:B,'Курс валют'!A:D,4,0) -> 100.7958 | D37: 665 | E37: Starkbond 2004 бочка 225 кг | F37: 900 | G37: 929 | H37: 500 | I37: =G37-F37 -> 29 | J37: =I37/F37*100 -> 3.2222222 | K37: 3.79 | L37: =H37/F37*100 -> 55.555556 | M37: =P37/F37 -> 211.78318 | N37: =(F37*K37-H37*3.04)/F37 -> 2.1011111 | O37: =N37*F37 -> 1891 | P37: =O37*C37 -> 190604.86
... A56: 45558 | B56: 45558 | C56: =VLOOKUP(B:B,'Курс валют'!A:D,4,0) -> 103.3773 | D56: 684 | E56: клей Starkbond 521 A бочка 220кг | F56: 6600 | G56: 6615 | H56: 3020 | I56: =G56-F56 -> 15 | J56: =I56/F56*100 -> 0.22727273 | K56: 3.87 | L56: =H56/F56*100 -> 45.757576 | M56: =P56/F56 -> 256.26919 | N56: =(F56*K56-H56*3.04)/F56 -> 2.4789697 | O56: =N56*F56 -> 16361.2 | P56: =O56*C56 -> 1691376.7
A57: 45558 | B57: 45558 | C57: =VLOOKUP(B:B,'Курс валют'!A:D,4,0) -> 103.3773 | D57: 685 | E57: отвердитель Starkbond 746 С ведро 20кг | F57: 220 | G57: 220 | H57: 0 | I57: =G57-F57 -> 0 | J57: =I57/F57*100 -> 0 | K57: 2.83 | L57: =H57/F57*100 -> 0 | M57: =P57/F57 -> 292.55776 | N57: =(F57*K57-H57*3.04)/F57 -> 2.83 | O57: =N57*F57 -> 622.6 | P57: =O57*C57 -> 64362.707 | R57: перелив
A58: 45559 | B58: 45560 | C58: =VLOOKUP(B:B,'Курс валют'!A:D,4,0) -> 103.41 | D58: 686 | E58: клей Starkbond 521 A бочка 220кг | F58: 6600 | G58: 6615 | H58: 3020 | I58: =G58-F58 -> 15 | J58: =I58/F58*100 -> 0.22727273 | K58: 3.87 | L58: =H58/F58*100 -> 45.757576 | M58: =P58/F58 -> 256.35026 | N58: =(F58*K58-H58*3.04)/F58 -> 2.4789697 | O58: =N58*F58 -> 16361.2 | P58: =O58*C58 -> 1691911.7
...

Sheet Курс валют
A1: 45536 | B1: 1 | C1: EUR | D1: 100.7622 | E1: RUB
A2: 45537 | B2: 1 | C2: EUR | D2: 100.7622 | E2: RUB
A3: 45538 | B3: 1 | C3: EUR | D3: 99.2613 | E3: RUB
A4: 45539 | B4: 1 | C4: EUR | D4: 97.8121 | E4: RUB
A5: 45540 | B5: 1 | C5: EUR | D5: 98.0725 | E5: RUB
A6: 45541 | B6: 1 | C6: EUR | D6: 99.1927 | E6: RUB
A7: 45542 | B7: 1 | C7: EUR | D7: 99.7156 | E7: RUB
A8: 45543 | B8: 1 | C8: EUR | D8: 99.7156 | E8: RUB
A9: 45544 | B9: 1 | C9: EUR | D9: 99.7156 | E9: RUB
A10: 45545 | B10: 1 | C10: EUR | D10: 99.9067 | E10: RUB
A11: 45546 | B11: 1 | C11: EUR | D11: 100.4995 | E11: RUB
A12: 45547 | B12: 1 | C12: EUR | D12: 100.7421 | E12: RUB
... A460: 45997 | B460: 1 | C460: EUR | D460: 88.7028 | E460: RUB
A461: 45998 | B461: 1 | C461: EUR | D461: 88.7028 | E461: RUB | F461: 93.5626
A462: 45999 | B462: 1 | C462: EUR | D462: 88.7028 | E462: RUB
A463: 46000 | B463: 1 | C463: EUR | D463: 89.7054 | E463: RUB
A464: 46001 | B464: 1 | C464: EUR | D464: 89.4267 | E464: RUB
A465: 46002 | B465: 1 | C465: EUR | D465: 91.3806 | E465: RUB
A466: 46003 | B466: 1 | C466: EUR | D466: 92.9384 | E466: RUB
A467: 46004 | B467: 1 | C467: EUR | D467: 93.5626 | E467: RUB
A468: 46005 | B468: 1 | C468: EUR | D468: 93.5626 | E468: RUB
A469: 46006 | B469: 1 | C469: EUR | D469: 93.5626 | E469: RUB
A470: 46007 | B470: 1 | C470: EUR | D470: 93.2274 | E470: RUB
A471: 46008 | B471: 1 | C471: EUR | D471: 93.8054 | E471: RUB
A472: 46009 | B472: 1 | C472: EUR | D472: 94.1478 | E472: RUB
A473: 46010 | B473: 1 | C473: EUR | D473: 94.2524 | E473: RUB
... A665: 46202 | B665: 1 | C665: EUR | D665: 87.4027 | E665: RUB
A666: 46203 | B666: 1 | C666: EUR
A667: 46204 | B667: 1 | C667: EUR
A668: 46205 | B668: 1 | C668: EUR
A669: 46206 | B669: 1 | C669: EUR
A670: 46207 | B670: 1 | C670: EUR
A671: 46208 | B671: 1 | C671: EUR
A672: 46209 | B672: 1 | C672: EUR
A673: 46210 | B673: 1 | C673: EUR
A674: 46211 | B674: 1 | C674: EUR
A675: 46212
A676: 46213

Sheet Формула Среднего
A1: Продукт | B1: Сентябрь 24 | C1: Октябрь 24 | D1: Ноябрь 24 | E1: Декабрь 24 | F1: Январь 25 | G1: Февраль 2025 | H1: Март 25 | I1: Апрель 25 | J1: Май 25 | K1: Июнь 25 | L1: Июль 25 | M1: Август 25 | N1: Сентябрь 25 | O1: Октябрь 25 | P1: Ноябрь 25 | Q1: Декабрь 25 | R1: Январь 26 | S1: Февраль 26 | T1: Март 26 | U1: Апрель 2026 | V1: Май 2026 | W1: Июнь 2026 | X1: Июль 2026
A2: Отвердитель Starkbond 521C 10.0 бочка 200кг | B2: =IFERROR(AVERAGEIFS('сентябрь 2024- июнь 2026'!$K:$K,'сентябрь 2024- июнь 2026'!$E:$E,$A:$A),"-") -> 1.9593443 | C2: =IFERROR(AVERAGEIFS(#REF!,#REF!,$A:$A),"-") -> - | D2: =IFERROR(AVERAGEIFS(#REF!,#REF!,$A:$A),"-") -> - | E2: =IFERROR(AVERAGEIFS(#REF!,#REF!,$A:$A),"-") -> - | F2: =IFERROR(AVERAGEIFS(#REF!,#REF!,$A:$A),"-") -> - | G2: =IFERROR(AVERAGEIFS(#REF!,#REF!,A:A),"-") -> - | H2: =IFERROR(AVERAGEIFS(#REF!,#REF!,$A:$A),"-") -> - | I2: =IFERROR(AVERAGEIFS(#REF!,#REF!,$A:$A),"-") -> - | J2: =IFERROR(AVERAGEIFS(#REF!,#REF!,$A:$A),"-") -> - | K2: =IFERROR(AVERAGEIFS(#REF!,#REF!,$A:$A),"-") -> - | L2: =IFERROR(AVERAGEIFS(#REF!,#REF!,$A:$A),"-") -> - | M2: =IFERROR(AVERAGEIFS(#REF!,#REF!,$A:$A),"-") -> - | N2: =IFERROR(AVERAGEIFS(#REF!,#REF!,$A:$A),"-") -> - | O2: =IFERROR(AVERAGEIFS(#REF!,#REF!,$A:$A),"-") -> - | ... W2: =IFERROR(AVERAGEIFS(#REF!,#REF!,$A:$A),"-") -> - | X2: =IFERROR(AVERAGEIFS('[1]Июль 2026'!$K:$K,'[1]Июль 2026'!$E:$E,$A:$A),"-") -> -
A3: клей Starkbond 521 A бочка 220кг | B3: =IFERROR(AVERAGEIFS('сентябрь 2024- июнь 2026'!$K:$K,'сентябрь 2024- июнь 2026'!$E:$E,$A:$A),"-") -> 3.585498 | C3: =IFERROR(AVERAGEIFS(#REF!,#REF!,$A:$A),"-") -> - | D3: =IFERROR(AVERAGEIFS(#REF!,#REF!,$A:$A),"-") -> - | E3: =IFERROR(AVERAGEIFS(#REF!,#REF!,$A:$A),"-") -> - | F3: =IFERROR(AVERAGEIFS(#REF!,#REF!,$A:$A),"-") -> - | G3: =IFERROR(AVERAGEIFS(#REF!,#REF!,A:A),"-") -> - | H3: =IFERROR(AVERAGEIFS(#REF!,#REF!,$A:$A),"-") -> - | I3: =IFERROR(AVERAGEIFS(#REF!,#REF!,$A:$A),"-") -> - | J3: =IFERROR(AVERAGEIFS(#REF!,#REF!,$A:$A),"-") -> - | K3: =IFERROR(AVERAGEIFS(#REF!,#REF!,$A:$A),"-") -> - | L3: =IFERROR(AVERAGEIFS(#REF!,#REF!,$A:$A),"-") -> - | M3: =IFERROR(AVERAGEIFS(#REF!,#REF!,$A:$A),"-") -> - | N3: =IFERROR(AVERAGEIFS(#REF!,#REF!,$A:$A),"-") -> - | O3: =IFERROR(AVERAGEIFS(#REF!,#REF!,$A:$A),"-") -> - | ... W3: =IFERROR(AVERAGEIFS(#REF!,#REF!,$A:$A),"-") -> - | X3: =IFERROR(AVERAGEIFS('[1]Июль 2026'!$K:$K,'[1]Июль 2026'!$E:$E,$A:$A),"-") -> -
A4: Отвердитель Starkbond 521C 11.0 бочка 200кг | B4: =IFERROR(AVERAGEIFS('сентябрь 2024- июнь 2026'!$K:$K,'сентябрь 2024- июнь 2026'!$E:$E,$A:$A),"-") -> 1.9477291 | C4: =IFERROR(AVERAGEIFS(#REF!,#REF!,$A:$A),"-") -> - | D4: =IFERROR(AVERAGEIFS(#REF!,#REF!,$A:$A),"-") -> - | E4: =IFERROR(AVERAGEIFS(#REF!,#REF!,$A:$A),"-") -> - | F4: =IFERROR(AVERAGEIFS(#REF!,#REF!,$A:$A),"-") -> - | G4: =IFERROR(AVERAGEIFS(#REF!,#REF!,A:A),"-") -> - | H4: =IFERROR(AVERAGEIFS(#REF!,#REF!,$A:$A),"-") -> - | I4: =IFERROR(AVERAGEIFS(#REF!,#REF!,$A:$A),"-") -> - | J4: =IFERROR(AVERAGEIFS(#REF!,#REF!,$A:$A),"-") -> - | K4: =IFERROR(AVERAGEIFS(#REF!,#REF!,$A:$A),"-") -> - | L4: =IFERROR(AVERAGEIFS(#REF!,#REF!,$A:$A),"-") -> - | M4: =IFERROR(AVERAGEIFS(#REF!,#REF!,$A:$A),"-") -> - | N4: =IFERROR(AVERAGEIFS(#REF!,#REF!,$A:$A),"-") -> - | O4: =IFERROR(AVERAGEIFS(#REF!,#REF!,$A:$A),"-") -> - | ... W4: =IFERROR(AVERAGEIFS(#REF!,#REF!,$A:$A),"-") -> - | X4: =IFERROR(AVERAGEIFS('[1]Июль 2026'!$K:$K,'[1]Июль 2026'!$E:$E,$A:$A),"-") -> -
A5: отвердитель Starkbond 746/1 С бочка 200кг | B5: =IFERROR(AVERAGEIFS('сентябрь 2024- июнь 2026'!$K:$K,'сентябрь 2024- июнь 2026'!$E:$E,$A:$A),"-") -> 2.7052941 | C5: =IFERROR(AVERAGEIFS(#REF!,#REF!,$A:$A),"-") -> - | D5: =IFERROR(AVERAGEIFS(#REF!,#REF!,$A:$A),"-") -> - | E5: =IFERROR(AVERAGEIFS(#REF!,#REF!,$A:$A),"-") -> - | F5: =IFERROR(AVERAGEIFS(#REF!,#REF!,$A:$A),"-") -> - | G5: =IFERROR(AVERAGEIFS(#REF!,#REF!,A:A),"-") -> - | H5: =IFERROR(AVERAGEIFS(#REF!,#REF!,$A:$A),"-") -> - | I5: =IFERROR(AVERAGEIFS(#REF!,#REF!,$A:$A),"-") -> - | J5: =IFERROR(AVERAGEIFS(#REF!,#REF!,$A:$A),"-") -> - | K5: =IFERROR(AVERAGEIFS(#REF!,#REF!,$A:$A),"-") -> - | L5: =IFERROR(AVERAGEIFS(#REF!,#REF!,$A:$A),"-") -> - | M5: =IFERROR(AVERAGEIFS(#REF!,#REF!,$A:$A),"-") -> - | N5: =IFERROR(AVERAGEIFS(#REF!,#REF!,$A:$A),"-") -> - | O5: =IFERROR(AVERAGEIFS(#REF!,#REF!,$A:$A),"-") -> - | ... W5: =IFERROR(AVERAGEIFS(#REF!,#REF!,$A:$A),"-") -> - | X5: =IFERROR(AVERAGEIFS('[1]Июль 2026'!$K:$K,'[1]Июль 2026'!$E:$E,$A:$A),"-") -> -
A6: Отвердитель Starkbond 525C 2.0 Бочка 200 кг | B6: =IFERROR(AVERAGEIFS('сентябрь 2024- июнь 2026'!$K:$K,'сентябрь 2024- июнь 2026'!$E:$E,$A:$A),"-") -> 3.27125 | C6: =IFERROR(AVERAGEIFS(#REF!,#REF!,$A:$A),"-") -> - | D6: =IFERROR(AVERAGEIFS(#REF!,#REF!,$A:$A),"-") -> - | E6: =IFERROR(AVERAGEIFS(#REF!,#REF!,$A:$A),"-") -> - | F6: =IFERROR(AVERAGEIFS(#REF!,#REF!,$A:$A),"-") -> - | G6: =IFERROR(AVERAGEIFS(#REF!,#REF!,A:A),"-") -> - | H6: =IFERROR(AVERAGEIFS(#REF!,#REF!,$A:$A),"-") -> - | I6: =IFERROR(AVERAGEIFS(#REF!,#REF!,$A:$A),"-") -> - | J6: =IFERROR(AVERAGEIFS(#REF!,#REF!,$A:$A),"-") -> - | K6: =IFERROR(AVERAGEIFS(#REF!,#REF!,$A:$A),"-") -> - | L6: =IFERROR(AVERAGEIFS(#REF!,#REF!,$A:$A),"-") -> - | M6: =IFERROR(AVERAGEIFS(#REF!,#REF!,$A:$A),"-") -> - | N6: =IFERROR(AVERAGEIFS(#REF!,#REF!,$A:$A),"-") -> - | O6: =IFERROR(AVERAGEIFS(#REF!,#REF!,$A:$A),"-") -> - | ... W6: =IFERROR(AVERAGEIFS(#REF!,#REF!,$A:$A),"-") -> - | X6: =IFERROR(AVERAGEIFS('[1]Июль 2026'!$K:$K,'[1]Июль 2026'!$E:$E,$A:$A),"-") -> -
A7: Отвердитель Starkbond 525C 3.0 Бочка 200 кг | B7: =IFERROR(AVERAGEIFS('сентябрь 2024- июнь 2026'!$K:$K,'сентябрь 2024- июнь 2026'!$E:$E,$A:$A),"-") -> 2.7321739 | C7: =IFERROR(AVERAGEIFS(#REF!,#REF!,$A:$A),"-") -> - | D7: =IFERROR(AVERAGEIFS(#REF!,#REF!,$A:$A),"-") -> - | E7: =IFERROR(AVERAGEIFS(#REF!,#REF!,$A:$A),"-") -> - | F7: =IFERROR(AVERAGEIFS(#REF!,#REF!,$A:$A),"-") -> - | G7: =IFERROR(AVERAGEIFS(#REF!,#REF!,A:A),"-") -> - | H7: =IFERROR(AVERAGEIFS(#REF!,#REF!,$A:$A),"-") -> - | I7: =IFERROR(AVERAGEIFS(#REF!,#REF!,$A:$A),"-") -> - | J7: =IFERROR(AVERAGEIFS(#REF!,#REF!,$A:$A),"-") -> - | K7: =IFERROR(AVERAGEIFS(#REF!,#REF!,$A:$A),"-") -> - | L7: =IFERROR(AVERAGEIFS(#REF!,#REF!,$A:$A),"-") -> - | M7: =IFERROR(AVERAGEIFS(#REF!,#REF!,$A:$A),"-") -> - | N7: =IFERROR(AVERAGEIFS(#REF!,#REF!,$A:$A),"-") -> - | O7: =IFERROR(AVERAGEIFS(#REF!,#REF!,$A:$A),"-") -> - | ... W7: =IFERROR(AVERAGEIFS(#REF!,#REF!,$A:$A),"-") -> - | X7: =IFERROR(AVERAGEIFS('[1]Июль 2026'!$K:$K,'[1]Июль 2026'!$E:$E,$A:$A),"-") -> -
A8: отвердитель Starkbond 525C v0 (ведро 22 кг) | B8: =IFERROR(AVERAGEIFS('сентябрь 2024- июнь 2026'!$K:$K,'сентябрь 2024- июнь 2026'!$E:$E,$A:$A),"-") -> 2.86 | C8: =IFERROR(AVERAGEIFS(#REF!,#REF!,$A:$A),"-") -> - | D8: =IFERROR(AVERAGEIFS(#REF!,#REF!,$A:$A),"-") -> - | E8: =IFERROR(AVERAGEIFS(#REF!,#REF!,$A:$A),"-") -> - | F8: =IFERROR(AVERAGEIFS(#REF!,#REF!,$A:$A),"-") -> - | G8: =IFERROR(AVERAGEIFS(#REF!,#REF!,A:A),"-") -> - | H8: =IFERROR(AVERAGEIFS(#REF!,#REF!,$A:$A),"-") -> - | I8: =IFERROR(AVERAGEIFS(#REF!,#REF!,$A:$A),"-") -> - | J8: =IFERROR(AVERAGEIFS(#REF!,#REF!,$A:$A),"-") -> - | K8: =IFERROR(AVERAGEIFS(#REF!,#REF!,$A:$A),"-") -> - | L8: =IFERROR(AVERAGEIFS(#REF!,#REF!,$A:$A),"-") -> - | M8: =IFERROR(AVERAGEIFS(#REF!,#REF!,$A:$A),"-") -> - | N8: =IFERROR(AVERAGEIFS(#REF!,#REF!,$A:$A),"-") -> - | O8: =IFERROR(AVERAGEIFS(#REF!,#REF!,$A:$A),"-") -> - | ... W8: =IFERROR(AVERAGEIFS(#REF!,#REF!,$A:$A),"-") -> - | X8: =IFERROR(AVERAGEIFS('[1]Июль 2026'!$K:$K,'[1]Июль 2026'!$E:$E,$A:$A),"-") -> -
A9: Клей Starkbond 745/41 А (бочка 200 кг) | B9: =IFERROR(AVERAGEIFS('сентябрь 2024- июнь 2026'!$K:$K,'сентябрь 2024- июнь 2026'!$E:$E,$A:$A),"-") -> 2.7238333 | C9: =IFERROR(AVERAGEIFS(#REF!,#REF!,$A:$A),"-") -> - | D9: =IFERROR(AVERAGEIFS(#REF!,#REF!,$A:$A),"-") -> - | E9: =IFERROR(AVERAGEIFS(#REF!,#REF!,$A:$A),"-") -> - | F9: =IFERROR(AVERAGEIFS(#REF!,#REF!,$A:$A),"-") -> - | G9: =IFERROR(AVERAGEIFS(#REF!,#REF!,A:A),"-") -> - | H9: =IFERROR(AVERAGEIFS(#REF!,#REF!,$A:$A),"-") -> - | I9: =IFERROR(AVERAGEIFS(#REF!,#REF!,$A:$A),"-") -> - | J9: =IFERROR(AVERAGEIFS(#REF!,#REF!,$A:$A),"-") -> - | K9: =IFERROR(AVERAGEIFS(#REF!,#REF!,$A:$A),"-") -> - | L9: =IFERROR(AVERAGEIFS(#REF!,#REF!,$A:$A),"-") -> - | M9: =IFERROR(AVERAGEIFS(#REF!,#REF!,$A:$A),"-") -> - | N9: =IFERROR(AVERAGEIFS(#REF!,#REF!,$A:$A),"-") -> - | O9: =IFERROR(AVERAGEIFS(#REF!,#REF!,$A:$A),"-") -> - | ... W9: =IFERROR(AVERAGEIFS(#REF!,#REF!,$A:$A),"-") -> - | X9: =IFERROR(AVERAGEIFS('[1]Июль 2026'!$K:$K,'[1]Июль 2026'!$E:$E,$A:$A),"-") -> -
A10: Клей Starkbond 525A бочка 200 кг | B10: =IFERROR(AVERAGEIFS('сентябрь 2024- июнь 2026'!$K:$K,'сентябрь 2024- июнь 2026'!$E:$E,$A:$A),"-") -> 3.1417241 | C10: =IFERROR(AVERAGEIFS(#REF!,#REF!,$A:$A),"-") -> - | D10: =IFERROR(AVERAGEIFS(#REF!,#REF!,$A:$A),"-") -> - | E10: =IFERROR(AVERAGEIFS(#REF!,#REF!,$A:$A),"-") -> - | F10: =IFERROR(AVERAGEIFS(#REF!,#REF!,$A:$A),"-") -> - | G10: =IFERROR(AVERAGEIFS(#REF!,#REF!,A:A),"-") -> - | H10: =IFERROR(AVERAGEIFS(#REF!,#REF!,$A:$A),"-") -> - | I10: =IFERROR(AVERAGEIFS(#REF!,#REF!,$A:$A),"-") -> - | J10: =IFERROR(AVERAGEIFS(#REF!,#REF!,$A:$A),"-") -> - | K10: =IFERROR(AVERAGEIFS(#REF!,#REF!,$A:$A),"-") -> - | L10: =IFERROR(AVERAGEIFS(#REF!,#REF!,$A:$A),"-") -> - | M10: =IFERROR(AVERAGEIFS(#REF!,#REF!,$A:$A),"-") -> - | N10: =IFERROR(AVERAGEIFS(#REF!,#REF!,$A:$A),"-") -> - | O10: =IFERROR(AVERAGEIFS(#REF!,#REF!,$A:$A),"-") -> - | ... W10: =IFERROR(AVERAGEIFS(#REF!,#REF!,$A:$A),"-") -> - | X10: =IFERROR(AVERAGEIFS('[1]Июль 2026'!$K:$K,'[1]Июль 2026'!$E:$E,$A:$A),"-") -> -
A11: Клей Starkbond 522A бочка 220 кг | B11: =IFERROR(AVERAGEIFS('сентябрь 2024- июнь 2026'!$K:$K,'сентябрь 2024- июнь 2026'!$E:$E,$A:$A),"-") -> 2.7780488 | C11: =IFERROR(AVERAGEIFS(#REF!,#REF!,$A:$A),"-") -> - | D11: =IFERROR(AVERAGEIFS(#REF!,#REF!,$A:$A),"-") -> - | E11: =IFERROR(AVERAGEIFS(#REF!,#REF!,$A:$A),"-") -> - | F11: =IFERROR(AVERAGEIFS(#REF!,#REF!,$A:$A),"-") -> - | G11: =IFERROR(AVERAGEIFS(#REF!,#REF!,A:A),"-") -> - | H11: =IFERROR(AVERAGEIFS(#REF!,#REF!,$A:$A),"-") -> - | I11: =IFERROR(AVERAGEIFS(#REF!,#REF!,$A:$A),"-") -> - | J11: =IFERROR(AVERAGEIFS(#REF!,#REF!,$A:$A),"-") -> - | K11: =IFERROR(AVERAGEIFS(#REF!,#REF!,$A:$A),"-") -> - | L11: =IFERROR(AVERAGEIFS(#REF!,#REF!,$A:$A),"-") -> - | M11: =IFERROR(AVERAGEIFS(#REF!,#REF!,$A:$A),"-") -> - | N11: =IFERROR(AVERAGEIFS(#REF!,#REF!,$A:$A),"-") -> - | O11: =IFERROR(AVERAGEIFS(#REF!,#REF!,$A:$A),"-") -> - | ... W11: =IFERROR(AVERAGEIFS(#REF!,#REF!,$A:$A),"-") -> - | X11: =IFERROR(AVERAGEIFS('[1]Июль 2026'!$K:$K,'[1]Июль 2026'!$E:$E,$A:$A),"-") -> -
A12: Отвердитель Starkbond 747С ведро 5 кг | B12: =IFERROR(AVERAGEIFS('сентябрь 2024- июнь 2026'!$K:$K,'сентябрь 2024- июнь 2026'!$E:$E,$A:$A),"-") -> 3.17 | C12: =IFERROR(AVERAGEIFS(#REF!,#REF!,$A:$A),"-") -> - | D12: =IFERROR(AVERAGEIFS(#REF!,#REF!,$A:$A),"-") -> - | E12: =IFERROR(AVERAGEIFS(#REF!,#REF!,$A:$A),"-") -> - | F12: =IFERROR(AVERAGEIFS(#REF!,#REF!,$A:$A),"-") -> - | G12: =IFERROR(AVERAGEIFS(#REF!,#REF!,A:A),"-") -> - | H12: =IFERROR(AVERAGEIFS(#REF!,#REF!,$A:$A),"-") -> - | I12: =IFERROR(AVERAGEIFS(#REF!,#REF!,$A:$A),"-") -> - | J12: =IFERROR(AVERAGEIFS(#REF!,#REF!,$A:$A),"-") -> - | K12: =IFERROR(AVERAGEIFS(#REF!,#REF!,$A:$A),"-") -> - | L12: =IFERROR(AVERAGEIFS(#REF!,#REF!,$A:$A),"-") -> - | M12: =IFERROR(AVERAGEIFS(#REF!,#REF!,$A:$A),"-") -> - | N12: =IFERROR(AVERAGEIFS(#REF!,#REF!,$A:$A),"-") -> - | O12: =IFERROR(AVERAGEIFS(#REF!,#REF!,$A:$A),"-") -> - | ... W12: =IFERROR(AVERAGEIFS(#REF!,#REF!,$A:$A),"-") -> - | X12: =IFERROR(AVERAGEIFS('[1]Июль 2026'!$K:$K,'[1]Июль 2026'!$E:$E,$A:$A),"-") -> -
A13: Клей Starkbond 2014 бочка 225кг | B13: =IFERROR(AVERAGEIFS('сентябрь 2024- июнь 2026'!$K:$K,'сентябрь 2024- июнь 2026'!$E:$E,$A:$A),"-") -> 2.7523944 | C13: =IFERROR(AVERAGEIFS(#REF!,#REF!,$A:$A),"-") -> - | D13: =IFERROR(AVERAGEIFS(#REF!,#REF!,$A:$A),"-") -> - | E13: =IFERROR(AVERAGEIFS(#REF!,#REF!,$A:$A),"-") -> - | F13: =IFERROR(AVERAGEIFS(#REF!,#REF!,$A:$A),"-") -> - | G13: =IFERROR(AVERAGEIFS(#REF!,#REF!,A:A),"-") -> - | H13: =IFERROR(AVERAGEIFS(#REF!,#REF!,$A:$A),"-") -> - | I13: =IFERROR(AVERAGEIFS(#REF!,#REF!,$A:$A),"-") -> - | J13: =IFERROR(AVERAGEIFS(#REF!,#REF!,$A:$A),"-") -> - | K13: =IFERROR(AVERAGEIFS(#REF!,#REF!,$A:$A),"-") -> - | L13: =IFERROR(AVERAGEIFS(#REF!,#REF!,$A:$A),"-") -> - | M13: =IFERROR(AVERAGEIFS(#REF!,#REF!,$A:$A),"-") -> - | N13: =IFERROR(AVERAGEIFS(#REF!,#REF!,$A:$A),"-") -> - | O13: =IFERROR(AVERAGEIFS(#REF!,#REF!,$A:$A),"-") -> - | ... W13: =IFERROR(AVERAGEIFS(#REF!,#REF!,$A:$A),"-") -> - | X13: =IFERROR(AVERAGEIFS('[1]Июль 2026'!$K:$K,'[1]Июль 2026'!$E:$E,$A:$A),"-") -> -
... A85: Sancos Pro Safety 145 канистра 11,59 кг | B85: =IFERROR(AVERAGEIFS('сентябрь 2024- июнь 2026'!$K:$K,'сентябрь 2024- июнь 2026'!$E:$E,$A:$A),"-") -> 1.73 | C85: =IFERROR(AVERAGEIFS(#REF!,#REF!,$A:$A),"-") -> - | D85: =IFERROR(AVERAGEIFS(#REF!,#REF!,$A:$A),"-") -> - | E85: =IFERROR(AVERAGEIFS(#REF!,#REF!,$A:$A),"-") -> - | F85: =IFERROR(AVERAGEIFS(#REF!,#REF!,$A:$A),"-") -> - | G85: =IFERROR(AVERAGEIFS(#REF!,#REF!,A:A),"-") -> - | H85: =IFERROR(AVERAGEIFS(#REF!,#REF!,$A:$A),"-") -> - | I85: =IFERROR(AVERAGEIFS(#REF!,#REF!,$A:$A),"-") -> - | J85: =IFERROR(AVERAGEIFS(#REF!,#REF!,$A:$A),"-") -> - | K85: =IFERROR(AVERAGEIFS(#REF!,#REF!,$A:$A),"-") -> - | L85: =IFERROR(AVERAGEIFS(#REF!,#REF!,$A:$A),"-") -> - | M85: =IFERROR(AVERAGEIFS(#REF!,#REF!,$A:$A),"-") -> - | N85: =IFERROR(AVERAGEIFS(#REF!,#REF!,$A:$A),"-") -> - | O85: =IFERROR(AVERAGEIFS(#REF!,#REF!,$A:$A),"-") -> - | ... W85: =IFERROR(AVERAGEIFS(#REF!,#REF!,$A:$A),"-") -> - | X85: =IFERROR(AVERAGEIFS('[1]Июль 2026'!$K:$K,'[1]Июль 2026'!$E:$E,$A:$A),"-") -> -
B86: =IFERROR(AVERAGEIFS('сентябрь 2024- июнь 2026'!$K:$K,'сентябрь 2024- июнь 2026'!$E:$E,$A:$A),"-") -> - | C86: =IFERROR(AVERAGEIFS(#REF!,#REF!,$A:$A),"-") -> - | D86: =IFERROR(AVERAGEIFS(#REF!,#REF!,$A:$A),"-") -> - | E86: =IFERROR(AVERAGEIFS(#REF!,#REF!,$A:$A),"-") -> - | F86: =IFERROR(AVERAGEIFS(#REF!,#REF!,$A:$A),"-") -> - | G86: =IFERROR(AVERAGEIFS(#REF!,#REF!,A:A),"-") -> - | H86: =IFERROR(AVERAGEIFS(#REF!,#REF!,$A:$A),"-") -> - | I86: =IFERROR(AVERAGEIFS(#REF!,#REF!,$A:$A),"-") -> - | J86: =IFERROR(AVERAGEIFS(#REF!,#REF!,$A:$A),"-") -> - | K86: =IFERROR(AVERAGEIFS(#REF!,#REF!,$A:$A),"-") -> - | L86: =IFERROR(AVERAGEIFS(#REF!,#REF!,$A:$A),"-") -> - | M86: =IFERROR(AVERAGEIFS(#REF!,#REF!,$A:$A),"-") -> - | N86: =IFERROR(AVERAGEIFS(#REF!,#REF!,$A:$A),"-") -> - | O86: =IFERROR(AVERAGEIFS(#REF!,#REF!,$A:$A),"-") -> - | ... W86: =IFERROR(AVERAGEIFS(#REF!,#REF!,$A:$A),"-") -> - | X86: =IFERROR(AVERAGEIFS('[1]Июль 2026'!$K:$K,'[1]Июль 2026'!$E:$E,$A:$A),"-") -> -
B87: =IFERROR(AVERAGEIFS('сентябрь 2024- июнь 2026'!$K:$K,'сентябрь 2024- июнь 2026'!$E:$E,$A:$A),"-") -> - | C87: =IFERROR(AVERAGEIFS(#REF!,#REF!,$A:$A),"-") -> - | D87: =IFERROR(AVERAGEIFS(#REF!,#REF!,$A:$A),"-") -> - | E87: =IFERROR(AVERAGEIFS(#REF!,#REF!,$A:$A),"-") -> - | F87: =IFERROR(AVERAGEIFS(#REF!,#REF!,$A:$A),"-") -> - | G87: =IFERROR(AVERAGEIFS(#REF!,#REF!,A:A),"-") -> - | H87: =IFERROR(AVERAGEIFS(#REF!,#REF!,$A:$A),"-") -> - | I87: =IFERROR(AVERAGEIFS(#REF!,#REF!,$A:$A),"-") -> - | J87: =IFERROR(AVERAGEIFS(#REF!,#REF!,$A:$A),"-") -> - | K87: =IFERROR(AVERAGEIFS(#REF!,#REF!,$A:$A),"-") -> - | L87: =IFERROR(AVERAGEIFS(#REF!,#REF!,$A:$A),"-") -> - | M87: =IFERROR(AVERAGEIFS(#REF!,#REF!,$A:$A),"-") -> - | N87: =IFERROR(AVERAGEIFS(#REF!,#REF!,$A:$A),"-") -> - | O87: =IFERROR(AVERAGEIFS(#REF!,#REF!,$A:$A),"-") -> - | ... W87: =IFERROR(AVERAGEIFS(#REF!,#REF!,$A:$A),"-") -> - | X87: =IFERROR(AVERAGEIFS('[1]Июль 2026'!$K:$K,'[1]Июль 2026'!$E:$E,$A:$A),"-") -> -
B88: =IFERROR(AVERAGEIFS('сентябрь 2024- июнь 2026'!$K:$K,'сентябрь 2024- июнь 2026'!$E:$E,$A:$A),"-") -> - | C88: =IFERROR(AVERAGEIFS(#REF!,#REF!,$A:$A),"-") -> - | D88: =IFERROR(AVERAGEIFS(#REF!,#REF!,$A:$A),"-") -> - | E88: =IFERROR(AVERAGEIFS(#REF!,#REF!,$A:$A),"-") -> - | F88: =IFERROR(AVERAGEIFS(#REF!,#REF!,$A:$A),"-") -> - | G88: =IFERROR(AVERAGEIFS(#REF!,#REF!,A:A),"-") -> - | H88: =IFERROR(AVERAGEIFS(#REF!,#REF!,$A:$A),"-") -> - | I88: =IFERROR(AVERAGEIFS(#REF!,#REF!,$A:$A),"-") -> - | J88: =IFERROR(AVERAGEIFS(#REF!,#REF!,$A:$A),"-") -> - | K88: =IFERROR(AVERAGEIFS(#REF!,#REF!,$A:$A),"-") -> - | L88: =IFERROR(AVERAGEIFS(#REF!,#REF!,$A:$A),"-") -> - | M88: =IFERROR(AVERAGEIFS(#REF!,#REF!,$A:$A),"-") -> - | N88: =IFERROR(AVERAGEIFS(#REF!,#REF!,$A:$A),"-") -> - | O88: =IFERROR(AVERAGEIFS(#REF!,#REF!,$A:$A),"-") -> - | ... W88: =IFERROR(AVERAGEIFS(#REF!,#REF!,$A:$A),"-") -> - | X88: =IFERROR(AVERAGEIFS('[1]Июль 2026'!$K:$K,'[1]Июль 2026'!$E:$E,$A:$A),"-") -> -
B89: =IFERROR(AVERAGEIFS('сентябрь 2024- июнь 2026'!$K:$K,'сентябрь 2024- июнь 2026'!$E:$E,$A:$A),"-") -> - | C89: =IFERROR(AVERAGEIFS(#REF!,#REF!,$A:$A),"-") -> - | D89: =IFERROR(AVERAGEIFS(#REF!,#REF!,$A:$A),"-") -> - | E89: =IFERROR(AVERAGEIFS(#REF!,#REF!,$A:$A),"-") -> - | F89: =IFERROR(AVERAGEIFS(#REF!,#REF!,$A:$A),"-") -> - | G89: =IFERROR(AVERAGEIFS(#REF!,#REF!,A:A),"-") -> - | H89: =IFERROR(AVERAGEIFS(#REF!,#REF!,$A:$A),"-") -> - | I89: =IFERROR(AVERAGEIFS(#REF!,#REF!,$A:$A),"-") -> - | J89: =IFERROR(AVERAGEIFS(#REF!,#REF!,$A:$A),"-") -> - | K89: =IFERROR(AVERAGEIFS(#REF!,#REF!,$A:$A),"-") -> - | L89: =IFERROR(AVERAGEIFS(#REF!,#REF!,$A:$A),"-") -> - | M89: =IFERROR(AVERAGEIFS(#REF!,#REF!,$A:$A),"-") -> - | N89: =IFERROR(AVERAGEIFS(#REF!,#REF!,$A:$A),"-") -> - | O89: =IFERROR(AVERAGEIFS(#REF!,#REF!,$A:$A),"-") -> - | ... W89: =IFERROR(AVERAGEIFS(#REF!,#REF!,$A:$A),"-") -> - | X89: =IFERROR(AVERAGEIFS('[1]Июль 2026'!$K:$K,'[1]Июль 2026'!$E:$E,$A:$A),"-") -> -
B90: =IFERROR(AVERAGEIFS('сентябрь 2024- июнь 2026'!$K:$K,'сентябрь 2024- июнь 2026'!$E:$E,$A:$A),"-") -> - | C90: =IFERROR(AVERAGEIFS(#REF!,#REF!,$A:$A),"-") -> - | D90: =IFERROR(AVERAGEIFS(#REF!,#REF!,$A:$A),"-") -> - | E90: =IFERROR(AVERAGEIFS(#REF!,#REF!,$A:$A),"-") -> - | F90: =IFERROR(AVERAGEIFS(#REF!,#REF!,$A:$A),"-") -> - | G90: =IFERROR(AVERAGEIFS(#REF!,#REF!,A:A),"-") -> - | H90: =IFERROR(AVERAGEIFS(#REF!,#REF!,$A:$A),"-") -> - | I90: =IFERROR(AVERAGEIFS(#REF!,#REF!,$A:$A),"-") -> - | J90: =IFERROR(AVERAGEIFS(#REF!,#REF!,$A:$A),"-") -> - | K90: =IFERROR(AVERAGEIFS(#REF!,#REF!,$A:$A),"-") -> - | L90: =IFERROR(AVERAGEIFS(#REF!,#REF!,$A:$A),"-") -> - | M90: =IFERROR(AVERAGEIFS(#REF!,#REF!,$A:$A),"-") -> - | N90: =IFERROR(AVERAGEIFS(#REF!,#REF!,$A:$A),"-") -> - | O90: =IFERROR(AVERAGEIFS(#REF!,#REF!,$A:$A),"-") -> - | ... W90: =IFERROR(AVERAGEIFS(#REF!,#REF!,$A:$A),"-") -> - | X90: =IFERROR(AVERAGEIFS('[1]Июль 2026'!$K:$K,'[1]Июль 2026'!$E:$E,$A:$A),"-") -> -
B91: =IFERROR(AVERAGEIFS('сентябрь 2024- июнь 2026'!$K:$K,'сентябрь 2024- июнь 2026'!$E:$E,$A:$A),"-") -> - | C91: =IFERROR(AVERAGEIFS(#REF!,#REF!,$A:$A),"-") -> - | D91: =IFERROR(AVERAGEIFS(#REF!,#REF!,$A:$A),"-") -> - | E91: =IFERROR(AVERAGEIFS(#REF!,#REF!,$A:$A),"-") -> - | F91: =IFERROR(AVERAGEIFS(#REF!,#REF!,$A:$A),"-") -> - | G91: =IFERROR(AVERAGEIFS(#REF!,#REF!,A:A),"-") -> - | H91: =IFERROR(AVERAGEIFS(#REF!,#REF!,$A:$A),"-") -> - | I91: =IFERROR(AVERAGEIFS(#REF!,#REF!,$A:$A),"-") -> - | J91: =IFERROR(AVERAGEIFS(#REF!,#REF!,$A:$A),"-") -> - | K91: =IFERROR(AVERAGEIFS(#REF!,#REF!,$A:$A),"-") -> - | L91: =IFERROR(AVERAGEIFS(#REF!,#REF!,$A:$A),"-") -> - | M91: =IFERROR(AVERAGEIFS(#REF!,#REF!,$A:$A),"-") -> - | N91: =IFERROR(AVERAGEIFS(#REF!,#REF!,$A:$A),"-") -> - | O91: =IFERROR(AVERAGEIFS(#REF!,#REF!,$A:$A),"-") -> - | ... W91: =IFERROR(AVERAGEIFS(#REF!,#REF!,$A:$A),"-") -> - | X91: =IFERROR(AVERAGEIFS('[1]Июль 2026'!$K:$K,'[1]Июль 2026'!$E:$E,$A:$A),"-") -> -
B92: =IFERROR(AVERAGEIFS('сентябрь 2024- июнь 2026'!$K:$K,'сентябрь 2024- июнь 2026'!$E:$E,$A:$A),"-") -> - | C92: =IFERROR(AVERAGEIFS(#REF!,#REF!,$A:$A),"-") -> - | D92: =IFERROR(AVERAGEIFS(#REF!,#REF!,$A:$A),"-") -> - | E92: =IFERROR(AVERAGEIFS(#REF!,#REF!,$A:$A),"-") -> - | F92: =IFERROR(AVERAGEIFS(#REF!,#REF!,$A:$A),"-") -> - | G92: =IFERROR(AVERAGEIFS(#REF!,#REF!,A:A),"-") -> - | H92: =IFERROR(AVERAGEIFS(#REF!,#REF!,$A:$A),"-") -> - | I92: =IFERROR(AVERAGEIFS(#REF!,#REF!,$A:$A),"-") -> - | J92: =IFERROR(AVERAGEIFS(#REF!,#REF!,$A:$A),"-") -> - | K92: =IFERROR(AVERAGEIFS(#REF!,#REF!,$A:$A),"-") -> - | L92: =IFERROR(AVERAGEIFS(#REF!,#REF!,$A:$A),"-") -> - | M92: =IFERROR(AVERAGEIFS(#REF!,#REF!,$A:$A),"-") -> - | N92: =IFERROR(AVERAGEIFS(#REF!,#REF!,$A:$A),"-") -> - | O92: =IFERROR(AVERAGEIFS(#REF!,#REF!,$A:$A),"-") -> - | ... W92: =IFERROR(AVERAGEIFS(#REF!,#REF!,$A:$A),"-") -> - | X92: =IFERROR(AVERAGEIFS('[1]Июль 2026'!$K:$K,'[1]Июль 2026'!$E:$E,$A:$A),"-") -> -
B93: =IFERROR(AVERAGEIFS('сентябрь 2024- июнь 2026'!$K:$K,'сентябрь 2024- июнь 2026'!$E:$E,$A:$A),"-") -> - | C93: =IFERROR(AVERAGEIFS(#REF!,#REF!,$A:$A),"-") -> - | D93: =IFERROR(AVERAGEIFS(#REF!,#REF!,$A:$A),"-") -> - | E93: =IFERROR(AVERAGEIFS(#REF!,#REF!,$A:$A),"-") -> - | F93: =IFERROR(AVERAGEIFS(#REF!,#REF!,$A:$A),"-") -> - | G93: =IFERROR(AVERAGEIFS(#REF!,#REF!,A:A),"-") -> - | H93: =IFERROR(AVERAGEIFS(#REF!,#REF!,$A:$A),"-") -> - | I93: =IFERROR(AVERAGEIFS(#REF!,#REF!,$A:$A),"-") -> - | J93: =IFERROR(AVERAGEIFS(#REF!,#REF!,$A:$A),"-") -> - | K93: =IFERROR(AVERAGEIFS(#REF!,#REF!,$A:$A),"-") -> - | L93: =IFERROR(AVERAGEIFS(#REF!,#REF!,$A:$A),"-") -> - | M93: =IFERROR(AVERAGEIFS(#REF!,#REF!,$A:$A),"-") -> - | N93: =IFERROR(AVERAGEIFS(#REF!,#REF!,$A:$A),"-") -> - | O93: =IFERROR(AVERAGEIFS(#REF!,#REF!,$A:$A),"-") -> - | ... W93: =IFERROR(AVERAGEIFS(#REF!,#REF!,$A:$A),"-") -> - | X93: =IFERROR(AVERAGEIFS('[1]Июль 2026'!$K:$K,'[1]Июль 2026'!$E:$E,$A:$A),"-") -> -
B94: =IFERROR(AVERAGEIFS('сентябрь 2024- июнь 2026'!$K:$K,'сентябрь 2024- июнь 2026'!$E:$E,$A:$A),"-") -> - | C94: =IFERROR(AVERAGEIFS(#REF!,#REF!,$A:$A),"-") -> - | D94: =IFERROR(AVERAGEIFS(#REF!,#REF!,$A:$A),"-") -> - | E94: =IFERROR(AVERAGEIFS(#REF!,#REF!,$A:$A),"-") -> - | F94: =IFERROR(AVERAGEIFS(#REF!,#REF!,$A:$A),"-") -> - | G94: =IFERROR(AVERAGEIFS(#REF!,#REF!,A:A),"-") -> - | H94: =IFERROR(AVERAGEIFS(#REF!,#REF!,$A:$A),"-") -> - | I94: =IFERROR(AVERAGEIFS(#REF!,#REF!,$A:$A),"-") -> - | J94: =IFERROR(AVERAGEIFS(#REF!,#REF!,$A:$A),"-") -> - | K94: =IFERROR(AVERAGEIFS(#REF!,#REF!,$A:$A),"-") -> - | L94: =IFERROR(AVERAGEIFS(#REF!,#REF!,$A:$A),"-") -> - | M94: =IFERROR(AVERAGEIFS(#REF!,#REF!,$A:$A),"-") -> - | N94: =IFERROR(AVERAGEIFS(#REF!,#REF!,$A:$A),"-") -> - | O94: =IFERROR(AVERAGEIFS(#REF!,#REF!,$A:$A),"-") -> - | ... W94: =IFERROR(AVERAGEIFS(#REF!,#REF!,$A:$A),"-") -> - | X94: =IFERROR(AVERAGEIFS('[1]Июль 2026'!$K:$K,'[1]Июль 2026'!$E:$E,$A:$A),"-") -> -
B95: =IFERROR(AVERAGEIFS('сентябрь 2024- июнь 2026'!$K:$K,'сентябрь 2024- июнь 2026'!$E:$E,$A:$A),"-") -> - | C95: =IFERROR(AVERAGEIFS(#REF!,#REF!,$A:$A),"-") -> - | D95: =IFERROR(AVERAGEIFS(#REF!,#REF!,$A:$A),"-") -> - | E95: =IFERROR(AVERAGEIFS(#REF!,#REF!,$A:$A),"-") -> - | F95: =IFERROR(AVERAGEIFS(#REF!,#REF!,$A:$A),"-") -> - | G95: =IFERROR(AVERAGEIFS(#REF!,#REF!,A:A),"-") -> - | H95: =IFERROR(AVERAGEIFS(#REF!,#REF!,$A:$A),"-") -> - | I95: =IFERROR(AVERAGEIFS(#REF!,#REF!,$A:$A),"-") -> - | J95: =IFERROR(AVERAGEIFS(#REF!,#REF!,$A:$A),"-") -> - | K95: =IFERROR(AVERAGEIFS(#REF!,#REF!,$A:$A),"-") -> - | L95: =IFERROR(AVERAGEIFS(#REF!,#REF!,$A:$A),"-") -> - | M95: =IFERROR(AVERAGEIFS(#REF!,#REF!,$A:$A),"-") -> - | N95: =IFERROR(AVERAGEIFS(#REF!,#REF!,$A:$A),"-") -> - | O95: =IFERROR(AVERAGEIFS(#REF!,#REF!,$A:$A),"-") -> - | ... W95: =IFERROR(AVERAGEIFS(#REF!,#REF!,$A:$A),"-") -> - | X95: =IFERROR(AVERAGEIFS('[1]Июль 2026'!$K:$K,'[1]Июль 2026'!$E:$E,$A:$A),"-") -> -
B96: =IFERROR(AVERAGEIFS('сентябрь 2024- июнь 2026'!$K:$K,'сентябрь 2024- июнь 2026'!$E:$E,$A:$A),"-") -> - | C96: =IFERROR(AVERAGEIFS(#REF!,#REF!,$A:$A),"-") -> - | D96: =IFERROR(AVERAGEIFS(#REF!,#REF!,$A:$A),"-") -> - | E96: =IFERROR(AVERAGEIFS(#REF!,#REF!,$A:$A),"-") -> - | F96: =IFERROR(AVERAGEIFS(#REF!,#REF!,$A:$A),"-") -> - | G96: =IFERROR(AVERAGEIFS(#REF!,#REF!,A:A),"-") -> - | H96: =IFERROR(AVERAGEIFS(#REF!,#REF!,$A:$A),"-") -> - | I96: =IFERROR(AVERAGEIFS(#REF!,#REF!,$A:$A),"-") -> - | J96: =IFERROR(AVERAGEIFS(#REF!,#REF!,$A:$A),"-") -> - | K96: =IFERROR(AVERAGEIFS(#REF!,#REF!,$A:$A),"-") -> - | L96: =IFERROR(AVERAGEIFS(#REF!,#REF!,$A:$A),"-") -> - | M96: =IFERROR(AVERAGEIFS(#REF!,#REF!,$A:$A),"-") -> - | N96: =IFERROR(AVERAGEIFS(#REF!,#REF!,$A:$A),"-") -> - | O96: =IFERROR(AVERAGEIFS(#REF!,#REF!,$A:$A),"-") -> - | ... W96: =IFERROR(AVERAGEIFS(#REF!,#REF!,$A:$A),"-") -> - | X96: =IFERROR(AVERAGEIFS('[1]Июль 2026'!$K:$K,'[1]Июль 2026'!$E:$E,$A:$A),"-") -> -
B97: =IFERROR(AVERAGEIFS('сентябрь 2024- июнь 2026'!$K:$K,'сентябрь 2024- июнь 2026'!$E:$E,$A:$A),"-") -> - | C97: =IFERROR(AVERAGEIFS(#REF!,#REF!,$A:$A),"-") -> - | D97: =IFERROR(AVERAGEIFS(#REF!,#REF!,$A:$A),"-") -> - | E97: =IFERROR(AVERAGEIFS(#REF!,#REF!,$A:$A),"-") -> - | F97: =IFERROR(AVERAGEIFS(#REF!,#REF!,$A:$A),"-") -> - | G97: =IFERROR(AVERAGEIFS(#REF!,#REF!,A:A),"-") -> - | H97: =IFERROR(AVERAGEIFS(#REF!,#REF!,$A:$A),"-") -> - | I97: =IFERROR(AVERAGEIFS(#REF!,#REF!,$A:$A),"-") -> - | J97: =IFERROR(AVERAGEIFS(#REF!,#REF!,$A:$A),"-") -> - | K97: =IFERROR(AVERAGEIFS(#REF!,#REF!,$A:$A),"-") -> - | L97: =IFERROR(AVERAGEIFS(#REF!,#REF!,$A:$A),"-") -> - | M97: =IFERROR(AVERAGEIFS(#REF!,#REF!,$A:$A),"-") -> - | N97: =IFERROR(AVERAGEIFS(#REF!,#REF!,$A:$A),"-") -> - | O97: =IFERROR(AVERAGEIFS(#REF!,#REF!,$A:$A),"-") -> - | ... W97: =IFERROR(AVERAGEIFS(#REF!,#REF!,$A:$A),"-") -> - | X97: =IFERROR(AVERAGEIFS('[1]Июль 2026'!$K:$K,'[1]Июль 2026'!$E:$E,$A:$A),"-") -> -
... B109: =IFERROR(AVERAGEIFS('сентябрь 2024- июнь 2026'!$K:$K,'сентябрь 2024- июнь 2026'!$E:$E,$A:$A),"-") -> - | C109: =IFERROR(AVERAGEIFS(#REF!,#REF!,$A:$A),"-") -> - | D109: =IFERROR(AVERAGEIFS(#REF!,#REF!,$A:$A),"-") -> - | E109: =IFERROR(AVERAGEIFS(#REF!,#REF!,$A:$A),"-") -> - | F109: =IFERROR(AVERAGEIFS(#REF!,#REF!,$A:$A),"-") -> - | G109: =IFERROR(AVERAGEIFS(#REF!,#REF!,A:A),"-") -> - | H109: =IFERROR(AVERAGEIFS(#REF!,#REF!,$A:$A),"-") -> - | I109: =IFERROR(AVERAGEIFS(#REF!,#REF!,$A:$A),"-") -> - | J109: =IFERROR(AVERAGEIFS(#REF!,#REF!,$A:$A),"-") -> - | K109: =IFERROR(AVERAGEIFS(#REF!,#REF!,$A:$A),"-") -> - | L109: =IFERROR(AVERAGEIFS(#REF!,#REF!,$A:$A),"-") -> - | M109: =IFERROR(AVERAGEIFS(#REF!,#REF!,$A:$A),"-") -> - | N109: =IFERROR(AVERAGEIFS(#REF!,#REF!,$A:$A),"-") -> - | O109: =IFERROR(AVERAGEIFS(#REF!,#REF!,$A:$A),"-") -> - | ... W109: =IFERROR(AVERAGEIFS(#REF!,#REF!,$A:$A),"-") -> - | X109: =IFERROR(AVERAGEIFS('[1]Июль 2026'!$K:$K,'[1]Июль 2026'!$E:$E,$A:$A),"-") -> -
B110: =IFERROR(AVERAGEIFS('сентябрь 2024- июнь 2026'!$K:$K,'сентябрь 2024- июнь 2026'!$E:$E,$A:$A),"-") -> - | C110: =IFERROR(AVERAGEIFS(#REF!,#REF!,$A:$A),"-") -> - | D110: =IFERROR(AVERAGEIFS(#REF!,#REF!,$A:$A),"-") -> - | E110: =IFERROR(AVERAGEIFS(#REF!,#REF!,$A:$A),"-") -> - | F110: =IFERROR(AVERAGEIFS(#REF!,#REF!,$A:$A),"-") -> - | G110: =IFERROR(AVERAGEIFS(#REF!,#REF!,A:A),"-") -> - | H110: =IFERROR(AVERAGEIFS(#REF!,#REF!,$A:$A),"-") -> - | I110: =IFERROR(AVERAGEIFS(#REF!,#REF!,$A:$A),"-") -> - | J110: =IFERROR(AVERAGEIFS(#REF!,#REF!,$A:$A),"-") -> - | K110: =IFERROR(AVERAGEIFS(#REF!,#REF!,$A:$A),"-") -> - | L110: =IFERROR(AVERAGEIFS(#REF!,#REF!,$A:$A),"-") -> - | M110: =IFERROR(AVERAGEIFS(#REF!,#REF!,$A:$A),"-") -> - | N110: =IFERROR(AVERAGEIFS(#REF!,#REF!,$A:$A),"-") -> - | O110: =IFERROR(AVERAGEIFS(#REF!,#REF!,$A:$A),"-") -> - | ... X110: =IFERROR(AVERAGEIFS(#REF!,#REF!,$A:$A),"-") -> -
B111: =IFERROR(AVERAGEIFS('сентябрь 2024- июнь 2026'!$K:$K,'сентябрь 2024- июнь 2026'!$E:$E,$A:$A),"-") -> - | C111: =IFERROR(AVERAGEIFS(#REF!,#REF!,$A:$A),"-") -> - | D111: =IFERROR(AVERAGEIFS(#REF!,#REF!,$A:$A),"-") -> - | E111: =IFERROR(AVERAGEIFS(#REF!,#REF!,$A:$A),"-") -> - | F111: =IFERROR(AVERAGEIFS(#REF!,#REF!,$A:$A),"-") -> - | G111: =IFERROR(AVERAGEIFS(#REF!,#REF!,A:A),"-") -> - | H111: =IFERROR(AVERAGEIFS(#REF!,#REF!,$A:$A),"-") -> - | I111: =IFERROR(AVERAGEIFS(#REF!,#REF!,$A:$A),"-") -> - | J111: =IFERROR(AVERAGEIFS(#REF!,#REF!,$A:$A),"-") -> - | K111: =IFERROR(AVERAGEIFS(#REF!,#REF!,$A:$A),"-") -> - | L111: =IFERROR(AVERAGEIFS(#REF!,#REF!,$A:$A),"-") -> - | M111: =IFERROR(AVERAGEIFS(#REF!,#REF!,$A:$A),"-") -> - | N111: =IFERROR(AVERAGEIFS(#REF!,#REF!,$A:$A),"-") -> - | O111: =IFERROR(AVERAGEIFS(#REF!,#REF!,$A:$A),"-") -> - | ... X111: =IFERROR(AVERAGEIFS(#REF!,#REF!,$A:$A),"-") -> -
B112: =IFERROR(AVERAGEIFS('сентябрь 2024- июнь 2026'!$K:$K,'сентябрь 2024- июнь 2026'!$E:$E,$A:$A),"-") -> - | C112: =IFERROR(AVERAGEIFS(#REF!,#REF!,$A:$A),"-") -> - | D112: =IFERROR(AVERAGEIFS(#REF!,#REF!,$A:$A),"-") -> - | E112: =IFERROR(AVERAGEIFS(#REF!,#REF!,$A:$A),"-") -> - | F112: =IFERROR(AVERAGEIFS(#REF!,#REF!,$A:$A),"-") -> - | G112: =IFERROR(AVERAGEIFS(#REF!,#REF!,A:A),"-") -> - | H112: =IFERROR(AVERAGEIFS(#REF!,#REF!,$A:$A),"-") -> - | I112: =IFERROR(AVERAGEIFS(#REF!,#REF!,$A:$A),"-") -> - | J112: =IFERROR(AVERAGEIFS(#REF!,#REF!,$A:$A),"-") -> - | K112: =IFERROR(AVERAGEIFS(#REF!,#REF!,$A:$A),"-") -> - | L112: =IFERROR(AVERAGEIFS(#REF!,#REF!,$A:$A),"-") -> - | M112: =IFERROR(AVERAGEIFS(#REF!,#REF!,$A:$A),"-") -> - | N112: =IFERROR(AVERAGEIFS(#REF!,#REF!,$A:$A),"-") -> - | O112: =IFERROR(AVERAGEIFS(#REF!,#REF!,$A:$A),"-") -> - | ... X112: =IFERROR(AVERAGEIFS(#REF!,#REF!,$A:$A),"-") -> -
B113: =IFERROR(AVERAGEIFS('сентябрь 2024- июнь 2026'!$K:$K,'сентябрь 2024- июнь 2026'!$E:$E,$A:$A),"-") -> - | C113: =IFERROR(AVERAGEIFS(#REF!,#REF!,$A:$A),"-") -> - | D113: =IFERROR(AVERAGEIFS(#REF!,#REF!,$A:$A),"-") -> - | E113: =IFERROR(AVERAGEIFS(#REF!,#REF!,$A:$A),"-") -> - | F113: =IFERROR(AVERAGEIFS(#REF!,#REF!,$A:$A),"-") -> - | G113: =IFERROR(AVERAGEIFS(#REF!,#REF!,A:A),"-") -> - | H113: =IFERROR(AVERAGEIFS(#REF!,#REF!,$A:$A),"-") -> - | I113: =IFERROR(AVERAGEIFS(#REF!,#REF!,$A:$A),"-") -> - | J113: =IFERROR(AVERAGEIFS(#REF!,#REF!,$A:$A),"-") -> - | K113: =IFERROR(AVERAGEIFS(#REF!,#REF!,$A:$A),"-") -> - | L113: =IFERROR(AVERAGEIFS(#REF!,#REF!,$A:$A),"-") -> - | M113: =IFERROR(AVERAGEIFS(#REF!,#REF!,$A:$A),"-") -> - | N113: =IFERROR(AVERAGEIFS(#REF!,#REF!,$A:$A),"-") -> - | O113: =IFERROR(AVERAGEIFS(#REF!,#REF!,$A:$A),"-") -> - | ... X113: =IFERROR(AVERAGEIFS(#REF!,#REF!,$A:$A),"-") -> -
B114: =IFERROR(AVERAGEIFS('сентябрь 2024- июнь 2026'!$K:$K,'сентябрь 2024- июнь 2026'!$E:$E,$A:$A),"-") -> - | C114: =IFERROR(AVERAGEIFS(#REF!,#REF!,$A:$A),"-") -> - | D114: =IFERROR(AVERAGEIFS(#REF!,#REF!,$A:$A),"-") -> - | E114: =IFERROR(AVERAGEIFS(#REF!,#REF!,$A:$A),"-") -> - | F114: =IFERROR(AVERAGEIFS(#REF!,#REF!,$A:$A),"-") -> - | G114: =IFERROR(AVERAGEIFS(#REF!,#REF!,A:A),"-") -> - | H114: =IFERROR(AVERAGEIFS(#REF!,#REF!,$A:$A),"-") -> - | I114: =IFERROR(AVERAGEIFS(#REF!,#REF!,$A:$A),"-") -> - | J114: =IFERROR(AVERAGEIFS(#REF!,#REF!,$A:$A),"-") -> - | K114: =IFERROR(AVERAGEIFS(#REF!,#REF!,$A:$A),"-") -> - | L114: =IFERROR(AVERAGEIFS(#REF!,#REF!,$A:$A),"-") -> - | M114: =IFERROR(AVERAGEIFS(#REF!,#REF!,$A:$A),"-") -> - | N114: =IFERROR(AVERAGEIFS(#REF!,#REF!,$A:$A),"-") -> - | O114: =IFERROR(AVERAGEIFS(#REF!,#REF!,$A:$A),"-") -> - | ... X114: =IFERROR(AVERAGEIFS(#REF!,#REF!,$A:$A),"-") -> -
B115: =IFERROR(AVERAGEIFS('сентябрь 2024- июнь 2026'!$K:$K,'сентябрь 2024- июнь 2026'!$E:$E,$A:$A),"-") -> - | C115: =IFERROR(AVERAGEIFS(#REF!,#REF!,$A:$A),"-") -> - | D115: =IFERROR(AVERAGEIFS(#REF!,#REF!,$A:$A),"-") -> - | E115: =IFERROR(AVERAGEIFS(#REF!,#REF!,$A:$A),"-") -> - | F115: =IFERROR(AVERAGEIFS(#REF!,#REF!,$A:$A),"-") -> - | G115: =IFERROR(AVERAGEIFS(#REF!,#REF!,A:A),"-") -> - | H115: =IFERROR(AVERAGEIFS(#REF!,#REF!,$A:$A),"-") -> - | I115: =IFERROR(AVERAGEIFS(#REF!,#REF!,$A:$A),"-") -> - | J115: =IFERROR(AVERAGEIFS(#REF!,#REF!,$A:$A),"-") -> - | K115: =IFERROR(AVERAGEIFS(#REF!,#REF!,$A:$A),"-") -> - | L115: =IFERROR(AVERAGEIFS(#REF!,#REF!,$A:$A),"-") -> - | M115: =IFERROR(AVERAGEIFS(#REF!,#REF!,$A:$A),"-") -> - | N115: =IFERROR(AVERAGEIFS(#REF!,#REF!,$A:$A),"-") -> - | O115: =IFERROR(AVERAGEIFS(#REF!,#REF!,$A:$A),"-") -> - | ... X115: =IFERROR(AVERAGEIFS(#REF!,#REF!,$A:$A),"-") -> -
B116: =IFERROR(AVERAGEIFS('сентябрь 2024- июнь 2026'!$K:$K,'сентябрь 2024- июнь 2026'!$E:$E,$A:$A),"-") -> - | C116: =IFERROR(AVERAGEIFS(#REF!,#REF!,$A:$A),"-") -> - | D116: =IFERROR(AVERAGEIFS(#REF!,#REF!,$A:$A),"-") -> - | E116: =IFERROR(AVERAGEIFS(#REF!,#REF!,$A:$A),"-") -> - | F116: =IFERROR(AVERAGEIFS(#REF!,#REF!,$A:$A),"-") -> - | G116: =IFERROR(AVERAGEIFS(#REF!,#REF!,A:A),"-") -> - | H116: =IFERROR(AVERAGEIFS(#REF!,#REF!,$A:$A),"-") -> - | I116: =IFERROR(AVERAGEIFS(#REF!,#REF!,$A:$A),"-") -> - | J116: =IFERROR(AVERAGEIFS(#REF!,#REF!,$A:$A),"-") -> - | K116: =IFERROR(AVERAGEIFS(#REF!,#REF!,$A:$A),"-") -> - | L116: =IFERROR(AVERAGEIFS(#REF!,#REF!,$A:$A),"-") -> - | M116: =IFERROR(AVERAGEIFS(#REF!,#REF!,$A:$A),"-") -> - | N116: =IFERROR(AVERAGEIFS(#REF!,#REF!,$A:$A),"-") -> - | O116: =IFERROR(AVERAGEIFS(#REF!,#REF!,$A:$A),"-") -> - | ... X116: =IFERROR(AVERAGEIFS(#REF!,#REF!,$A:$A),"-") -> -
B117: =IFERROR(AVERAGEIFS('сентябрь 2024- июнь 2026'!$K:$K,'сентябрь 2024- июнь 2026'!$E:$E,$A:$A),"-") -> - | C117: =IFERROR(AVERAGEIFS(#REF!,#REF!,$A:$A),"-") -> - | D117: =IFERROR(AVERAGEIFS(#REF!,#REF!,$A:$A),"-") -> - | E117: =IFERROR(AVERAGEIFS(#REF!,#REF!,$A:$A),"-") -> - | F117: =IFERROR(AVERAGEIFS(#REF!,#REF!,$A:$A),"-") -> - | G117: =IFERROR(AVERAGEIFS(#REF!,#REF!,A:A),"-") -> - | H117: =IFERROR(AVERAGEIFS(#REF!,#REF!,$A:$A),"-") -> - | I117: =IFERROR(AVERAGEIFS(#REF!,#REF!,$A:$A),"-") -> - | J117: =IFERROR(AVERAGEIFS(#REF!,#REF!,$A:$A),"-") -> - | K117: =IFERROR(AVERAGEIFS(#REF!,#REF!,$A:$A),"-") -> - | L117: =IFERROR(AVERAGEIFS(#REF!,#REF!,$A:$A),"-") -> - | M117: =IFERROR(AVERAGEIFS(#REF!,#REF!,$A:$A),"-") -> - | N117: =IFERROR(AVERAGEIFS(#REF!,#REF!,$A:$A),"-") -> - | O117: =IFERROR(AVERAGEIFS(#REF!,#REF!,$A:$A),"-") -> - | ... X117: =IFERROR(AVERAGEIFS(#REF!,#REF!,$A:$A),"-") -> -
B118: =IFERROR(AVERAGEIFS('сентябрь 2024- июнь 2026'!$K:$K,'сентябрь 2024- июнь 2026'!$E:$E,$A:$A),"-") -> - | C118: =IFERROR(AVERAGEIFS(#REF!,#REF!,$A:$A),"-") -> - | D118: =IFERROR(AVERAGEIFS(#REF!,#REF!,$A:$A),"-") -> - | E118: =IFERROR(AVERAGEIFS(#REF!,#REF!,$A:$A),"-") -> - | F118: =IFERROR(AVERAGEIFS(#REF!,#REF!,$A:$A),"-") -> - | G118: =IFERROR(AVERAGEIFS(#REF!,#REF!,A:A),"-") -> - | H118: =IFERROR(AVERAGEIFS(#REF!,#REF!,$A:$A),"-") -> - | I118: =IFERROR(AVERAGEIFS(#REF!,#REF!,$A:$A),"-") -> - | J118: =IFERROR(AVERAGEIFS(#REF!,#REF!,$A:$A),"-") -> - | K118: =IFERROR(AVERAGEIFS(#REF!,#REF!,$A:$A),"-") -> - | L118: =IFERROR(AVERAGEIFS(#REF!,#REF!,$A:$A),"-") -> - | M118: =IFERROR(AVERAGEIFS(#REF!,#REF!,$A:$A),"-") -> - | N118: =IFERROR(AVERAGEIFS(#REF!,#REF!,$A:$A),"-") -> - | O118: =IFERROR(AVERAGEIFS(#REF!,#REF!,$A:$A),"-") -> - | ... X118: =IFERROR(AVERAGEIFS(#REF!,#REF!,$A:$A),"-") -> -
B119: =IFERROR(AVERAGEIFS('сентябрь 2024- июнь 2026'!$K:$K,'сентябрь 2024- июнь 2026'!$E:$E,$A:$A),"-") -> - | C119: =IFERROR(AVERAGEIFS(#REF!,#REF!,$A:$A),"-") -> - | D119: =IFERROR(AVERAGEIFS(#REF!,#REF!,$A:$A),"-") -> - | E119: =IFERROR(AVERAGEIFS(#REF!,#REF!,$A:$A),"-") -> - | F119: =IFERROR(AVERAGEIFS(#REF!,#REF!,$A:$A),"-") -> - | G119: =IFERROR(AVERAGEIFS(#REF!,#REF!,A:A),"-") -> - | H119: =IFERROR(AVERAGEIFS(#REF!,#REF!,$A:$A),"-") -> - | I119: =IFERROR(AVERAGEIFS(#REF!,#REF!,$A:$A),"-") -> - | J119: =IFERROR(AVERAGEIFS(#REF!,#REF!,$A:$A),"-") -> - | K119: =IFERROR(AVERAGEIFS(#REF!,#REF!,$A:$A),"-") -> - | L119: =IFERROR(AVERAGEIFS(#REF!,#REF!,$A:$A),"-") -> - | M119: =IFERROR(AVERAGEIFS(#REF!,#REF!,$A:$A),"-") -> - | N119: =IFERROR(AVERAGEIFS(#REF!,#REF!,$A:$A),"-") -> - | O119: =IFERROR(AVERAGEIFS(#REF!,#REF!,$A:$A),"-") -> - | ... X119: =IFERROR(AVERAGEIFS(#REF!,#REF!,$A:$A),"-") -> -
B120: =IFERROR(AVERAGEIFS('сентябрь 2024- июнь 2026'!$K:$K,'сентябрь 2024- июнь 2026'!$E:$E,$A:$A),"-") -> - | C120: =IFERROR(AVERAGEIFS(#REF!,#REF!,$A:$A),"-") -> - | D120: =IFERROR(AVERAGEIFS(#REF!,#REF!,$A:$A),"-") -> - | E120: =IFERROR(AVERAGEIFS(#REF!,#REF!,$A:$A),"-") -> - | F120: =IFERROR(AVERAGEIFS(#REF!,#REF!,$A:$A),"-") -> - | G120: =IFERROR(AVERAGEIFS(#REF!,#REF!,A:A),"-") -> - | H120: =IFERROR(AVERAGEIFS(#REF!,#REF!,$A:$A),"-") -> - | I120: =IFERROR(AVERAGEIFS(#REF!,#REF!,$A:$A),"-") -> - | J120: =IFERROR(AVERAGEIFS(#REF!,#REF!,$A:$A),"-") -> - | K120: =IFERROR(AVERAGEIFS(#REF!,#REF!,$A:$A),"-") -> - | L120: =IFERROR(AVERAGEIFS(#REF!,#REF!,$A:$A),"-") -> - | M120: =IFERROR(AVERAGEIFS(#REF!,#REF!,$A:$A),"-") -> - | N120: =IFERROR(AVERAGEIFS(#REF!,#REF!,$A:$A),"-") -> - | O120: =IFERROR(AVERAGEIFS(#REF!,#REF!,$A:$A),"-") -> - | ... X120: =IFERROR(AVERAGEIFS(#REF!,#REF!,$A:$A),"-") -> -
B121: =IFERROR(AVERAGEIFS('сентябрь 2024- июнь 2026'!$K:$K,'сентябрь 2024- июнь 2026'!$E:$E,$A:$A),"-") -> - | C121: =IFERROR(AVERAGEIFS(#REF!,#REF!,$A:$A),"-") -> - | D121: =IFERROR(AVERAGEIFS(#REF!,#REF!,$A:$A),"-") -> - | E121: =IFERROR(AVERAGEIFS(#REF!,#REF!,$A:$A),"-") -> - | F121: =IFERROR(AVERAGEIFS(#REF!,#REF!,$A:$A),"-") -> - | G121: =IFERROR(AVERAGEIFS(#REF!,#REF!,A:A),"-") -> - | H121: =IFERROR(AVERAGEIFS(#REF!,#REF!,$A:$A),"-") -> - | I121: =IFERROR(AVERAGEIFS(#REF!,#REF!,$A:$A),"-") -> - | J121: =IFERROR(AVERAGEIFS(#REF!,#REF!,$A:$A),"-") -> - | K121: =IFERROR(AVERAGEIFS(#REF!,#REF!,$A:$A),"-") -> - | L121: =IFERROR(AVERAGEIFS(#REF!,#REF!,$A:$A),"-") -> - | M121: =IFERROR(AVERAGEIFS(#REF!,#REF!,$A:$A),"-") -> - | N121: =IFERROR(AVERAGEIFS(#REF!,#REF!,$A:$A),"-") -> - | O121: =IFERROR(AVERAGEIFS(#REF!,#REF!,$A:$A),"-") -> - | ... X121: =IFERROR(AVERAGEIFS(#REF!,#REF!,$A:$A),"-") -> -
... B123: =IFERROR(AVERAGEIFS('сентябрь 2024- июнь 2026'!$K:$K,'сентябрь 2024- июнь 2026'!$E:$E,$A:$A),"-") -> - | C123: =IFERROR(AVERAGEIFS(#REF!,#REF!,$A:$A),"-") -> - | D123: =IFERROR(AVERAGEIFS(#REF!,#REF!,$A:$A),"-") -> - | E123: =IFERROR(AVERAGEIFS(#REF!,#REF!,$A:$A),"-") -> - | F123: =IFERROR(AVERAGEIFS(#REF!,#REF!,$A:$A),"-") -> - | G123: =IFERROR(AVERAGEIFS(#REF!,#REF!,A:A),"-") -> - | H123: =IFERROR(AVERAGEIFS(#REF!,#REF!,$A:$A),"-") -> - | I123: =IFERROR(AVERAGEIFS(#REF!,#REF!,$A:$A),"-") -> - | J123: =IFERROR(AVERAGEIFS(#REF!,#REF!,$A:$A),"-") -> - | K123: =IFERROR(AVERAGEIFS(#REF!,#REF!,$A:$A),"-") -> - | L123: =IFERROR(AVERAGEIFS(#REF!,#REF!,$A:$A),"-") -> - | M123: =IFERROR(AVERAGEIFS(#REF!,#REF!,$A:$A),"-") -> - | N123: =IFERROR(AVERAGEIFS(#REF!,#REF!,$A:$A),"-") -> - | O123: =IFERROR(AVERAGEIFS(#REF!,#REF!,$A:$A),"-") -> - | ... X123: =IFERROR(AVERAGEIFS(#REF!,#REF!,$A:$A),"-") -> -
...

Sheet СС
A2: номер заказа | B2: дата ТД | C2: наименование | D2: кол-во | E2: Сумма евро с НДС | F2: Сумма руб с НДС | G2: Себес с НДС, евро | H2: ндс | I2: Сумма евро без НДС | J2: Сумма руб без ндс | K2: Себес без НДС, евро
A3: ШККА-000109 | B3: 45796 | C3: Изоцианат лупранат MI компонент Б (бочка 225) | D3: 19000 | E3: 56430 | F3: 5189680.9 | I3: 56430 | J3: 5189680.9
C4: Возмещаемые расходы: Сверхнормативное использование контейнера, Kumport - Новороссийск, LAMU7000547 | E4: 1121.1 | F4: 103104 | H4: без ндс | I4: 1121.1 | J4: 103104
C5: Транспортно-экспедиционное обслуживание по маршруту FCA Kumport - Новороссийск, MDTRLS2504449, LAMU7000547, Инвйос 2025/R0376 от 14.05.25 | E5: 5255.16 | F5: 483300 | H5: без ндс | I5: 5255.16 | J5: 483300
C6: Комплекс услуг таможенного представителя по таможенному декларированию товаров, ДТ 10317120/190525/5087193, Инвйос 2025/R0376 от 14.05.25 | E6: 326.21 | F6: 30000 | H6: 0.2 | I6: 271.84 | J6: 25000
C7: Транспортно-экспедиционное обслуживание по маршруту НУТЭП - Склад, LAMU7000547, Инвйос 2025/R0376 от 14.05.25 | E7: 2598.77 | F7: 239000 | H7: 0 | I7: 2598.77 | J7: 239000
C8: Возмещаемые расходы: Хранение рефрижераторного контейнера, подключенного к электропитанию, с первых суток , LAMU7000547 | E8: 231.36 | F8: 21277.48 | H8: 0.2 | I8: 192.8 | J8: 17731.23
C9: Возмещаемые расходы: Фрахтовая надбавка DTHC (стивидорный сбор порта выгрузки), LAMU7000547 | E9: 840.82 | F9: 77327.63 | H9: 0.2 | I9: 700.69 | J9: 64439.69
C10: Возмещаемые расходы: Агентское вознаграждение (Hamburg Sud), LAMU7000547 | E10: 54.8 | F10: 5040 | H10: 0.2 | I10: 45.67 | J10: 4200 | M10: дельта | N10: =K16-K34 -> 0.49166667 | O10: евро
E11: 0 | H11: 0.2 | I11: 0 | J11: 0 | M11: Расход на 1100 | N11: 607.7 | O11: кг
C12: НДС на таможне | E12: 12791.46 | F12: 1176388.7 | I12: 12791.46 | J12: 1176388.7 | M12: Ошибка в 1С | N12: =N11*N10 -> 298.78583
C13: Пошлина | E13: 3045.59 | F13: 280092.54 | I13: 3045.59 | J13: 280092.54 | M13: На кг | N13: =N12/1100 -> 0.27162348
C14: Таможенный сбор | E14: 299.46 | F14: 27540 | I14: 299.46 | J14: 27540
C15: итого по заказу | D15: 19000 | E15: 82994.73 | F15: 7632751.2 | G15: 4.37 | I15: 66616.02 | J15: 6126455.8 | L15: бндс | M15: Корр по курсу
G16: 4.3681436 | K16: =G15-G15/6 -> 3.6416667 | M16: 45740 | N16: 93.2547
C17: * доп услуги пересчитаны в евро по курсу на 09.07.2025 | G17: 401.72375 | K17: 322.44504 | M17: 45869 | N17: 96.8504
M18: 45854 | N18: 92.9762 | O18: =AVERAGE(N17:N18) -> 94.9133
N19: =N16-O18 -> -1.6586
N20: =N19/89.9011 -> -0.018449162
A21: номер заказа | B21: дата ТД | C21: наименование | D21: кол-во | E21: Сумма евро с НДС | F21: Сумма руб с НДС | G21: Себес с НДС, евро | H21: ндс | I21: Сумма евро без НДС | J21: Сумма руб без ндс | K21: Себес без НДС, евро | M21: корр на кг | N21: =N13+N20 -> 0.25317432
A22: 83 | B22: 45971 | C22: Изоцианат Lupranate MI (бочка 225 кг) | D22: 20250 | E22: 49 916,25 | F22: 4 646 756,50 | I22: 49 916,25 | J22: 4 646 756,50
C23: Транспортно-экспедиционное обслуживание по маршруту FCA Istanbul - Mersin - Новороссийск, ULDMERNVK001004, SEGU9862812 40'RF, Инвойс 2025/R0476 от 23.09.2025 | E23: 5792.03 | F23: 523274.05 | H23: без ндс | I23: 5792.03 | J23: 523274.05
C24: Возмещаемые расходы за ТЭУ по оформлению документов: Документационные услуги в импорте/экспорте SEGU9862812 | E24: 863.37 | F24: 78000 | H24: 0 | I24: 863.37 | J24: 78000
C25: Комплекс услуг таможенного представителя по таможенному декларированию товаров, ДТ 10317120/101125/5178711, Инвойс 2025/R0476 от 23.09.2025 | E25: 332.06 | F25: 30000 | H25: 0.2 | I25: 276.72 | J25: 25000
C26: Возмещаемые услуги за услуги платежного агента SEGU9862812 | E26: 100.43 | F26: 9073.48 | H26: 0.2 | I26: 98.64 | J26: 8911.45
C27: Возмещаемые услуги за организацию хранения груженного станд 40'RF контейнера в импорте (неопасный груз) с 08.11-11.11 SEGU9862812 | E27: 287.79 | F27: 26000 | H27: 0 | I27: 287.79 | J27: 26000
C28: Транспортно-экспедиционное обслуживание по маршруту Новороссийск (НУТЭП) - г.Москва (Склад), SEGU9862812 40'RF, Инвойс 2025/R0476 от 23.09.2025 | E28: 2490.49 | F28: 225000 | H28: 0 | I28: 2490.49 | J28: 225000
E29: 0 | H29: 0 | I29: 0 | J29: 0
C30: НДС на таможне | E30: 12103.99 | F30: 1093520.4
C31: Пошлина | E31: 2881.9 | F31: 260362.01 | I31: 2881.9 | J31: 518185.47
C32: Таможенный сбор | E32: 236.25 | F32: 21344 | I32: 236.25 | J32: 30000
