Workbook

Sheet новы
A2: пп | B2: Дата выпуска продукции | C2: курс | D2: № ЗП | E2: Продукт | F2: Вес готового продукта | G2: Израсходовано по факту | H2: Израсходовано по факту Polyether Polyol Puranol D220, LE-220A Пропиленгликоль | I2: Потери, кг | J2: % потерь | K2: СС 1С на дату выпуска, EUR | L2: % пропиленгликоля в составе + полиол | M2: СС КГ, РУБ, Б/НДС | N2: СС Факт , EUR, Б/НДС | O2: СС Партии, EUR, Б/НДС | P2: СС Партии, РУБ, Б/НДС | R2: Примечание
B3: 45992 | C3: =VLOOKUP(B:B,'Курс валют'!A:D,4,0) -> 90.819 | D3: 01L2503-6 | E3: клей Starkbond 521 A бочка 220кг | F3: 4400 | G3: 4473.24 | H3: 78.84 | I3: =G3-F3 -> 73.24 | J3: =I3/F3*100 -> 1.6645455 | K3: 2.57 | L3: =H3/F3*100 -> 1.7918182 | M3: =P3/F3 -> 228.4578 | N3: =(F3*K3-H3*3.04)/F3 -> 2.5155287 | O3: =N3*F3 -> 11068.326 | P3: =O3*C3 -> 1005214.3
B4: 45994 | C4: =VLOOKUP(B:B,'Курс валют'!A:D,4,0) -> 89.8514 | D4: 03L2501-10 | E4: клей Starkbond 521 A бочка 220кг | F4: 11000 | G4: 11333.1 | H4: 197.1 | I4: =G4-F4 -> 333.1 | J4: =I4/F4*100 -> 3.0281818 | K4: 2.61 | L4: =H4/F4*100 -> 1.7918182 | M4: =P4/F4 -> 229.61783 | N4: =(F4*K4-H4*3.04)/F4 -> 2.5555287 | O4: =N4*F4 -> 28110.816 | P4: =O4*C4 -> 2525796.2
B5: 45995 | C5: =VLOOKUP(B:B,'Курс валют'!A:D,4,0) -> 90.5903 | D5: 04L2501-09 | E5: клей Starkbond 521 A бочка 220кг | F5: 9900 | G5: 9965.8 | H5: 177.39 | I5: =G5-F5 -> 65.8 | J5: =I5/F5*100 -> 0.66464646 | K5: 2.57 | L5: =H5/F5*100 -> 1.7918182 | M5: =P5/F5 -> 227.8825 | N5: =(F5*K5-H5*3.04)/F5 -> 2.5155287 | O5: =N5*F5 -> 24903.734 | P5: =O5*C5 -> 2256036.8
B6: 45996 | C6: =VLOOKUP(B:B,'Курс валют'!A:D,4,0) -> 89.9011 | D6: 05L2501-10 | E6: клей Starkbond 521 A бочка 220кг | F6: 11000 | G6: 11093.1 | H6: 4072.29 | I6: =G6-F6 -> 93.1 | J6: =I6/F6*100 -> 0.84636364 | K6: 3.57 | L6: =H6/F6*100 -> 37.020818 | M6: =P6/F6 -> 219.76927 | N6: =(F6*K6-H6*3.04)/F6 -> 2.4445671 | O6: =N6*F6 -> 26890.238 | P6: =O6*C6 -> 2417462
B7: 45997 | C7: =VLOOKUP(B:B,'Курс валют'!A:D,4,0) -> 88.7028 | D7: 06L2501-09 | E7: клей Starkbond 521 A бочка 220кг | F7: 9900 | G7: 9983.8 | H7: 4532.49 | I7: =G7-F7 -> 83.8 | J7: =I7/F7*100 -> 0.84646465 | K7: 3.84 | L7: =H7/F7*100 -> 45.782727 | M7: =P7/F7 -> 217.16265 | N7: =(F7*K7-H7*3.04)/F7 -> 2.4482051 | O7: =N7*F7 -> 24237.23 | P7: =O7*C7 -> 2149910.2
B8: 45998 | C8: =VLOOKUP(B:B,'Курс валют'!A:D,4,0) -> 88.7028 | D8: 07L2501-10 | E8: клей Starkbond 521 A бочка 220кг | F8: 11000 | G8: 11093.1 | H8: 5036.1 | I8: =G8-F8 -> 93.1 | J8: =I8/F8*100 -> 0.84636364 | K8: 3.52 | L8: =H8/F8*100 -> 45.782727 | M8: =P8/F8 -> 188.77775 | N8: =(F8*K8-H8*3.04)/F8 -> 2.1282051 | O8: =N8*F8 -> 23410.256 | P8: =O8*C8 -> 2076555.3
B9: 45999 | C9: =VLOOKUP(B:B,'Курс валют'!A:D,4,0) -> 88.7028 | D9: 08L2501-10 | E9: клей Starkbond 521 A бочка 220кг | F9: 11000 | G9: 11093.1 | H9: =5036.1-96.88 -> 4939.22 | I9: =G9-F9 -> 93.1 | J9: =I9/F9*100 -> 0.84636364 | K9: 3.5 | L9: =H9/F9*100 -> 44.902 | M9: =P9/F9 -> 189.37863 | N9: =(F9*K9-H9*3.04)/F9 -> 2.1349792 | O9: =N9*F9 -> 23484.771 | P9: =O9*C9 -> 2083165
B10: 46000 | C10: =VLOOKUP(B:B,'Курс валют'!A:D,4,0) -> 89.7054 | D10: 09L2502-10 | E10: клей Starkbond 521 A бочка 220кг | F10: 9900 | G10: 9988.3 | H10: 1868.79 | I10: =G10-F10 -> 88.3 | J10: =I10/F10*100 -> 0.89191919 | K10: 2.71 | L10: =H10/F10*100 -> 18.876667 | M10: =P10/F10 -> 191.62413 | N10: =(F10*K10-H10*3.04)/F10 -> 2.1361493 | O10: =N10*F10 -> 21147.878 | P10: =O10*C10 -> 1897078.9
B11: 46001 | C11: =VLOOKUP(B:B,'Курс валют'!A:D,4,0) -> 89.4267 | D11: 10L2501-10 | E11: клей Starkbond 521 A бочка 220кг | F11: 11000 | G11: 11118.1 | H11: 5031.1 | I11: =G11-F11 -> 118.1 | J11: =I11/F11*100 -> 1.0736364 | K11: 3.52 | L11: =H11/F11*100 -> 45.737273 | M11: =P11/F11 -> 190.44193 | N11: =(F11*K11-H11*3.04)/F11 -> 2.1295869 | O11: =N11*F11 -> 23425.456 | P11: =O11*C11 -> 2094861.2

Sheet Курс валют
A1: 45536 | B1: 1 | C1: EUR | D1: 100.7622 | E1: RUB
A2: 45537 | B2: 1 | C2: EUR | D2: 100.7622 | E2: RUB
A3: 45538 | B3: 1 | C3: EUR | D3: 99.2613 | E3: RUB
A4: 45539 | B4: 1 | C4: EUR | D4: 97.8121 | E4: RUB
A5: 45540 | B5: 1 | C5: EUR | D5: 98.0725 | E5: RUB
A6: 45541 | B6: 1 | C6: EUR | D6: 99.1927 | E6: RUB
A7: 45542 | B7: 1 | C7: EUR | D7: 99.7156 | E7: RUB
A8: 45543 | B8: 1 | C8: EUR | D8: 99.7156 | E8: RUB
A9: 45544 | B9: 1 | C9: EUR | D9: 99.7156 | E9: RUB
A10: 45545 | B10: 1 | C10: EUR | D10: 99.9067 | E10: RUB
A11: 45546 | B11: 1 | C11: EUR | D11: 100.4995 | E11: RUB
A12: 45547 | B12: 1 | C12: EUR | D12: 100.7421 | E12: RUB
... A460: 45997 | B460: 1 | C460: EUR | D460: 88.7028 | E460: RUB
A461: 45998 | B461: 1 | C461: EUR | D461: 88.7028 | E461: RUB | F461: 93.5626
A462: 45999 | B462: 1 | C462: EUR | D462: 88.7028 | E462: RUB
A463: 46000 | B463: 1 | C463: EUR | D463: 89.7054 | E463: RUB
A464: 46001 | B464: 1 | C464: EUR | D464: 89.4267 | E464: RUB
A465: 46002 | B465: 1 | C465: EUR | D465: 91.3806 | E465: RUB
A466: 46003 | B466: 1 | C466: EUR | D466: 92.9384 | E466: RUB
A467: 46004 | B467: 1 | C467: EUR | D467: 93.5626 | E467: RUB
A468: 46005 | B468: 1 | C468: EUR | D468: 93.5626 | E468: RUB
A469: 46006 | B469: 1 | C469: EUR | D469: 93.5626 | E469: RUB
A470: 46007 | B470: 1 | C470: EUR | D470: 93.2274 | E470: RUB
A471: 46008 | B471: 1 | C471: EUR | D471: 93.8054 | E471: RUB
A472: 46009 | B472: 1 | C472: EUR | D472: 94.1478 | E472: RUB
A473: 46010 | B473: 1 | C473: EUR | D473: 94.2524 | E473: RUB
... A652: 46189 | B652: 1 | C652: EUR | D652: 83.8044 | E652: RUB
A653: 46190 | B653: 1 | C653: EUR | E653: RUB
A654: 46191 | B654: 1 | C654: EUR | E654: RUB
A655: 46192 | B655: 1 | C655: EUR | E655: RUB
A656: 46193 | B656: 1 | C656: EUR | E656: RUB
A657: 46194 | B657: 1 | C657: EUR | E657: RUB
A658: 46195 | B658: 1 | C658: EUR | E658: RUB
A659: 46196 | B659: 1 | C659: EUR | E659: RUB
A660: 46197 | B660: 1 | C660: EUR | E660: RUB
A661: 46198 | B661: 1 | C661: EUR | E661: RUB
A662: 46199 | B662: 1 | C662: EUR | E662: RUB
E663: RUB
E664: RUB
E665: RUB

Sheet Формула Среднего
A1: Продукт | B1: Сентябрь 24 | C1: Октябрь 24 | D1: Ноябрь 24 | E1: Декабрь 24 | F1: Январь 25 | G1: Февраль 2025 | H1: Март 25 | I1: Апрель 25 | J1: Май 25 | K1: Июнь 25 | L1: Июль 25 | M1: Август 25 | N1: Сентябрь 25 | O1: Октябрь 25 | P1: Ноябрь 25 | Q1: Декабрь 25 | R1: Январь 26 | S1: Февраль 26 | T1: Март 26 | U1: Апрель 2026 | V1: Май 2026 | W1: Июнь 2026 | X1: Июль 2026
A2: Отвердитель Starkbond 521C 10.0 бочка 200кг | B2: =IFERROR(AVERAGEIFS('Сентябрь 2024'!$K:$K,'Сентябрь 2024'!$E:$E,$A:$A),"-") -> 1.946 | C2: =IFERROR(AVERAGEIFS('Октябрь 2024'!$K:$K,'Октябрь 2024'!$E:$E,$A:$A),"-") -> 2.77 | D2: =IFERROR(AVERAGEIFS('Ноябрь 2024'!$K:$K,'Ноябрь 2024'!$E:$E,$A:$A),"-") -> 1.9733333 | E2: =IFERROR(AVERAGEIFS('Декабрь 2024'!$K:$K,'Декабрь 2024'!$E:$E,$A:$A),"-") -> - | F2: =IFERROR(AVERAGEIFS('Январь 2025'!$K:$K,'Январь 2025'!$E:$E,$A:$A),"-") -> 2.0853846 | G2: =IFERROR(AVERAGEIFS('Февраль 2025 '!K:K,'Февраль 2025 '!E:E,A:A),"-") -> 2.02 | H2: =IFERROR(AVERAGEIFS('Март 2025'!$K:$K,'Март 2025'!$E:$E,$A:$A),"-") -> 2.0116667 | I2: =IFERROR(AVERAGEIFS('Апрель 2025'!$K:$K,'Апрель 2025'!$E:$E,$A:$A),"-") -> 1.9366667 | J2: =IFERROR(AVERAGEIFS('Май 2025'!$K:$K,'Май 2025'!$E:$E,$A:$A),"-") -> 1.8828571 | K2: =IFERROR(AVERAGEIFS('Июнь 2025'!$K:$K,'Июнь 2025'!$E:$E,$A:$A),"-") -> 1.8633333 | L2: =IFERROR(AVERAGEIFS('Июль 2025'!$K:$K,'Июль 2025'!$E:$E,$A:$A),"-") -> 2.2175 | M2: =IFERROR(AVERAGEIFS('Август 2025'!$K:$K,'Август 2025'!$E:$E,$A:$A),"-") -> 1.8766667 | N2: =IFERROR(AVERAGEIFS('Сентябрь 2025'!$K:$K,'Сентябрь 2025'!$E:$E,$A:$A),"-") -> 2.02 | O2: =IFERROR(AVERAGEIFS('Октябрь 2025'!$K:$K,'Октябрь 2025'!$E:$E,$A:$A),"-") -> 1.9028571 | P2: =IFERROR(AVERAGEIFS('Ноябрь 2025'!$K:$K,'Ноябрь 2025'!$E:$E,$A:$A),"-") -> 1.9333333 | Q2: =IFERROR(AVERAGEIFS('Декабрь 2025'!$K:$K,'Декабрь 2025'!$E:$E,$A:$A),"-") -> 1.9184615 | R2: =IFERROR(AVERAGEIFS('Январь 2026'!$K:$K,'Январь 2026'!$E:$E,$A:$A),"-") -> 1.97 | S2: =IFERROR(AVERAGEIFS('Февраль 2026'!$K:$K,'Февраль 2026'!$E:$E,$A:$A),"-") -> 1.95 | T2: =IFERROR(AVERAGEIFS('Март 2026'!$K:$K,'Март 2026'!$E:$E,$A:$A),"-") -> 1.9616667 | U2: =IFERROR(AVERAGEIFS('Апрель 2026'!$K:$K,'Апрель 2026'!$E:$E,$A:$A),"-") -> 1.886 | V2: =IFERROR(AVERAGEIFS('Май 2026'!$K:$K,'Май 2026'!$E:$E,$A:$A),"-") -> - | W2: =IFERROR(AVERAGEIFS('Июнь 2026'!$K:$K,'Июнь 2026'!$E:$E,$A:$A),"-") -> - | X2: =IFERROR(AVERAGEIFS('Июль 2026'!$K:$K,'Июль 2026'!$E:$E,$A:$A),"-") -> -
A3: клей Starkbond 521 A бочка 220кг | B3: =IFERROR(AVERAGEIFS('Сентябрь 2024'!$K:$K,'Сентябрь 2024'!$E:$E,$A:$A),"-") -> 3.998125 | C3: =IFERROR(AVERAGEIFS('Октябрь 2024'!$K:$K,'Октябрь 2024'!$E:$E,$A:$A),"-") -> 4.01 | D3: =IFERROR(AVERAGEIFS('Ноябрь 2024'!$K:$K,'Ноябрь 2024'!$E:$E,$A:$A),"-") -> 3.805625 | E3: =IFERROR(AVERAGEIFS('Декабрь 2024'!$K:$K,'Декабрь 2024'!$E:$E,$A:$A),"-") -> 3.58625 | F3: =IFERROR(AVERAGEIFS('Январь 2025'!$K:$K,'Январь 2025'!$E:$E,$A:$A),"-") -> 3.6981818 | G3: =IFERROR(AVERAGEIFS('Февраль 2025 '!K:K,'Февраль 2025 '!E:E,A:A),"-") -> 3.7193333 | H3: =IFERROR(AVERAGEIFS('Март 2025'!$K:$K,'Март 2025'!$E:$E,$A:$A),"-") -> 2.7869231 | I3: =IFERROR(AVERAGEIFS('Апрель 2025'!$K:$K,'Апрель 2025'!$E:$E,$A:$A),"-") -> 2.788125 | J3: =IFERROR(AVERAGEIFS('Май 2025'!$K:$K,'Май 2025'!$E:$E,$A:$A),"-") -> 3.1246667 | K3: =IFERROR(AVERAGEIFS('Июнь 2025'!$K:$K,'Июнь 2025'!$E:$E,$A:$A),"-") -> 3.7633333 | L3: =IFERROR(AVERAGEIFS('Июль 2025'!$K:$K,'Июль 2025'!$E:$E,$A:$A),"-") -> 2.4871429 | M3: =IFERROR(AVERAGEIFS('Август 2025'!$K:$K,'Август 2025'!$E:$E,$A:$A),"-") -> 2.6475 | N3: =IFERROR(AVERAGEIFS('Сентябрь 2025'!$K:$K,'Сентябрь 2025'!$E:$E,$A:$A),"-") -> 3.6257143 | O3: =IFERROR(AVERAGEIFS('Октябрь 2025'!$K:$K,'Октябрь 2025'!$E:$E,$A:$A),"-") -> 3.3088235 | P3: =IFERROR(AVERAGEIFS('Ноябрь 2025'!$K:$K,'Ноябрь 2025'!$E:$E,$A:$A),"-") -> 3.0361538 | Q3: =IFERROR(AVERAGEIFS('Декабрь 2025'!$K:$K,'Декабрь 2025'!$E:$E,$A:$A),"-") -> 3.4235294 | R3: =IFERROR(AVERAGEIFS('Январь 2026'!$K:$K,'Январь 2026'!$E:$E,$A:$A),"-") -> - | S3: =IFERROR(AVERAGEIFS('Февраль 2026'!$K:$K,'Февраль 2026'!$E:$E,$A:$A),"-") -> 3.1130952 | T3: =IFERROR(AVERAGEIFS('Март 2026'!$K:$K,'Март 2026'!$E:$E,$A:$A),"-") -> 2.9145536 | U3: =IFERROR(AVERAGEIFS('Апрель 2026'!$K:$K,'Апрель 2026'!$E:$E,$A:$A),"-") -> 6.4107246 | V3: =IFERROR(AVERAGEIFS('Май 2026'!$K:$K,'Май 2026'!$E:$E,$A:$A),"-") -> 5.2023469 | W3: =IFERROR(AVERAGEIFS('Июнь 2026'!$K:$K,'Июнь 2026'!$E:$E,$A:$A),"-") -> - | X3: =IFERROR(AVERAGEIFS('Июль 2026'!$K:$K,'Июль 2026'!$E:$E,$A:$A),"-") -> -
A4: Отвердитель Starkbond 521C 11.0 бочка 200кг | B4: =IFERROR(AVERAGEIFS('Сентябрь 2024'!$K:$K,'Сентябрь 2024'!$E:$E,$A:$A),"-") -> 1.94 | C4: =IFERROR(AVERAGEIFS('Октябрь 2024'!$K:$K,'Октябрь 2024'!$E:$E,$A:$A),"-") -> 1.99 | D4: =IFERROR(AVERAGEIFS('Ноябрь 2024'!$K:$K,'Ноябрь 2024'!$E:$E,$A:$A),"-") -> 1.9966667 | E4: =IFERROR(AVERAGEIFS('Декабрь 2024'!$K:$K,'Декабрь 2024'!$E:$E,$A:$A),"-") -> - | F4: =IFERROR(AVERAGEIFS('Январь 2025'!$K:$K,'Январь 2025'!$E:$E,$A:$A),"-") -> 2.18 | G4: =IFERROR(AVERAGEIFS('Февраль 2025 '!K:K,'Февраль 2025 '!E:E,A:A),"-") -> - | H4: =IFERROR(AVERAGEIFS('Март 2025'!$K:$K,'Март 2025'!$E:$E,$A:$A),"-") -> 2.18 | I4: =IFERROR(AVERAGEIFS('Апрель 2025'!$K:$K,'Апрель 2025'!$E:$E,$A:$A),"-") -> 2.03 | J4: =IFERROR(AVERAGEIFS('Май 2025'!$K:$K,'Май 2025'!$E:$E,$A:$A),"-") -> - | K4: =IFERROR(AVERAGEIFS('Июнь 2025'!$K:$K,'Июнь 2025'!$E:$E,$A:$A),"-") -> 1.89 | L4: =IFERROR(AVERAGEIFS('Июль 2025'!$K:$K,'Июль 2025'!$E:$E,$A:$A),"-") -> 1.99 | M4: =IFERROR(AVERAGEIFS('Август 2025'!$K:$K,'Август 2025'!$E:$E,$A:$A),"-") -> 1.99 | N4: =IFERROR(AVERAGEIFS('Сентябрь 2025'!$K:$K,'Сентябрь 2025'!$E:$E,$A:$A),"-") -> 1.9266667 | O4: =IFERROR(AVERAGEIFS('Октябрь 2025'!$K:$K,'Октябрь 2025'!$E:$E,$A:$A),"-") -> 1.89375 | P4: =IFERROR(AVERAGEIFS('Ноябрь 2025'!$K:$K,'Ноябрь 2025'!$E:$E,$A:$A),"-") -> 1.91 | Q4: =IFERROR(AVERAGEIFS('Декабрь 2025'!$K:$K,'Декабрь 2025'!$E:$E,$A:$A),"-") -> 2.0478571 | R4: =IFERROR(AVERAGEIFS('Январь 2026'!$K:$K,'Январь 2026'!$E:$E,$A:$A),"-") -> 2.001 | S4: =IFERROR(AVERAGEIFS('Февраль 2026'!$K:$K,'Февраль 2026'!$E:$E,$A:$A),"-") -> - | T4: =IFERROR(AVERAGEIFS('Март 2026'!$K:$K,'Март 2026'!$E:$E,$A:$A),"-") -> 1.9721667 | U4: =IFERROR(AVERAGEIFS('Апрель 2026'!$K:$K,'Апрель 2026'!$E:$E,$A:$A),"-") -> 1.8911429 | V4: =IFERROR(AVERAGEIFS('Май 2026'!$K:$K,'Май 2026'!$E:$E,$A:$A),"-") -> 1.9107692 | W4: =IFERROR(AVERAGEIFS('Июнь 2026'!$K:$K,'Июнь 2026'!$E:$E,$A:$A),"-") -> - | X4: =IFERROR(AVERAGEIFS('Июль 2026'!$K:$K,'Июль 2026'!$E:$E,$A:$A),"-") -> -
A5: отвердитель Starkbond 746/1 С бочка 200кг | B5: =IFERROR(AVERAGEIFS('Сентябрь 2024'!$K:$K,'Сентябрь 2024'!$E:$E,$A:$A),"-") -> - | C5: =IFERROR(AVERAGEIFS('Октябрь 2024'!$K:$K,'Октябрь 2024'!$E:$E,$A:$A),"-") -> - | D5: =IFERROR(AVERAGEIFS('Ноябрь 2024'!$K:$K,'Ноябрь 2024'!$E:$E,$A:$A),"-") -> - | E5: =IFERROR(AVERAGEIFS('Декабрь 2024'!$K:$K,'Декабрь 2024'!$E:$E,$A:$A),"-") -> - | F5: =IFERROR(AVERAGEIFS('Январь 2025'!$K:$K,'Январь 2025'!$E:$E,$A:$A),"-") -> - | G5: =IFERROR(AVERAGEIFS('Февраль 2025 '!K:K,'Февраль 2025 '!E:E,A:A),"-") -> 2.62 | H5: =IFERROR(AVERAGEIFS('Март 2025'!$K:$K,'Март 2025'!$E:$E,$A:$A),"-") -> 2.715 | I5: =IFERROR(AVERAGEIFS('Апрель 2025'!$K:$K,'Апрель 2025'!$E:$E,$A:$A),"-") -> - | J5: =IFERROR(AVERAGEIFS('Май 2025'!$K:$K,'Май 2025'!$E:$E,$A:$A),"-") -> - | K5: =IFERROR(AVERAGEIFS('Июнь 2025'!$K:$K,'Июнь 2025'!$E:$E,$A:$A),"-") -> - | L5: =IFERROR(AVERAGEIFS('Июль 2025'!$K:$K,'Июль 2025'!$E:$E,$A:$A),"-") -> - | M5: =IFERROR(AVERAGEIFS('Август 2025'!$K:$K,'Август 2025'!$E:$E,$A:$A),"-") -> - | N5: =IFERROR(AVERAGEIFS('Сентябрь 2025'!$K:$K,'Сентябрь 2025'!$E:$E,$A:$A),"-") -> 2.69 | O5: =IFERROR(AVERAGEIFS('Октябрь 2025'!$K:$K,'Октябрь 2025'!$E:$E,$A:$A),"-") -> 2.6 | P5: =IFERROR(AVERAGEIFS('Ноябрь 2025'!$K:$K,'Ноябрь 2025'!$E:$E,$A:$A),"-") -> 2.68 | Q5: =IFERROR(AVERAGEIFS('Декабрь 2025'!$K:$K,'Декабрь 2025'!$E:$E,$A:$A),"-") -> - | R5: =IFERROR(AVERAGEIFS('Январь 2026'!$K:$K,'Январь 2026'!$E:$E,$A:$A),"-") -> 2.74 | S5: =IFERROR(AVERAGEIFS('Февраль 2026'!$K:$K,'Февраль 2026'!$E:$E,$A:$A),"-") -> - | T5: =IFERROR(AVERAGEIFS('Март 2026'!$K:$K,'Март 2026'!$E:$E,$A:$A),"-") -> 2.75 | U5: =IFERROR(AVERAGEIFS('Апрель 2026'!$K:$K,'Апрель 2026'!$E:$E,$A:$A),"-") -> 2.765 | V5: =IFERROR(AVERAGEIFS('Май 2026'!$K:$K,'Май 2026'!$E:$E,$A:$A),"-") -> 2.78 | W5: =IFERROR(AVERAGEIFS('Июнь 2026'!$K:$K,'Июнь 2026'!$E:$E,$A:$A),"-") -> - | X5: =IFERROR(AVERAGEIFS('Июль 2026'!$K:$K,'Июль 2026'!$E:$E,$A:$A),"-") -> -
A6: Отвердитель Starkbond 525C 2.0 Бочка 200 кг | B6: =IFERROR(AVERAGEIFS('Сентябрь 2024'!$K:$K,'Сентябрь 2024'!$E:$E,$A:$A),"-") -> 3.42 | C6: =IFERROR(AVERAGEIFS('Октябрь 2024'!$K:$K,'Октябрь 2024'!$E:$E,$A:$A),"-") -> 3.33 | D6: =IFERROR(AVERAGEIFS('Ноябрь 2024'!$K:$K,'Ноябрь 2024'!$E:$E,$A:$A),"-") -> 3.22 | E6: =IFERROR(AVERAGEIFS('Декабрь 2024'!$K:$K,'Декабрь 2024'!$E:$E,$A:$A),"-") -> - | F6: =IFERROR(AVERAGEIFS('Январь 2025'!$K:$K,'Январь 2025'!$E:$E,$A:$A),"-") -> - | G6: =IFERROR(AVERAGEIFS('Февраль 2025 '!K:K,'Февраль 2025 '!E:E,A:A),"-") -> 3.19 | H6: =IFERROR(AVERAGEIFS('Март 2025'!$K:$K,'Март 2025'!$E:$E,$A:$A),"-") -> 3.185 | I6: =IFERROR(AVERAGEIFS('Апрель 2025'!$K:$K,'Апрель 2025'!$E:$E,$A:$A),"-") -> - | J6: =IFERROR(AVERAGEIFS('Май 2025'!$K:$K,'Май 2025'!$E:$E,$A:$A),"-") -> - | K6: =IFERROR(AVERAGEIFS('Июнь 2025'!$K:$K,'Июнь 2025'!$E:$E,$A:$A),"-") -> - | L6: =IFERROR(AVERAGEIFS('Июль 2025'!$K:$K,'Июль 2025'!$E:$E,$A:$A),"-") -> - | M6: =IFERROR(AVERAGEIFS('Август 2025'!$K:$K,'Август 2025'!$E:$E,$A:$A),"-") -> - | N6: =IFERROR(AVERAGEIFS('Сентябрь 2025'!$K:$K,'Сентябрь 2025'!$E:$E,$A:$A),"-") -> - | O6: =IFERROR(AVERAGEIFS('Октябрь 2025'!$K:$K,'Октябрь 2025'!$E:$E,$A:$A),"-") -> - | P6: =IFERROR(AVERAGEIFS('Ноябрь 2025'!$K:$K,'Ноябрь 2025'!$E:$E,$A:$A),"-") -> - | Q6: =IFERROR(AVERAGEIFS('Декабрь 2025'!$K:$K,'Декабрь 2025'!$E:$E,$A:$A),"-") -> - | R6: =IFERROR(AVERAGEIFS('Январь 2026'!$K:$K,'Январь 2026'!$E:$E,$A:$A),"-") -> - | S6: =IFERROR(AVERAGEIFS('Февраль 2026'!$K:$K,'Февраль 2026'!$E:$E,$A:$A),"-") -> - | T6: =IFERROR(AVERAGEIFS('Март 2026'!$K:$K,'Март 2026'!$E:$E,$A:$A),"-") -> - | U6: =IFERROR(AVERAGEIFS('Апрель 2026'!$K:$K,'Апрель 2026'!$E:$E,$A:$A),"-") -> - | V6: =IFERROR(AVERAGEIFS('Май 2026'!$K:$K,'Май 2026'!$E:$E,$A:$A),"-") -> - | W6: =IFERROR(AVERAGEIFS('Июнь 2026'!$K:$K,'Июнь 2026'!$E:$E,$A:$A),"-") -> - | X6: =IFERROR(AVERAGEIFS('Июль 2026'!$K:$K,'Июль 2026'!$E:$E,$A:$A),"-") -> -
A7: Отвердитель Starkbond 525C 3.0 Бочка 200 кг | B7: =IFERROR(AVERAGEIFS('Сентябрь 2024'!$K:$K,'Сентябрь 2024'!$E:$E,$A:$A),"-") -> - | C7: =IFERROR(AVERAGEIFS('Октябрь 2024'!$K:$K,'Октябрь 2024'!$E:$E,$A:$A),"-") -> - | D7: =IFERROR(AVERAGEIFS('Ноябрь 2024'!$K:$K,'Ноябрь 2024'!$E:$E,$A:$A),"-") -> - | E7: =IFERROR(AVERAGEIFS('Декабрь 2024'!$K:$K,'Декабрь 2024'!$E:$E,$A:$A),"-") -> - | F7: =IFERROR(AVERAGEIFS('Январь 2025'!$K:$K,'Январь 2025'!$E:$E,$A:$A),"-") -> 3.01 | G7: =IFERROR(AVERAGEIFS('Февраль 2025 '!K:K,'Февраль 2025 '!E:E,A:A),"-") -> - | H7: =IFERROR(AVERAGEIFS('Март 2025'!$K:$K,'Март 2025'!$E:$E,$A:$A),"-") -> 2.9 | I7: =IFERROR(AVERAGEIFS('Апрель 2025'!$K:$K,'Апрель 2025'!$E:$E,$A:$A),"-") -> - | J7: =IFERROR(AVERAGEIFS('Май 2025'!$K:$K,'Май 2025'!$E:$E,$A:$A),"-") -> 3.225 | K7: =IFERROR(AVERAGEIFS('Июнь 2025'!$K:$K,'Июнь 2025'!$E:$E,$A:$A),"-") -> 2.7133333 | L7: =IFERROR(AVERAGEIFS('Июль 2025'!$K:$K,'Июль 2025'!$E:$E,$A:$A),"-") -> 2.5933333 | M7: =IFERROR(AVERAGEIFS('Август 2025'!$K:$K,'Август 2025'!$E:$E,$A:$A),"-") -> - | N7: =IFERROR(AVERAGEIFS('Сентябрь 2025'!$K:$K,'Сентябрь 2025'!$E:$E,$A:$A),"-") -> - | O7: =IFERROR(AVERAGEIFS('Октябрь 2025'!$K:$K,'Октябрь 2025'!$E:$E,$A:$A),"-") -> - | P7: =IFERROR(AVERAGEIFS('Ноябрь 2025'!$K:$K,'Ноябрь 2025'!$E:$E,$A:$A),"-") -> - | Q7: =IFERROR(AVERAGEIFS('Декабрь 2025'!$K:$K,'Декабрь 2025'!$E:$E,$A:$A),"-") -> 2.53 | R7: =IFERROR(AVERAGEIFS('Январь 2026'!$K:$K,'Январь 2026'!$E:$E,$A:$A),"-") -> - | S7: =IFERROR(AVERAGEIFS('Февраль 2026'!$K:$K,'Февраль 2026'!$E:$E,$A:$A),"-") -> - | T7: =IFERROR(AVERAGEIFS('Март 2026'!$K:$K,'Март 2026'!$E:$E,$A:$A),"-") -> - | U7: =IFERROR(AVERAGEIFS('Апрель 2026'!$K:$K,'Апрель 2026'!$E:$E,$A:$A),"-") -> - | V7: =IFERROR(AVERAGEIFS('Май 2026'!$K:$K,'Май 2026'!$E:$E,$A:$A),"-") -> 2.5725 | W7: =IFERROR(AVERAGEIFS('Июнь 2026'!$K:$K,'Июнь 2026'!$E:$E,$A:$A),"-") -> - | X7: =IFERROR(AVERAGEIFS('Июль 2026'!$K:$K,'Июль 2026'!$E:$E,$A:$A),"-") -> -
A8: отвердитель Starkbond 525C v0 (ведро 22 кг) | B8: =IFERROR(AVERAGEIFS('Сентябрь 2024'!$K:$K,'Сентябрь 2024'!$E:$E,$A:$A),"-") -> - | C8: =IFERROR(AVERAGEIFS('Октябрь 2024'!$K:$K,'Октябрь 2024'!$E:$E,$A:$A),"-") -> - | D8: =IFERROR(AVERAGEIFS('Ноябрь 2024'!$K:$K,'Ноябрь 2024'!$E:$E,$A:$A),"-") -> - | E8: =IFERROR(AVERAGEIFS('Декабрь 2024'!$K:$K,'Декабрь 2024'!$E:$E,$A:$A),"-") -> - | F8: =IFERROR(AVERAGEIFS('Январь 2025'!$K:$K,'Январь 2025'!$E:$E,$A:$A),"-") -> - | G8: =IFERROR(AVERAGEIFS('Февраль 2025 '!K:K,'Февраль 2025 '!E:E,A:A),"-") -> - | H8: =IFERROR(AVERAGEIFS('Март 2025'!$K:$K,'Март 2025'!$E:$E,$A:$A),"-") -> 2.86 | I8: =IFERROR(AVERAGEIFS('Апрель 2025'!$K:$K,'Апрель 2025'!$E:$E,$A:$A),"-") -> - | J8: =IFERROR(AVERAGEIFS('Май 2025'!$K:$K,'Май 2025'!$E:$E,$A:$A),"-") -> - | K8: =IFERROR(AVERAGEIFS('Июнь 2025'!$K:$K,'Июнь 2025'!$E:$E,$A:$A),"-") -> - | L8: =IFERROR(AVERAGEIFS('Июль 2025'!$K:$K,'Июль 2025'!$E:$E,$A:$A),"-") -> - | M8: =IFERROR(AVERAGEIFS('Август 2025'!$K:$K,'Август 2025'!$E:$E,$A:$A),"-") -> - | N8: =IFERROR(AVERAGEIFS('Сентябрь 2025'!$K:$K,'Сентябрь 2025'!$E:$E,$A:$A),"-") -> - | O8: =IFERROR(AVERAGEIFS('Октябрь 2025'!$K:$K,'Октябрь 2025'!$E:$E,$A:$A),"-") -> - | P8: =IFERROR(AVERAGEIFS('Ноябрь 2025'!$K:$K,'Ноябрь 2025'!$E:$E,$A:$A),"-") -> - | Q8: =IFERROR(AVERAGEIFS('Декабрь 2025'!$K:$K,'Декабрь 2025'!$E:$E,$A:$A),"-") -> - | R8: =IFERROR(AVERAGEIFS('Январь 2026'!$K:$K,'Январь 2026'!$E:$E,$A:$A),"-") -> - | S8: =IFERROR(AVERAGEIFS('Февраль 2026'!$K:$K,'Февраль 2026'!$E:$E,$A:$A),"-") -> - | T8: =IFERROR(AVERAGEIFS('Март 2026'!$K:$K,'Март 2026'!$E:$E,$A:$A),"-") -> - | U8: =IFERROR(AVERAGEIFS('Апрель 2026'!$K:$K,'Апрель 2026'!$E:$E,$A:$A),"-") -> - | V8: =IFERROR(AVERAGEIFS('Май 2026'!$K:$K,'Май 2026'!$E:$E,$A:$A),"-") -> - | W8: =IFERROR(AVERAGEIFS('Июнь 2026'!$K:$K,'Июнь 2026'!$E:$E,$A:$A),"-") -> - | X8: =IFERROR(AVERAGEIFS('Июль 2026'!$K:$K,'Июль 2026'!$E:$E,$A:$A),"-") -> -
A9: Клей Starkbond 745/41 А (бочка 200 кг) | B9: =IFERROR(AVERAGEIFS('Сентябрь 2024'!$K:$K,'Сентябрь 2024'!$E:$E,$A:$A),"-") -> 3.24625 | C9: =IFERROR(AVERAGEIFS('Октябрь 2024'!$K:$K,'Октябрь 2024'!$E:$E,$A:$A),"-") -> - | D9: =IFERROR(AVERAGEIFS('Ноябрь 2024'!$K:$K,'Ноябрь 2024'!$E:$E,$A:$A),"-") -> 3.03 | E9: =IFERROR(AVERAGEIFS('Декабрь 2024'!$K:$K,'Декабрь 2024'!$E:$E,$A:$A),"-") -> - | F9: =IFERROR(AVERAGEIFS('Январь 2025'!$K:$K,'Январь 2025'!$E:$E,$A:$A),"-") -> - | G9: =IFERROR(AVERAGEIFS('Февраль 2025 '!K:K,'Февраль 2025 '!E:E,A:A),"-") -> 3.07 | H9: =IFERROR(AVERAGEIFS('Март 2025'!$K:$K,'Март 2025'!$E:$E,$A:$A),"-") -> 3.12 | I9: =IFERROR(AVERAGEIFS('Апрель 2025'!$K:$K,'Апрель 2025'!$E:$E,$A:$A),"-") -> 3.1766667 | J9: =IFERROR(AVERAGEIFS('Май 2025'!$K:$K,'Май 2025'!$E:$E,$A:$A),"-") -> 3.15625 | K9: =IFERROR(AVERAGEIFS('Июнь 2025'!$K:$K,'Июнь 2025'!$E:$E,$A:$A),"-") -> - | L9: =IFERROR(AVERAGEIFS('Июль 2025'!$K:$K,'Июль 2025'!$E:$E,$A:$A),"-") -> - | M9: =IFERROR(AVERAGEIFS('Август 2025'!$K:$K,'Август 2025'!$E:$E,$A:$A),"-") -> 2.3375 | N9: =IFERROR(AVERAGEIFS('Сентябрь 2025'!$K:$K,'Сентябрь 2025'!$E:$E,$A:$A),"-") -> 2.48 | O9: =IFERROR(AVERAGEIFS('Октябрь 2025'!$K:$K,'Октябрь 2025'!$E:$E,$A:$A),"-") -> 2.296 | P9: =IFERROR(AVERAGEIFS('Ноябрь 2025'!$K:$K,'Ноябрь 2025'!$E:$E,$A:$A),"-") -> 2.3 | Q9: =IFERROR(AVERAGEIFS('Декабрь 2025'!$K:$K,'Декабрь 2025'!$E:$E,$A:$A),"-") -> 2.38 | R9: =IFERROR(AVERAGEIFS('Январь 2026'!$K:$K,'Январь 2026'!$E:$E,$A:$A),"-") -> 2.24 | S9: =IFERROR(AVERAGEIFS('Февраль 2026'!$K:$K,'Февраль 2026'!$E:$E,$A:$A),"-") -> 2.3433333 | T9: =IFERROR(AVERAGEIFS('Март 2026'!$K:$K,'Март 2026'!$E:$E,$A:$A),"-") -> 2.37 | U9: =IFERROR(AVERAGEIFS('Апрель 2026'!$K:$K,'Апрель 2026'!$E:$E,$A:$A),"-") -> 2.36 | V9: =IFERROR(AVERAGEIFS('Май 2026'!$K:$K,'Май 2026'!$E:$E,$A:$A),"-") -> 2.43 | W9: =IFERROR(AVERAGEIFS('Июнь 2026'!$K:$K,'Июнь 2026'!$E:$E,$A:$A),"-") -> - | X9: =IFERROR(AVERAGEIFS('Июль 2026'!$K:$K,'Июль 2026'!$E:$E,$A:$A),"-") -> -
A10: Клей Starkbond 525A бочка 200 кг | B10: =IFERROR(AVERAGEIFS('Сентябрь 2024'!$K:$K,'Сентябрь 2024'!$E:$E,$A:$A),"-") -> - | C10: =IFERROR(AVERAGEIFS('Октябрь 2024'!$K:$K,'Октябрь 2024'!$E:$E,$A:$A),"-") -> - | D10: =IFERROR(AVERAGEIFS('Ноябрь 2024'!$K:$K,'Ноябрь 2024'!$E:$E,$A:$A),"-") -> - | E10: =IFERROR(AVERAGEIFS('Декабрь 2024'!$K:$K,'Декабрь 2024'!$E:$E,$A:$A),"-") -> - | F10: =IFERROR(AVERAGEIFS('Январь 2025'!$K:$K,'Январь 2025'!$E:$E,$A:$A),"-") -> 3.91 | G10: =IFERROR(AVERAGEIFS('Февраль 2025 '!K:K,'Февраль 2025 '!E:E,A:A),"-") -> - | H10: =IFERROR(AVERAGEIFS('Март 2025'!$K:$K,'Март 2025'!$E:$E,$A:$A),"-") -> - | I10: =IFERROR(AVERAGEIFS('Апрель 2025'!$K:$K,'Апрель 2025'!$E:$E,$A:$A),"-") -> 2.78 | J10: =IFERROR(AVERAGEIFS('Май 2025'!$K:$K,'Май 2025'!$E:$E,$A:$A),"-") -> 2.66875 | K10: =IFERROR(AVERAGEIFS('Июнь 2025'!$K:$K,'Июнь 2025'!$E:$E,$A:$A),"-") -> 3.7985714 | L10: =IFERROR(AVERAGEIFS('Июль 2025'!$K:$K,'Июль 2025'!$E:$E,$A:$A),"-") -> 3.0855556 | M10: =IFERROR(AVERAGEIFS('Август 2025'!$K:$K,'Август 2025'!$E:$E,$A:$A),"-") -> - | N10: =IFERROR(AVERAGEIFS('Сентябрь 2025'!$K:$K,'Сентябрь 2025'!$E:$E,$A:$A),"-") -> - | O10: =IFERROR(AVERAGEIFS('Октябрь 2025'!$K:$K,'Октябрь 2025'!$E:$E,$A:$A),"-") -> - | P10: =IFERROR(AVERAGEIFS('Ноябрь 2025'!$K:$K,'Ноябрь 2025'!$E:$E,$A:$A),"-") -> - | Q10: =IFERROR(AVERAGEIFS('Декабрь 2025'!$K:$K,'Декабрь 2025'!$E:$E,$A:$A),"-") -> - | R10: =IFERROR(AVERAGEIFS('Январь 2026'!$K:$K,'Январь 2026'!$E:$E,$A:$A),"-") -> - | S10: =IFERROR(AVERAGEIFS('Февраль 2026'!$K:$K,'Февраль 2026'!$E:$E,$A:$A),"-") -> 2.44 | T10: =IFERROR(AVERAGEIFS('Март 2026'!$K:$K,'Март 2026'!$E:$E,$A:$A),"-") -> - | U10: =IFERROR(AVERAGEIFS('Апрель 2026'!$K:$K,'Апрель 2026'!$E:$E,$A:$A),"-") -> - | V10: =IFERROR(AVERAGEIFS('Май 2026'!$K:$K,'Май 2026'!$E:$E,$A:$A),"-") -> 2.6 | W10: =IFERROR(AVERAGEIFS('Июнь 2026'!$K:$K,'Июнь 2026'!$E:$E,$A:$A),"-") -> - | X10: =IFERROR(AVERAGEIFS('Июль 2026'!$K:$K,'Июль 2026'!$E:$E,$A:$A),"-") -> -
A11: Клей Starkbond 522A бочка 220 кг | B11: =IFERROR(AVERAGEIFS('Сентябрь 2024'!$K:$K,'Сентябрь 2024'!$E:$E,$A:$A),"-") -> 3.86 | C11: =IFERROR(AVERAGEIFS('Октябрь 2024'!$K:$K,'Октябрь 2024'!$E:$E,$A:$A),"-") -> - | D11: =IFERROR(AVERAGEIFS('Ноябрь 2024'!$K:$K,'Ноябрь 2024'!$E:$E,$A:$A),"-") -> 3.7216667 | E11: =IFERROR(AVERAGEIFS('Декабрь 2024'!$K:$K,'Декабрь 2024'!$E:$E,$A:$A),"-") -> 3.598 | F11: =IFERROR(AVERAGEIFS('Январь 2025'!$K:$K,'Январь 2025'!$E:$E,$A:$A),"-") -> - | G11: =IFERROR(AVERAGEIFS('Февраль 2025 '!K:K,'Февраль 2025 '!E:E,A:A),"-") -> 3.0633333 | H11: =IFERROR(AVERAGEIFS('Март 2025'!$K:$K,'Март 2025'!$E:$E,$A:$A),"-") -> - | I11: =IFERROR(AVERAGEIFS('Апрель 2025'!$K:$K,'Апрель 2025'!$E:$E,$A:$A),"-") -> 2.85 | J11: =IFERROR(AVERAGEIFS('Май 2025'!$K:$K,'Май 2025'!$E:$E,$A:$A),"-") -> - | K11: =IFERROR(AVERAGEIFS('Июнь 2025'!$K:$K,'Июнь 2025'!$E:$E,$A:$A),"-") -> 3.7566667 | L11: =IFERROR(AVERAGEIFS('Июль 2025'!$K:$K,'Июль 2025'!$E:$E,$A:$A),"-") -> 2.62 | M11: =IFERROR(AVERAGEIFS('Август 2025'!$K:$K,'Август 2025'!$E:$E,$A:$A),"-") -> 2.6128571 | N11: =IFERROR(AVERAGEIFS('Сентябрь 2025'!$K:$K,'Сентябрь 2025'!$E:$E,$A:$A),"-") -> 3.0866667 | O11: =IFERROR(AVERAGEIFS('Октябрь 2025'!$K:$K,'Октябрь 2025'!$E:$E,$A:$A),"-") -> 3.0075 | P11: =IFERROR(AVERAGEIFS('Ноябрь 2025'!$K:$K,'Ноябрь 2025'!$E:$E,$A:$A),"-") -> 2.8933333 | Q11: =IFERROR(AVERAGEIFS('Декабрь 2025'!$K:$K,'Декабрь 2025'!$E:$E,$A:$A),"-") -> 3.2975 | R11: =IFERROR(AVERAGEIFS('Январь 2026'!$K:$K,'Январь 2026'!$E:$E,$A:$A),"-") -> 3.7175 | S11: =IFERROR(AVERAGEIFS('Февраль 2026'!$K:$K,'Февраль 2026'!$E:$E,$A:$A),"-") -> 2.3172414 | T11: =IFERROR(AVERAGEIFS('Март 2026'!$K:$K,'Март 2026'!$E:$E,$A:$A),"-") -> 3.1984615 | U11: =IFERROR(AVERAGEIFS('Апрель 2026'!$K:$K,'Апрель 2026'!$E:$E,$A:$A),"-") -> 2.4441667 | V11: =IFERROR(AVERAGEIFS('Май 2026'!$K:$K,'Май 2026'!$E:$E,$A:$A),"-") -> 2.466129 | W11: =IFERROR(AVERAGEIFS('Июнь 2026'!$K:$K,'Июнь 2026'!$E:$E,$A:$A),"-") -> - | X11: =IFERROR(AVERAGEIFS('Июль 2026'!$K:$K,'Июль 2026'!$E:$E,$A:$A),"-") -> -
A12: Отвердитель Starkbond 747С ведро 5 кг | B12: =IFERROR(AVERAGEIFS('Сентябрь 2024'!$K:$K,'Сентябрь 2024'!$E:$E,$A:$A),"-") -> - | C12: =IFERROR(AVERAGEIFS('Октябрь 2024'!$K:$K,'Октябрь 2024'!$E:$E,$A:$A),"-") -> - | D12: =IFERROR(AVERAGEIFS('Ноябрь 2024'!$K:$K,'Ноябрь 2024'!$E:$E,$A:$A),"-") -> - | E12: =IFERROR(AVERAGEIFS('Декабрь 2024'!$K:$K,'Декабрь 2024'!$E:$E,$A:$A),"-") -> - | F12: =IFERROR(AVERAGEIFS('Январь 2025'!$K:$K,'Январь 2025'!$E:$E,$A:$A),"-") -> - | G12: =IFERROR(AVERAGEIFS('Февраль 2025 '!K:K,'Февраль 2025 '!E:E,A:A),"-") -> - | H12: =IFERROR(AVERAGEIFS('Март 2025'!$K:$K,'Март 2025'!$E:$E,$A:$A),"-") -> 3.17 | I12: =IFERROR(AVERAGEIFS('Апрель 2025'!$K:$K,'Апрель 2025'!$E:$E,$A:$A),"-") -> - | J12: =IFERROR(AVERAGEIFS('Май 2025'!$K:$K,'Май 2025'!$E:$E,$A:$A),"-") -> - | K12: =IFERROR(AVERAGEIFS('Июнь 2025'!$K:$K,'Июнь 2025'!$E:$E,$A:$A),"-") -> - | L12: =IFERROR(AVERAGEIFS('Июль 2025'!$K:$K,'Июль 2025'!$E:$E,$A:$A),"-") -> - | M12: =IFERROR(AVERAGEIFS('Август 2025'!$K:$K,'Август 2025'!$E:$E,$A:$A),"-") -> - | N12: =IFERROR(AVERAGEIFS('Сентябрь 2025'!$K:$K,'Сентябрь 2025'!$E:$E,$A:$A),"-") -> - | O12: =IFERROR(AVERAGEIFS('Октябрь 2025'!$K:$K,'Октябрь 2025'!$E:$E,$A:$A),"-") -> - | P12: =IFERROR(AVERAGEIFS('Ноябрь 2025'!$K:$K,'Ноябрь 2025'!$E:$E,$A:$A),"-") -> - | Q12: =IFERROR(AVERAGEIFS('Декабрь 2025'!$K:$K,'Декабрь 2025'!$E:$E,$A:$A),"-") -> - | R12: =IFERROR(AVERAGEIFS('Январь 2026'!$K:$K,'Январь 2026'!$E:$E,$A:$A),"-") -> - | S12: =IFERROR(AVERAGEIFS('Февраль 2026'!$K:$K,'Февраль 2026'!$E:$E,$A:$A),"-") -> - | T12: =IFERROR(AVERAGEIFS('Март 2026'!$K:$K,'Март 2026'!$E:$E,$A:$A),"-") -> - | U12: =IFERROR(AVERAGEIFS('Апрель 2026'!$K:$K,'Апрель 2026'!$E:$E,$A:$A),"-") -> - | V12: =IFERROR(AVERAGEIFS('Май 2026'!$K:$K,'Май 2026'!$E:$E,$A:$A),"-") -> - | W12: =IFERROR(AVERAGEIFS('Июнь 2026'!$K:$K,'Июнь 2026'!$E:$E,$A:$A),"-") -> - | X12: =IFERROR(AVERAGEIFS('Июль 2026'!$K:$K,'Июль 2026'!$E:$E,$A:$A),"-") -> -
A13: Клей Starkbond 2014 бочка 225кг | B13: =IFERROR(AVERAGEIFS('Сентябрь 2024'!$K:$K,'Сентябрь 2024'!$E:$E,$A:$A),"-") -> 3.2353333 | C13: =IFERROR(AVERAGEIFS('Октябрь 2024'!$K:$K,'Октябрь 2024'!$E:$E,$A:$A),"-") -> 3.3494118 | D13: =IFERROR(AVERAGEIFS('Ноябрь 2024'!$K:$K,'Ноябрь 2024'!$E:$E,$A:$A),"-") -> 3.1477778 | E13: =IFERROR(AVERAGEIFS('Декабрь 2024'!$K:$K,'Декабрь 2024'!$E:$E,$A:$A),"-") -> 2.76 | F13: =IFERROR(AVERAGEIFS('Январь 2025'!$K:$K,'Январь 2025'!$E:$E,$A:$A),"-") -> 3.18 | G13: =IFERROR(AVERAGEIFS('Февраль 2025 '!K:K,'Февраль 2025 '!E:E,A:A),"-") -> 3.3223077 | H13: =IFERROR(AVERAGEIFS('Март 2025'!$K:$K,'Март 2025'!$E:$E,$A:$A),"-") -> 2.50875 | I13: =IFERROR(AVERAGEIFS('Апрель 2025'!$K:$K,'Апрель 2025'!$E:$E,$A:$A),"-") -> 2.1714286 | J13: =IFERROR(AVERAGEIFS('Май 2025'!$K:$K,'Май 2025'!$E:$E,$A:$A),"-") -> 2.6966667 | K13: =IFERROR(AVERAGEIFS('Июнь 2025'!$K:$K,'Июнь 2025'!$E:$E,$A:$A),"-") -> - | L13: =IFERROR(AVERAGEIFS('Июль 2025'!$K:$K,'Июль 2025'!$E:$E,$A:$A),"-") -> 2.5082353 | M13: =IFERROR(AVERAGEIFS('Август 2025'!$K:$K,'Август 2025'!$E:$E,$A:$A),"-") -> 2.4675 | N13: =IFERROR(AVERAGEIFS('Сентябрь 2025'!$K:$K,'Сентябрь 2025'!$E:$E,$A:$A),"-") -> 3.1866667 | O13: =IFERROR(AVERAGEIFS('Октябрь 2025'!$K:$K,'Октябрь 2025'!$E:$E,$A:$A),"-") -> 3.1 | P13: =IFERROR(AVERAGEIFS('Ноябрь 2025'!$K:$K,'Ноябрь 2025'!$E:$E,$A:$A),"-") -> 3.075 | Q13: =IFERROR(AVERAGEIFS('Декабрь 2025'!$K:$K,'Декабрь 2025'!$E:$E,$A:$A),"-") -> - | R13: =IFERROR(AVERAGEIFS('Январь 2026'!$K:$K,'Январь 2026'!$E:$E,$A:$A),"-") -> - | S13: =IFERROR(AVERAGEIFS('Февраль 2026'!$K:$K,'Февраль 2026'!$E:$E,$A:$A),"-") -> 3.29 | T13: =IFERROR(AVERAGEIFS('Март 2026'!$K:$K,'Март 2026'!$E:$E,$A:$A),"-") -> - | U13: =IFERROR(AVERAGEIFS('Апрель 2026'!$K:$K,'Апрель 2026'!$E:$E,$A:$A),"-") -> 1.9558333 | V13: =IFERROR(AVERAGEIFS('Май 2026'!$K:$K,'Май 2026'!$E:$E,$A:$A),"-") -> 2.092 | W13: =IFERROR(AVERAGEIFS('Июнь 2026'!$K:$K,'Июнь 2026'!$E:$E,$A:$A),"-") -> - | X13: =IFERROR(AVERAGEIFS('Июль 2026'!$K:$K,'Июль 2026'!$E:$E,$A:$A),"-") -> -
... A85: Sancos Pro Safety 145 канистра 11,59 кг | B85: =IFERROR(AVERAGEIFS('Сентябрь 2024'!$K:$K,'Сентябрь 2024'!$E:$E,$A:$A),"-") -> - | C85: =IFERROR(AVERAGEIFS('Октябрь 2024'!$K:$K,'Октябрь 2024'!$E:$E,$A:$A),"-") -> - | D85: =IFERROR(AVERAGEIFS('Ноябрь 2024'!$K:$K,'Ноябрь 2024'!$E:$E,$A:$A),"-") -> - | E85: =IFERROR(AVERAGEIFS('Декабрь 2024'!$K:$K,'Декабрь 2024'!$E:$E,$A:$A),"-") -> - | F85: =IFERROR(AVERAGEIFS('Январь 2025'!$K:$K,'Январь 2025'!$E:$E,$A:$A),"-") -> - | G85: =IFERROR(AVERAGEIFS('Февраль 2025 '!K:K,'Февраль 2025 '!E:E,A:A),"-") -> - | H85: =IFERROR(AVERAGEIFS('Март 2025'!$K:$K,'Март 2025'!$E:$E,$A:$A),"-") -> - | I85: =IFERROR(AVERAGEIFS('Апрель 2025'!$K:$K,'Апрель 2025'!$E:$E,$A:$A),"-") -> - | J85: =IFERROR(AVERAGEIFS('Май 2025'!$K:$K,'Май 2025'!$E:$E,$A:$A),"-") -> - | K85: =IFERROR(AVERAGEIFS('Июнь 2025'!$K:$K,'Июнь 2025'!$E:$E,$A:$A),"-") -> - | L85: =IFERROR(AVERAGEIFS('Июль 2025'!$K:$K,'Июль 2025'!$E:$E,$A:$A),"-") -> - | M85: =IFERROR(AVERAGEIFS('Август 2025'!$K:$K,'Август 2025'!$E:$E,$A:$A),"-") -> - | N85: =IFERROR(AVERAGEIFS('Сентябрь 2025'!$K:$K,'Сентябрь 2025'!$E:$E,$A:$A),"-") -> 1.48 | O85: =IFERROR(AVERAGEIFS('Октябрь 2025'!$K:$K,'Октябрь 2025'!$E:$E,$A:$A),"-") -> - | P85: =IFERROR(AVERAGEIFS('Ноябрь 2025'!$K:$K,'Ноябрь 2025'!$E:$E,$A:$A),"-") -> - | Q85: =IFERROR(AVERAGEIFS('Декабрь 2025'!$K:$K,'Декабрь 2025'!$E:$E,$A:$A),"-") -> - | R85: =IFERROR(AVERAGEIFS('Январь 2026'!$K:$K,'Январь 2026'!$E:$E,$A:$A),"-") -> - | S85: =IFERROR(AVERAGEIFS('Февраль 2026'!$K:$K,'Февраль 2026'!$E:$E,$A:$A),"-") -> - | T85: =IFERROR(AVERAGEIFS('Март 2026'!$K:$K,'Март 2026'!$E:$E,$A:$A),"-") -> 1.98 | U85: =IFERROR(AVERAGEIFS('Апрель 2026'!$K:$K,'Апрель 2026'!$E:$E,$A:$A),"-") -> - | V85: =IFERROR(AVERAGEIFS('Май 2026'!$K:$K,'Май 2026'!$E:$E,$A:$A),"-") -> - | W85: =IFERROR(AVERAGEIFS('Июнь 2026'!$K:$K,'Июнь 2026'!$E:$E,$A:$A),"-") -> - | X85: =IFERROR(AVERAGEIFS('Июль 2026'!$K:$K,'Июль 2026'!$E:$E,$A:$A),"-") -> -
B86: =IFERROR(AVERAGEIFS('Сентябрь 2024'!$K:$K,'Сентябрь 2024'!$E:$E,$A:$A),"-") -> - | C86: =IFERROR(AVERAGEIFS('Октябрь 2024'!$K:$K,'Октябрь 2024'!$E:$E,$A:$A),"-") -> - | D86: =IFERROR(AVERAGEIFS('Ноябрь 2024'!$K:$K,'Ноябрь 2024'!$E:$E,$A:$A),"-") -> - | E86: =IFERROR(AVERAGEIFS('Декабрь 2024'!$K:$K,'Декабрь 2024'!$E:$E,$A:$A),"-") -> - | F86: =IFERROR(AVERAGEIFS('Январь 2025'!$K:$K,'Январь 2025'!$E:$E,$A:$A),"-") -> - | G86: =IFERROR(AVERAGEIFS('Февраль 2025 '!K:K,'Февраль 2025 '!E:E,A:A),"-") -> - | H86: =IFERROR(AVERAGEIFS('Март 2025'!$K:$K,'Март 2025'!$E:$E,$A:$A),"-") -> - | I86: =IFERROR(AVERAGEIFS('Апрель 2025'!$K:$K,'Апрель 2025'!$E:$E,$A:$A),"-") -> - | J86: =IFERROR(AVERAGEIFS('Май 2025'!$K:$K,'Май 2025'!$E:$E,$A:$A),"-") -> - | K86: =IFERROR(AVERAGEIFS('Июнь 2025'!$K:$K,'Июнь 2025'!$E:$E,$A:$A),"-") -> - | L86: =IFERROR(AVERAGEIFS('Июль 2025'!$K:$K,'Июль 2025'!$E:$E,$A:$A),"-") -> - | M86: =IFERROR(AVERAGEIFS('Август 2025'!$K:$K,'Август 2025'!$E:$E,$A:$A),"-") -> - | N86: =IFERROR(AVERAGEIFS('Сентябрь 2025'!$K:$K,'Сентябрь 2025'!$E:$E,$A:$A),"-") -> - | O86: =IFERROR(AVERAGEIFS('Октябрь 2025'!$K:$K,'Октябрь 2025'!$E:$E,$A:$A),"-") -> - | P86: =IFERROR(AVERAGEIFS('Ноябрь 2025'!$K:$K,'Ноябрь 2025'!$E:$E,$A:$A),"-") -> - | Q86: =IFERROR(AVERAGEIFS('Декабрь 2025'!$K:$K,'Декабрь 2025'!$E:$E,$A:$A),"-") -> - | R86: =IFERROR(AVERAGEIFS('Январь 2026'!$K:$K,'Январь 2026'!$E:$E,$A:$A),"-") -> - | S86: =IFERROR(AVERAGEIFS('Февраль 2026'!$K:$K,'Февраль 2026'!$E:$E,$A:$A),"-") -> - | T86: =IFERROR(AVERAGEIFS('Март 2026'!$K:$K,'Март 2026'!$E:$E,$A:$A),"-") -> - | U86: =IFERROR(AVERAGEIFS('Апрель 2026'!$K:$K,'Апрель 2026'!$E:$E,$A:$A),"-") -> - | V86: =IFERROR(AVERAGEIFS('Май 2026'!$K:$K,'Май 2026'!$E:$E,$A:$A),"-") -> - | W86: =IFERROR(AVERAGEIFS('Июнь 2026'!$K:$K,'Июнь 2026'!$E:$E,$A:$A),"-") -> - | X86: =IFERROR(AVERAGEIFS('Июль 2026'!$K:$K,'Июль 2026'!$E:$E,$A:$A),"-") -> -
B87: =IFERROR(AVERAGEIFS('Сентябрь 2024'!$K:$K,'Сентябрь 2024'!$E:$E,$A:$A),"-") -> - | C87: =IFERROR(AVERAGEIFS('Октябрь 2024'!$K:$K,'Октябрь 2024'!$E:$E,$A:$A),"-") -> - | D87: =IFERROR(AVERAGEIFS('Ноябрь 2024'!$K:$K,'Ноябрь 2024'!$E:$E,$A:$A),"-") -> - | E87: =IFERROR(AVERAGEIFS('Декабрь 2024'!$K:$K,'Декабрь 2024'!$E:$E,$A:$A),"-") -> - | F87: =IFERROR(AVERAGEIFS('Январь 2025'!$K:$K,'Январь 2025'!$E:$E,$A:$A),"-") -> - | G87: =IFERROR(AVERAGEIFS('Февраль 2025 '!K:K,'Февраль 2025 '!E:E,A:A),"-") -> - | H87: =IFERROR(AVERAGEIFS('Март 2025'!$K:$K,'Март 2025'!$E:$E,$A:$A),"-") -> - | I87: =IFERROR(AVERAGEIFS('Апрель 2025'!$K:$K,'Апрель 2025'!$E:$E,$A:$A),"-") -> - | J87: =IFERROR(AVERAGEIFS('Май 2025'!$K:$K,'Май 2025'!$E:$E,$A:$A),"-") -> - | K87: =IFERROR(AVERAGEIFS('Июнь 2025'!$K:$K,'Июнь 2025'!$E:$E,$A:$A),"-") -> - | L87: =IFERROR(AVERAGEIFS('Июль 2025'!$K:$K,'Июль 2025'!$E:$E,$A:$A),"-") -> - | M87: =IFERROR(AVERAGEIFS('Август 2025'!$K:$K,'Август 2025'!$E:$E,$A:$A),"-") -> - | N87: =IFERROR(AVERAGEIFS('Сентябрь 2025'!$K:$K,'Сентябрь 2025'!$E:$E,$A:$A),"-") -> - | O87: =IFERROR(AVERAGEIFS('Октябрь 2025'!$K:$K,'Октябрь 2025'!$E:$E,$A:$A),"-") -> - | P87: =IFERROR(AVERAGEIFS('Ноябрь 2025'!$K:$K,'Ноябрь 2025'!$E:$E,$A:$A),"-") -> - | Q87: =IFERROR(AVERAGEIFS('Декабрь 2025'!$K:$K,'Декабрь 2025'!$E:$E,$A:$A),"-") -> - | R87: =IFERROR(AVERAGEIFS('Январь 2026'!$K:$K,'Январь 2026'!$E:$E,$A:$A),"-") -> - | S87: =IFERROR(AVERAGEIFS('Февраль 2026'!$K:$K,'Февраль 2026'!$E:$E,$A:$A),"-") -> - | T87: =IFERROR(AVERAGEIFS('Март 2026'!$K:$K,'Март 2026'!$E:$E,$A:$A),"-") -> - | U87: =IFERROR(AVERAGEIFS('Апрель 2026'!$K:$K,'Апрель 2026'!$E:$E,$A:$A),"-") -> - | V87: =IFERROR(AVERAGEIFS('Май 2026'!$K:$K,'Май 2026'!$E:$E,$A:$A),"-") -> - | W87: =IFERROR(AVERAGEIFS('Июнь 2026'!$K:$K,'Июнь 2026'!$E:$E,$A:$A),"-") -> - | X87: =IFERROR(AVERAGEIFS('Июль 2026'!$K:$K,'Июль 2026'!$E:$E,$A:$A),"-") -> -
B88: =IFERROR(AVERAGEIFS('Сентябрь 2024'!$K:$K,'Сентябрь 2024'!$E:$E,$A:$A),"-") -> - | C88: =IFERROR(AVERAGEIFS('Октябрь 2024'!$K:$K,'Октябрь 2024'!$E:$E,$A:$A),"-") -> - | D88: =IFERROR(AVERAGEIFS('Ноябрь 2024'!$K:$K,'Ноябрь 2024'!$E:$E,$A:$A),"-") -> - | E88: =IFERROR(AVERAGEIFS('Декабрь 2024'!$K:$K,'Декабрь 2024'!$E:$E,$A:$A),"-") -> - | F88: =IFERROR(AVERAGEIFS('Январь 2025'!$K:$K,'Январь 2025'!$E:$E,$A:$A),"-") -> - | G88: =IFERROR(AVERAGEIFS('Февраль 2025 '!K:K,'Февраль 2025 '!E:E,A:A),"-") -> - | H88: =IFERROR(AVERAGEIFS('Март 2025'!$K:$K,'Март 2025'!$E:$E,$A:$A),"-") -> - | I88: =IFERROR(AVERAGEIFS('Апрель 2025'!$K:$K,'Апрель 2025'!$E:$E,$A:$A),"-") -> - | J88: =IFERROR(AVERAGEIFS('Май 2025'!$K:$K,'Май 2025'!$E:$E,$A:$A),"-") -> - | K88: =IFERROR(AVERAGEIFS('Июнь 2025'!$K:$K,'Июнь 2025'!$E:$E,$A:$A),"-") -> - | L88: =IFERROR(AVERAGEIFS('Июль 2025'!$K:$K,'Июль 2025'!$E:$E,$A:$A),"-") -> - | M88: =IFERROR(AVERAGEIFS('Август 2025'!$K:$K,'Август 2025'!$E:$E,$A:$A),"-") -> - | N88: =IFERROR(AVERAGEIFS('Сентябрь 2025'!$K:$K,'Сентябрь 2025'!$E:$E,$A:$A),"-") -> - | O88: =IFERROR(AVERAGEIFS('Октябрь 2025'!$K:$K,'Октябрь 2025'!$E:$E,$A:$A),"-") -> - | P88: =IFERROR(AVERAGEIFS('Ноябрь 2025'!$K:$K,'Ноябрь 2025'!$E:$E,$A:$A),"-") -> - | Q88: =IFERROR(AVERAGEIFS('Декабрь 2025'!$K:$K,'Декабрь 2025'!$E:$E,$A:$A),"-") -> - | R88: =IFERROR(AVERAGEIFS('Январь 2026'!$K:$K,'Январь 2026'!$E:$E,$A:$A),"-") -> - | S88: =IFERROR(AVERAGEIFS('Февраль 2026'!$K:$K,'Февраль 2026'!$E:$E,$A:$A),"-") -> - | T88: =IFERROR(AVERAGEIFS('Март 2026'!$K:$K,'Март 2026'!$E:$E,$A:$A),"-") -> - | U88: =IFERROR(AVERAGEIFS('Апрель 2026'!$K:$K,'Апрель 2026'!$E:$E,$A:$A),"-") -> - | V88: =IFERROR(AVERAGEIFS('Май 2026'!$K:$K,'Май 2026'!$E:$E,$A:$A),"-") -> - | W88: =IFERROR(AVERAGEIFS('Июнь 2026'!$K:$K,'Июнь 2026'!$E:$E,$A:$A),"-") -> - | X88: =IFERROR(AVERAGEIFS('Июль 2026'!$K:$K,'Июль 2026'!$E:$E,$A:$A),"-") -> -
B89: =IFERROR(AVERAGEIFS('Сентябрь 2024'!$K:$K,'Сентябрь 2024'!$E:$E,$A:$A),"-") -> - | C89: =IFERROR(AVERAGEIFS('Октябрь 2024'!$K:$K,'Октябрь 2024'!$E:$E,$A:$A),"-") -> - | D89: =IFERROR(AVERAGEIFS('Ноябрь 2024'!$K:$K,'Ноябрь 2024'!$E:$E,$A:$A),"-") -> - | E89: =IFERROR(AVERAGEIFS('Декабрь 2024'!$K:$K,'Декабрь 2024'!$E:$E,$A:$A),"-") -> - | F89: =IFERROR(AVERAGEIFS('Январь 2025'!$K:$K,'Январь 2025'!$E:$E,$A:$A),"-") -> - | G89: =IFERROR(AVERAGEIFS('Февраль 2025 '!K:K,'Февраль 2025 '!E:E,A:A),"-") -> - | H89: =IFERROR(AVERAGEIFS('Март 2025'!$K:$K,'Март 2025'!$E:$E,$A:$A),"-") -> - | I89: =IFERROR(AVERAGEIFS('Апрель 2025'!$K:$K,'Апрель 2025'!$E:$E,$A:$A),"-") -> - | J89: =IFERROR(AVERAGEIFS('Май 2025'!$K:$K,'Май 2025'!$E:$E,$A:$A),"-") -> - | K89: =IFERROR(AVERAGEIFS('Июнь 2025'!$K:$K,'Июнь 2025'!$E:$E,$A:$A),"-") -> - | L89: =IFERROR(AVERAGEIFS('Июль 2025'!$K:$K,'Июль 2025'!$E:$E,$A:$A),"-") -> - | M89: =IFERROR(AVERAGEIFS('Август 2025'!$K:$K,'Август 2025'!$E:$E,$A:$A),"-") -> - | N89: =IFERROR(AVERAGEIFS('Сентябрь 2025'!$K:$K,'Сентябрь 2025'!$E:$E,$A:$A),"-") -> - | O89: =IFERROR(AVERAGEIFS('Октябрь 2025'!$K:$K,'Октябрь 2025'!$E:$E,$A:$A),"-") -> - | P89: =IFERROR(AVERAGEIFS('Ноябрь 2025'!$K:$K,'Ноябрь 2025'!$E:$E,$A:$A),"-") -> - | Q89: =IFERROR(AVERAGEIFS('Декабрь 2025'!$K:$K,'Декабрь 2025'!$E:$E,$A:$A),"-") -> - | R89: =IFERROR(AVERAGEIFS('Январь 2026'!$K:$K,'Январь 2026'!$E:$E,$A:$A),"-") -> - | S89: =IFERROR(AVERAGEIFS('Февраль 2026'!$K:$K,'Февраль 2026'!$E:$E,$A:$A),"-") -> - | T89: =IFERROR(AVERAGEIFS('Март 2026'!$K:$K,'Март 2026'!$E:$E,$A:$A),"-") -> - | U89: =IFERROR(AVERAGEIFS('Апрель 2026'!$K:$K,'Апрель 2026'!$E:$E,$A:$A),"-") -> - | V89: =IFERROR(AVERAGEIFS('Май 2026'!$K:$K,'Май 2026'!$E:$E,$A:$A),"-") -> - | W89: =IFERROR(AVERAGEIFS('Июнь 2026'!$K:$K,'Июнь 2026'!$E:$E,$A:$A),"-") -> - | X89: =IFERROR(AVERAGEIFS('Июль 2026'!$K:$K,'Июль 2026'!$E:$E,$A:$A),"-") -> -
B90: =IFERROR(AVERAGEIFS('Сентябрь 2024'!$K:$K,'Сентябрь 2024'!$E:$E,$A:$A),"-") -> - | C90: =IFERROR(AVERAGEIFS('Октябрь 2024'!$K:$K,'Октябрь 2024'!$E:$E,$A:$A),"-") -> - | D90: =IFERROR(AVERAGEIFS('Ноябрь 2024'!$K:$K,'Ноябрь 2024'!$E:$E,$A:$A),"-") -> - | E90: =IFERROR(AVERAGEIFS('Декабрь 2024'!$K:$K,'Декабрь 2024'!$E:$E,$A:$A),"-") -> - | F90: =IFERROR(AVERAGEIFS('Январь 2025'!$K:$K,'Январь 2025'!$E:$E,$A:$A),"-") -> - | G90: =IFERROR(AVERAGEIFS('Февраль 2025 '!K:K,'Февраль 2025 '!E:E,A:A),"-") -> - | H90: =IFERROR(AVERAGEIFS('Март 2025'!$K:$K,'Март 2025'!$E:$E,$A:$A),"-") -> - | I90: =IFERROR(AVERAGEIFS('Апрель 2025'!$K:$K,'Апрель 2025'!$E:$E,$A:$A),"-") -> - | J90: =IFERROR(AVERAGEIFS('Май 2025'!$K:$K,'Май 2025'!$E:$E,$A:$A),"-") -> - | K90: =IFERROR(AVERAGEIFS('Июнь 2025'!$K:$K,'Июнь 2025'!$E:$E,$A:$A),"-") -> - | L90: =IFERROR(AVERAGEIFS('Июль 2025'!$K:$K,'Июль 2025'!$E:$E,$A:$A),"-") -> - | M90: =IFERROR(AVERAGEIFS('Август 2025'!$K:$K,'Август 2025'!$E:$E,$A:$A),"-") -> - | N90: =IFERROR(AVERAGEIFS('Сентябрь 2025'!$K:$K,'Сентябрь 2025'!$E:$E,$A:$A),"-") -> - | O90: =IFERROR(AVERAGEIFS('Октябрь 2025'!$K:$K,'Октябрь 2025'!$E:$E,$A:$A),"-") -> - | P90: =IFERROR(AVERAGEIFS('Ноябрь 2025'!$K:$K,'Ноябрь 2025'!$E:$E,$A:$A),"-") -> - | Q90: =IFERROR(AVERAGEIFS('Декабрь 2025'!$K:$K,'Декабрь 2025'!$E:$E,$A:$A),"-") -> - | R90: =IFERROR(AVERAGEIFS('Январь 2026'!$K:$K,'Январь 2026'!$E:$E,$A:$A),"-") -> - | S90: =IFERROR(AVERAGEIFS('Февраль 2026'!$K:$K,'Февраль 2026'!$E:$E,$A:$A),"-") -> - | T90: =IFERROR(AVERAGEIFS('Март 2026'!$K:$K,'Март 2026'!$E:$E,$A:$A),"-") -> - | U90: =IFERROR(AVERAGEIFS('Апрель 2026'!$K:$K,'Апрель 2026'!$E:$E,$A:$A),"-") -> - | V90: =IFERROR(AVERAGEIFS('Май 2026'!$K:$K,'Май 2026'!$E:$E,$A:$A),"-") -> - | W90: =IFERROR(AVERAGEIFS('Июнь 2026'!$K:$K,'Июнь 2026'!$E:$E,$A:$A),"-") -> - | X90: =IFERROR(AVERAGEIFS('Июль 2026'!$K:$K,'Июль 2026'!$E:$E,$A:$A),"-") -> -
B91: =IFERROR(AVERAGEIFS('Сентябрь 2024'!$K:$K,'Сентябрь 2024'!$E:$E,$A:$A),"-") -> - | C91: =IFERROR(AVERAGEIFS('Октябрь 2024'!$K:$K,'Октябрь 2024'!$E:$E,$A:$A),"-") -> - | D91: =IFERROR(AVERAGEIFS('Ноябрь 2024'!$K:$K,'Ноябрь 2024'!$E:$E,$A:$A),"-") -> - | E91: =IFERROR(AVERAGEIFS('Декабрь 2024'!$K:$K,'Декабрь 2024'!$E:$E,$A:$A),"-") -> - | F91: =IFERROR(AVERAGEIFS('Январь 2025'!$K:$K,'Январь 2025'!$E:$E,$A:$A),"-") -> - | G91: =IFERROR(AVERAGEIFS('Февраль 2025 '!K:K,'Февраль 2025 '!E:E,A:A),"-") -> - | H91: =IFERROR(AVERAGEIFS('Март 2025'!$K:$K,'Март 2025'!$E:$E,$A:$A),"-") -> - | I91: =IFERROR(AVERAGEIFS('Апрель 2025'!$K:$K,'Апрель 2025'!$E:$E,$A:$A),"-") -> - | J91: =IFERROR(AVERAGEIFS('Май 2025'!$K:$K,'Май 2025'!$E:$E,$A:$A),"-") -> - | K91: =IFERROR(AVERAGEIFS('Июнь 2025'!$K:$K,'Июнь 2025'!$E:$E,$A:$A),"-") -> - | L91: =IFERROR(AVERAGEIFS('Июль 2025'!$K:$K,'Июль 2025'!$E:$E,$A:$A),"-") -> - | M91: =IFERROR(AVERAGEIFS('Август 2025'!$K:$K,'Август 2025'!$E:$E,$A:$A),"-") -> - | N91: =IFERROR(AVERAGEIFS('Сентябрь 2025'!$K:$K,'Сентябрь 2025'!$E:$E,$A:$A),"-") -> - | O91: =IFERROR(AVERAGEIFS('Октябрь 2025'!$K:$K,'Октябрь 2025'!$E:$E,$A:$A),"-") -> - | P91: =IFERROR(AVERAGEIFS('Ноябрь 2025'!$K:$K,'Ноябрь 2025'!$E:$E,$A:$A),"-") -> - | Q91: =IFERROR(AVERAGEIFS('Декабрь 2025'!$K:$K,'Декабрь 2025'!$E:$E,$A:$A),"-") -> - | R91: =IFERROR(AVERAGEIFS('Январь 2026'!$K:$K,'Январь 2026'!$E:$E,$A:$A),"-") -> - | S91: =IFERROR(AVERAGEIFS('Февраль 2026'!$K:$K,'Февраль 2026'!$E:$E,$A:$A),"-") -> - | T91: =IFERROR(AVERAGEIFS('Март 2026'!$K:$K,'Март 2026'!$E:$E,$A:$A),"-") -> - | U91: =IFERROR(AVERAGEIFS('Апрель 2026'!$K:$K,'Апрель 2026'!$E:$E,$A:$A),"-") -> - | V91: =IFERROR(AVERAGEIFS('Май 2026'!$K:$K,'Май 2026'!$E:$E,$A:$A),"-") -> - | W91: =IFERROR(AVERAGEIFS('Июнь 2026'!$K:$K,'Июнь 2026'!$E:$E,$A:$A),"-") -> - | X91: =IFERROR(AVERAGEIFS('Июль 2026'!$K:$K,'Июль 2026'!$E:$E,$A:$A),"-") -> -
B92: =IFERROR(AVERAGEIFS('Сентябрь 2024'!$K:$K,'Сентябрь 2024'!$E:$E,$A:$A),"-") -> - | C92: =IFERROR(AVERAGEIFS('Октябрь 2024'!$K:$K,'Октябрь 2024'!$E:$E,$A:$A),"-") -> - | D92: =IFERROR(AVERAGEIFS('Ноябрь 2024'!$K:$K,'Ноябрь 2024'!$E:$E,$A:$A),"-") -> - | E92: =IFERROR(AVERAGEIFS('Декабрь 2024'!$K:$K,'Декабрь 2024'!$E:$E,$A:$A),"-") -> - | F92: =IFERROR(AVERAGEIFS('Январь 2025'!$K:$K,'Январь 2025'!$E:$E,$A:$A),"-") -> - | G92: =IFERROR(AVERAGEIFS('Февраль 2025 '!K:K,'Февраль 2025 '!E:E,A:A),"-") -> - | H92: =IFERROR(AVERAGEIFS('Март 2025'!$K:$K,'Март 2025'!$E:$E,$A:$A),"-") -> - | I92: =IFERROR(AVERAGEIFS('Апрель 2025'!$K:$K,'Апрель 2025'!$E:$E,$A:$A),"-") -> - | J92: =IFERROR(AVERAGEIFS('Май 2025'!$K:$K,'Май 2025'!$E:$E,$A:$A),"-") -> - | K92: =IFERROR(AVERAGEIFS('Июнь 2025'!$K:$K,'Июнь 2025'!$E:$E,$A:$A),"-") -> - | L92: =IFERROR(AVERAGEIFS('Июль 2025'!$K:$K,'Июль 2025'!$E:$E,$A:$A),"-") -> - | M92: =IFERROR(AVERAGEIFS('Август 2025'!$K:$K,'Август 2025'!$E:$E,$A:$A),"-") -> - | N92: =IFERROR(AVERAGEIFS('Сентябрь 2025'!$K:$K,'Сентябрь 2025'!$E:$E,$A:$A),"-") -> - | O92: =IFERROR(AVERAGEIFS('Октябрь 2025'!$K:$K,'Октябрь 2025'!$E:$E,$A:$A),"-") -> - | P92: =IFERROR(AVERAGEIFS('Ноябрь 2025'!$K:$K,'Ноябрь 2025'!$E:$E,$A:$A),"-") -> - | Q92: =IFERROR(AVERAGEIFS('Декабрь 2025'!$K:$K,'Декабрь 2025'!$E:$E,$A:$A),"-") -> - | R92: =IFERROR(AVERAGEIFS('Январь 2026'!$K:$K,'Январь 2026'!$E:$E,$A:$A),"-") -> - | S92: =IFERROR(AVERAGEIFS('Февраль 2026'!$K:$K,'Февраль 2026'!$E:$E,$A:$A),"-") -> - | T92: =IFERROR(AVERAGEIFS('Март 2026'!$K:$K,'Март 2026'!$E:$E,$A:$A),"-") -> - | U92: =IFERROR(AVERAGEIFS('Апрель 2026'!$K:$K,'Апрель 2026'!$E:$E,$A:$A),"-") -> - | V92: =IFERROR(AVERAGEIFS('Май 2026'!$K:$K,'Май 2026'!$E:$E,$A:$A),"-") -> - | W92: =IFERROR(AVERAGEIFS('Июнь 2026'!$K:$K,'Июнь 2026'!$E:$E,$A:$A),"-") -> - | X92: =IFERROR(AVERAGEIFS('Июль 2026'!$K:$K,'Июль 2026'!$E:$E,$A:$A),"-") -> -
B93: =IFERROR(AVERAGEIFS('Сентябрь 2024'!$K:$K,'Сентябрь 2024'!$E:$E,$A:$A),"-") -> - | C93: =IFERROR(AVERAGEIFS('Октябрь 2024'!$K:$K,'Октябрь 2024'!$E:$E,$A:$A),"-") -> - | D93: =IFERROR(AVERAGEIFS('Ноябрь 2024'!$K:$K,'Ноябрь 2024'!$E:$E,$A:$A),"-") -> - | E93: =IFERROR(AVERAGEIFS('Декабрь 2024'!$K:$K,'Декабрь 2024'!$E:$E,$A:$A),"-") -> - | F93: =IFERROR(AVERAGEIFS('Январь 2025'!$K:$K,'Январь 2025'!$E:$E,$A:$A),"-") -> - | G93: =IFERROR(AVERAGEIFS('Февраль 2025 '!K:K,'Февраль 2025 '!E:E,A:A),"-") -> - | H93: =IFERROR(AVERAGEIFS('Март 2025'!$K:$K,'Март 2025'!$E:$E,$A:$A),"-") -> - | I93: =IFERROR(AVERAGEIFS('Апрель 2025'!$K:$K,'Апрель 2025'!$E:$E,$A:$A),"-") -> - | J93: =IFERROR(AVERAGEIFS('Май 2025'!$K:$K,'Май 2025'!$E:$E,$A:$A),"-") -> - | K93: =IFERROR(AVERAGEIFS('Июнь 2025'!$K:$K,'Июнь 2025'!$E:$E,$A:$A),"-") -> - | L93: =IFERROR(AVERAGEIFS('Июль 2025'!$K:$K,'Июль 2025'!$E:$E,$A:$A),"-") -> - | M93: =IFERROR(AVERAGEIFS('Август 2025'!$K:$K,'Август 2025'!$E:$E,$A:$A),"-") -> - | N93: =IFERROR(AVERAGEIFS('Сентябрь 2025'!$K:$K,'Сентябрь 2025'!$E:$E,$A:$A),"-") -> - | O93: =IFERROR(AVERAGEIFS('Октябрь 2025'!$K:$K,'Октябрь 2025'!$E:$E,$A:$A),"-") -> - | P93: =IFERROR(AVERAGEIFS('Ноябрь 2025'!$K:$K,'Ноябрь 2025'!$E:$E,$A:$A),"-") -> - | Q93: =IFERROR(AVERAGEIFS('Декабрь 2025'!$K:$K,'Декабрь 2025'!$E:$E,$A:$A),"-") -> - | R93: =IFERROR(AVERAGEIFS('Январь 2026'!$K:$K,'Январь 2026'!$E:$E,$A:$A),"-") -> - | S93: =IFERROR(AVERAGEIFS('Февраль 2026'!$K:$K,'Февраль 2026'!$E:$E,$A:$A),"-") -> - | T93: =IFERROR(AVERAGEIFS('Март 2026'!$K:$K,'Март 2026'!$E:$E,$A:$A),"-") -> - | U93: =IFERROR(AVERAGEIFS('Апрель 2026'!$K:$K,'Апрель 2026'!$E:$E,$A:$A),"-") -> - | V93: =IFERROR(AVERAGEIFS('Май 2026'!$K:$K,'Май 2026'!$E:$E,$A:$A),"-") -> - | W93: =IFERROR(AVERAGEIFS('Июнь 2026'!$K:$K,'Июнь 2026'!$E:$E,$A:$A),"-") -> - | X93: =IFERROR(AVERAGEIFS('Июль 2026'!$K:$K,'Июль 2026'!$E:$E,$A:$A),"-") -> -
B94: =IFERROR(AVERAGEIFS('Сентябрь 2024'!$K:$K,'Сентябрь 2024'!$E:$E,$A:$A),"-") -> - | C94: =IFERROR(AVERAGEIFS('Октябрь 2024'!$K:$K,'Октябрь 2024'!$E:$E,$A:$A),"-") -> - | D94: =IFERROR(AVERAGEIFS('Ноябрь 2024'!$K:$K,'Ноябрь 2024'!$E:$E,$A:$A),"-") -> - | E94: =IFERROR(AVERAGEIFS('Декабрь 2024'!$K:$K,'Декабрь 2024'!$E:$E,$A:$A),"-") -> - | F94: =IFERROR(AVERAGEIFS('Январь 2025'!$K:$K,'Январь 2025'!$E:$E,$A:$A),"-") -> - | G94: =IFERROR(AVERAGEIFS('Февраль 2025 '!K:K,'Февраль 2025 '!E:E,A:A),"-") -> - | H94: =IFERROR(AVERAGEIFS('Март 2025'!$K:$K,'Март 2025'!$E:$E,$A:$A),"-") -> - | I94: =IFERROR(AVERAGEIFS('Апрель 2025'!$K:$K,'Апрель 2025'!$E:$E,$A:$A),"-") -> - | J94: =IFERROR(AVERAGEIFS('Май 2025'!$K:$K,'Май 2025'!$E:$E,$A:$A),"-") -> - | K94: =IFERROR(AVERAGEIFS('Июнь 2025'!$K:$K,'Июнь 2025'!$E:$E,$A:$A),"-") -> - | L94: =IFERROR(AVERAGEIFS('Июль 2025'!$K:$K,'Июль 2025'!$E:$E,$A:$A),"-") -> - | M94: =IFERROR(AVERAGEIFS('Август 2025'!$K:$K,'Август 2025'!$E:$E,$A:$A),"-") -> - | N94: =IFERROR(AVERAGEIFS('Сентябрь 2025'!$K:$K,'Сентябрь 2025'!$E:$E,$A:$A),"-") -> - | O94: =IFERROR(AVERAGEIFS('Октябрь 2025'!$K:$K,'Октябрь 2025'!$E:$E,$A:$A),"-") -> - | P94: =IFERROR(AVERAGEIFS('Ноябрь 2025'!$K:$K,'Ноябрь 2025'!$E:$E,$A:$A),"-") -> - | Q94: =IFERROR(AVERAGEIFS('Декабрь 2025'!$K:$K,'Декабрь 2025'!$E:$E,$A:$A),"-") -> - | R94: =IFERROR(AVERAGEIFS('Январь 2026'!$K:$K,'Январь 2026'!$E:$E,$A:$A),"-") -> - | S94: =IFERROR(AVERAGEIFS('Февраль 2026'!$K:$K,'Февраль 2026'!$E:$E,$A:$A),"-") -> - | T94: =IFERROR(AVERAGEIFS('Март 2026'!$K:$K,'Март 2026'!$E:$E,$A:$A),"-") -> - | U94: =IFERROR(AVERAGEIFS('Апрель 2026'!$K:$K,'Апрель 2026'!$E:$E,$A:$A),"-") -> - | V94: =IFERROR(AVERAGEIFS('Май 2026'!$K:$K,'Май 2026'!$E:$E,$A:$A),"-") -> - | W94: =IFERROR(AVERAGEIFS('Июнь 2026'!$K:$K,'Июнь 2026'!$E:$E,$A:$A),"-") -> - | X94: =IFERROR(AVERAGEIFS('Июль 2026'!$K:$K,'Июль 2026'!$E:$E,$A:$A),"-") -> -
B95: =IFERROR(AVERAGEIFS('Сентябрь 2024'!$K:$K,'Сентябрь 2024'!$E:$E,$A:$A),"-") -> - | C95: =IFERROR(AVERAGEIFS('Октябрь 2024'!$K:$K,'Октябрь 2024'!$E:$E,$A:$A),"-") -> - | D95: =IFERROR(AVERAGEIFS('Ноябрь 2024'!$K:$K,'Ноябрь 2024'!$E:$E,$A:$A),"-") -> - | E95: =IFERROR(AVERAGEIFS('Декабрь 2024'!$K:$K,'Декабрь 2024'!$E:$E,$A:$A),"-") -> - | F95: =IFERROR(AVERAGEIFS('Январь 2025'!$K:$K,'Январь 2025'!$E:$E,$A:$A),"-") -> - | G95: =IFERROR(AVERAGEIFS('Февраль 2025 '!K:K,'Февраль 2025 '!E:E,A:A),"-") -> - | H95: =IFERROR(AVERAGEIFS('Март 2025'!$K:$K,'Март 2025'!$E:$E,$A:$A),"-") -> - | I95: =IFERROR(AVERAGEIFS('Апрель 2025'!$K:$K,'Апрель 2025'!$E:$E,$A:$A),"-") -> - | J95: =IFERROR(AVERAGEIFS('Май 2025'!$K:$K,'Май 2025'!$E:$E,$A:$A),"-") -> - | K95: =IFERROR(AVERAGEIFS('Июнь 2025'!$K:$K,'Июнь 2025'!$E:$E,$A:$A),"-") -> - | L95: =IFERROR(AVERAGEIFS('Июль 2025'!$K:$K,'Июль 2025'!$E:$E,$A:$A),"-") -> - | M95: =IFERROR(AVERAGEIFS('Август 2025'!$K:$K,'Август 2025'!$E:$E,$A:$A),"-") -> - | N95: =IFERROR(AVERAGEIFS('Сентябрь 2025'!$K:$K,'Сентябрь 2025'!$E:$E,$A:$A),"-") -> - | O95: =IFERROR(AVERAGEIFS('Октябрь 2025'!$K:$K,'Октябрь 2025'!$E:$E,$A:$A),"-") -> - | P95: =IFERROR(AVERAGEIFS('Ноябрь 2025'!$K:$K,'Ноябрь 2025'!$E:$E,$A:$A),"-") -> - | Q95: =IFERROR(AVERAGEIFS('Декабрь 2025'!$K:$K,'Декабрь 2025'!$E:$E,$A:$A),"-") -> - | R95: =IFERROR(AVERAGEIFS('Январь 2026'!$K:$K,'Январь 2026'!$E:$E,$A:$A),"-") -> - | S95: =IFERROR(AVERAGEIFS('Февраль 2026'!$K:$K,'Февраль 2026'!$E:$E,$A:$A),"-") -> - | T95: =IFERROR(AVERAGEIFS('Март 2026'!$K:$K,'Март 2026'!$E:$E,$A:$A),"-") -> - | U95: =IFERROR(AVERAGEIFS('Апрель 2026'!$K:$K,'Апрель 2026'!$E:$E,$A:$A),"-") -> - | V95: =IFERROR(AVERAGEIFS('Май 2026'!$K:$K,'Май 2026'!$E:$E,$A:$A),"-") -> - | W95: =IFERROR(AVERAGEIFS('Июнь 2026'!$K:$K,'Июнь 2026'!$E:$E,$A:$A),"-") -> - | X95: =IFERROR(AVERAGEIFS('Июль 2026'!$K:$K,'Июль 2026'!$E:$E,$A:$A),"-") -> -
B96: =IFERROR(AVERAGEIFS('Сентябрь 2024'!$K:$K,'Сентябрь 2024'!$E:$E,$A:$A),"-") -> - | C96: =IFERROR(AVERAGEIFS('Октябрь 2024'!$K:$K,'Октябрь 2024'!$E:$E,$A:$A),"-") -> - | D96: =IFERROR(AVERAGEIFS('Ноябрь 2024'!$K:$K,'Ноябрь 2024'!$E:$E,$A:$A),"-") -> - | E96: =IFERROR(AVERAGEIFS('Декабрь 2024'!$K:$K,'Декабрь 2024'!$E:$E,$A:$A),"-") -> - | F96: =IFERROR(AVERAGEIFS('Январь 2025'!$K:$K,'Январь 2025'!$E:$E,$A:$A),"-") -> - | G96: =IFERROR(AVERAGEIFS('Февраль 2025 '!K:K,'Февраль 2025 '!E:E,A:A),"-") -> - | H96: =IFERROR(AVERAGEIFS('Март 2025'!$K:$K,'Март 2025'!$E:$E,$A:$A),"-") -> - | I96: =IFERROR(AVERAGEIFS('Апрель 2025'!$K:$K,'Апрель 2025'!$E:$E,$A:$A),"-") -> - | J96: =IFERROR(AVERAGEIFS('Май 2025'!$K:$K,'Май 2025'!$E:$E,$A:$A),"-") -> - | K96: =IFERROR(AVERAGEIFS('Июнь 2025'!$K:$K,'Июнь 2025'!$E:$E,$A:$A),"-") -> - | L96: =IFERROR(AVERAGEIFS('Июль 2025'!$K:$K,'Июль 2025'!$E:$E,$A:$A),"-") -> - | M96: =IFERROR(AVERAGEIFS('Август 2025'!$K:$K,'Август 2025'!$E:$E,$A:$A),"-") -> - | N96: =IFERROR(AVERAGEIFS('Сентябрь 2025'!$K:$K,'Сентябрь 2025'!$E:$E,$A:$A),"-") -> - | O96: =IFERROR(AVERAGEIFS('Октябрь 2025'!$K:$K,'Октябрь 2025'!$E:$E,$A:$A),"-") -> - | P96: =IFERROR(AVERAGEIFS('Ноябрь 2025'!$K:$K,'Ноябрь 2025'!$E:$E,$A:$A),"-") -> - | Q96: =IFERROR(AVERAGEIFS('Декабрь 2025'!$K:$K,'Декабрь 2025'!$E:$E,$A:$A),"-") -> - | R96: =IFERROR(AVERAGEIFS('Январь 2026'!$K:$K,'Январь 2026'!$E:$E,$A:$A),"-") -> - | S96: =IFERROR(AVERAGEIFS('Февраль 2026'!$K:$K,'Февраль 2026'!$E:$E,$A:$A),"-") -> - | T96: =IFERROR(AVERAGEIFS('Март 2026'!$K:$K,'Март 2026'!$E:$E,$A:$A),"-") -> - | U96: =IFERROR(AVERAGEIFS('Апрель 2026'!$K:$K,'Апрель 2026'!$E:$E,$A:$A),"-") -> - | V96: =IFERROR(AVERAGEIFS('Май 2026'!$K:$K,'Май 2026'!$E:$E,$A:$A),"-") -> - | W96: =IFERROR(AVERAGEIFS('Июнь 2026'!$K:$K,'Июнь 2026'!$E:$E,$A:$A),"-") -> - | X96: =IFERROR(AVERAGEIFS('Июль 2026'!$K:$K,'Июль 2026'!$E:$E,$A:$A),"-") -> -
B97: =IFERROR(AVERAGEIFS('Сентябрь 2024'!$K:$K,'Сентябрь 2024'!$E:$E,$A:$A),"-") -> - | C97: =IFERROR(AVERAGEIFS('Октябрь 2024'!$K:$K,'Октябрь 2024'!$E:$E,$A:$A),"-") -> - | D97: =IFERROR(AVERAGEIFS('Ноябрь 2024'!$K:$K,'Ноябрь 2024'!$E:$E,$A:$A),"-") -> - | E97: =IFERROR(AVERAGEIFS('Декабрь 2024'!$K:$K,'Декабрь 2024'!$E:$E,$A:$A),"-") -> - | F97: =IFERROR(AVERAGEIFS('Январь 2025'!$K:$K,'Январь 2025'!$E:$E,$A:$A),"-") -> - | G97: =IFERROR(AVERAGEIFS('Февраль 2025 '!K:K,'Февраль 2025 '!E:E,A:A),"-") -> - | H97: =IFERROR(AVERAGEIFS('Март 2025'!$K:$K,'Март 2025'!$E:$E,$A:$A),"-") -> - | I97: =IFERROR(AVERAGEIFS('Апрель 2025'!$K:$K,'Апрель 2025'!$E:$E,$A:$A),"-") -> - | J97: =IFERROR(AVERAGEIFS('Май 2025'!$K:$K,'Май 2025'!$E:$E,$A:$A),"-") -> - | K97: =IFERROR(AVERAGEIFS('Июнь 2025'!$K:$K,'Июнь 2025'!$E:$E,$A:$A),"-") -> - | L97: =IFERROR(AVERAGEIFS('Июль 2025'!$K:$K,'Июль 2025'!$E:$E,$A:$A),"-") -> - | M97: =IFERROR(AVERAGEIFS('Август 2025'!$K:$K,'Август 2025'!$E:$E,$A:$A),"-") -> - | N97: =IFERROR(AVERAGEIFS('Сентябрь 2025'!$K:$K,'Сентябрь 2025'!$E:$E,$A:$A),"-") -> - | O97: =IFERROR(AVERAGEIFS('Октябрь 2025'!$K:$K,'Октябрь 2025'!$E:$E,$A:$A),"-") -> - | P97: =IFERROR(AVERAGEIFS('Ноябрь 2025'!$K:$K,'Ноябрь 2025'!$E:$E,$A:$A),"-") -> - | Q97: =IFERROR(AVERAGEIFS('Декабрь 2025'!$K:$K,'Декабрь 2025'!$E:$E,$A:$A),"-") -> - | R97: =IFERROR(AVERAGEIFS('Январь 2026'!$K:$K,'Январь 2026'!$E:$E,$A:$A),"-") -> - | S97: =IFERROR(AVERAGEIFS('Февраль 2026'!$K:$K,'Февраль 2026'!$E:$E,$A:$A),"-") -> - | T97: =IFERROR(AVERAGEIFS('Март 2026'!$K:$K,'Март 2026'!$E:$E,$A:$A),"-") -> - | U97: =IFERROR(AVERAGEIFS('Апрель 2026'!$K:$K,'Апрель 2026'!$E:$E,$A:$A),"-") -> - | V97: =IFERROR(AVERAGEIFS('Май 2026'!$K:$K,'Май 2026'!$E:$E,$A:$A),"-") -> - | W97: =IFERROR(AVERAGEIFS('Июнь 2026'!$K:$K,'Июнь 2026'!$E:$E,$A:$A),"-") -> - | X97: =IFERROR(AVERAGEIFS('Июль 2026'!$K:$K,'Июль 2026'!$E:$E,$A:$A),"-") -> -
... B109: =IFERROR(AVERAGEIFS('Сентябрь 2024'!$K:$K,'Сентябрь 2024'!$E:$E,$A:$A),"-") -> - | C109: =IFERROR(AVERAGEIFS('Октябрь 2024'!$K:$K,'Октябрь 2024'!$E:$E,$A:$A),"-") -> - | D109: =IFERROR(AVERAGEIFS('Ноябрь 2024'!$K:$K,'Ноябрь 2024'!$E:$E,$A:$A),"-") -> - | E109: =IFERROR(AVERAGEIFS('Декабрь 2024'!$K:$K,'Декабрь 2024'!$E:$E,$A:$A),"-") -> - | F109: =IFERROR(AVERAGEIFS('Январь 2025'!$K:$K,'Январь 2025'!$E:$E,$A:$A),"-") -> - | G109: =IFERROR(AVERAGEIFS('Февраль 2025 '!K:K,'Февраль 2025 '!E:E,A:A),"-") -> - | H109: =IFERROR(AVERAGEIFS('Март 2025'!$K:$K,'Март 2025'!$E:$E,$A:$A),"-") -> - | I109: =IFERROR(AVERAGEIFS('Апрель 2025'!$K:$K,'Апрель 2025'!$E:$E,$A:$A),"-") -> - | J109: =IFERROR(AVERAGEIFS('Май 2025'!$K:$K,'Май 2025'!$E:$E,$A:$A),"-") -> - | K109: =IFERROR(AVERAGEIFS('Июнь 2025'!$K:$K,'Июнь 2025'!$E:$E,$A:$A),"-") -> - | L109: =IFERROR(AVERAGEIFS('Июль 2025'!$K:$K,'Июль 2025'!$E:$E,$A:$A),"-") -> - | M109: =IFERROR(AVERAGEIFS('Август 2025'!$K:$K,'Август 2025'!$E:$E,$A:$A),"-") -> - | N109: =IFERROR(AVERAGEIFS('Сентябрь 2025'!$K:$K,'Сентябрь 2025'!$E:$E,$A:$A),"-") -> - | O109: =IFERROR(AVERAGEIFS('Октябрь 2025'!$K:$K,'Октябрь 2025'!$E:$E,$A:$A),"-") -> - | P109: =IFERROR(AVERAGEIFS('Ноябрь 2025'!$K:$K,'Ноябрь 2025'!$E:$E,$A:$A),"-") -> - | Q109: =IFERROR(AVERAGEIFS('Декабрь 2025'!$K:$K,'Декабрь 2025'!$E:$E,$A:$A),"-") -> - | R109: =IFERROR(AVERAGEIFS('Январь 2026'!$K:$K,'Январь 2026'!$E:$E,$A:$A),"-") -> - | S109: =IFERROR(AVERAGEIFS('Февраль 2026'!$K:$K,'Февраль 2026'!$E:$E,$A:$A),"-") -> - | T109: =IFERROR(AVERAGEIFS('Март 2026'!$K:$K,'Март 2026'!$E:$E,$A:$A),"-") -> - | U109: =IFERROR(AVERAGEIFS('Апрель 2026'!$K:$K,'Апрель 2026'!$E:$E,$A:$A),"-") -> - | V109: =IFERROR(AVERAGEIFS('Май 2026'!$K:$K,'Май 2026'!$E:$E,$A:$A),"-") -> - | W109: =IFERROR(AVERAGEIFS('Июнь 2026'!$K:$K,'Июнь 2026'!$E:$E,$A:$A),"-") -> - | X109: =IFERROR(AVERAGEIFS('Июль 2026'!$K:$K,'Июль 2026'!$E:$E,$A:$A),"-") -> -
B110: =IFERROR(AVERAGEIFS('Сентябрь 2024'!$K:$K,'Сентябрь 2024'!$E:$E,$A:$A),"-") -> - | C110: =IFERROR(AVERAGEIFS('Октябрь 2024'!$K:$K,'Октябрь 2024'!$E:$E,$A:$A),"-") -> - | D110: =IFERROR(AVERAGEIFS('Ноябрь 2024'!$K:$K,'Ноябрь 2024'!$E:$E,$A:$A),"-") -> - | E110: =IFERROR(AVERAGEIFS('Декабрь 2024'!$K:$K,'Декабрь 2024'!$E:$E,$A:$A),"-") -> - | F110: =IFERROR(AVERAGEIFS('Январь 2025'!$K:$K,'Январь 2025'!$E:$E,$A:$A),"-") -> - | G110: =IFERROR(AVERAGEIFS('Февраль 2025 '!K:K,'Февраль 2025 '!E:E,A:A),"-") -> - | H110: =IFERROR(AVERAGEIFS('Март 2025'!$K:$K,'Март 2025'!$E:$E,$A:$A),"-") -> - | I110: =IFERROR(AVERAGEIFS('Апрель 2025'!$K:$K,'Апрель 2025'!$E:$E,$A:$A),"-") -> - | J110: =IFERROR(AVERAGEIFS('Май 2025'!$K:$K,'Май 2025'!$E:$E,$A:$A),"-") -> - | K110: =IFERROR(AVERAGEIFS('Июнь 2025'!$K:$K,'Июнь 2025'!$E:$E,$A:$A),"-") -> - | L110: =IFERROR(AVERAGEIFS('Июль 2025'!$K:$K,'Июль 2025'!$E:$E,$A:$A),"-") -> - | M110: =IFERROR(AVERAGEIFS('Август 2025'!$K:$K,'Август 2025'!$E:$E,$A:$A),"-") -> - | N110: =IFERROR(AVERAGEIFS('Сентябрь 2025'!$K:$K,'Сентябрь 2025'!$E:$E,$A:$A),"-") -> - | O110: =IFERROR(AVERAGEIFS('Октябрь 2025'!$K:$K,'Октябрь 2025'!$E:$E,$A:$A),"-") -> - | P110: =IFERROR(AVERAGEIFS('Ноябрь 2025'!$K:$K,'Ноябрь 2025'!$E:$E,$A:$A),"-") -> - | Q110: =IFERROR(AVERAGEIFS('Декабрь 2025'!$K:$K,'Декабрь 2025'!$E:$E,$A:$A),"-") -> - | R110: =IFERROR(AVERAGEIFS('Январь 2026'!$K:$K,'Январь 2026'!$E:$E,$A:$A),"-") -> - | S110: =IFERROR(AVERAGEIFS('Февраль 2026'!$K:$K,'Февраль 2026'!$E:$E,$A:$A),"-") -> - | T110: =IFERROR(AVERAGEIFS('Март 2026'!$K:$K,'Март 2026'!$E:$E,$A:$A),"-") -> - | U110: =IFERROR(AVERAGEIFS('Апрель 2026'!$K:$K,'Апрель 2026'!$E:$E,$A:$A),"-") -> - | V110: =IFERROR(AVERAGEIFS('Май 2026'!$K:$K,'Май 2026'!$E:$E,$A:$A),"-") -> - | W110: =IFERROR(AVERAGEIFS('Май 2026'!$K:$K,'Май 2026'!$E:$E,$A:$A),"-") -> - | X110: =IFERROR(AVERAGEIFS('Май 2026'!$K:$K,'Май 2026'!$E:$E,$A:$A),"-") -> -
